Workbook

Sheet TABLE
A1: =(CONCATENATE("PG_CI_",(MID(B4,4,LEN(B4)-4)))) -> PG_CI_CUSTOMER
A3: PK | B3: Nombre Campo | C3: Tipo Dato
A4: X | B4: [K_CUSTOMER] | C4: [INT]
B5: [D_CUSTOMER] | C5: [VARCHAR](500)
B6: [C_CUSTOMER] | C6: [VARCHAR](500)
B7: [S_CUSTOMER] | C7: [VARCHAR](10)
B8: [K_COUNTRY] | C8: [INT]
B9: [K_STATE_GEO] | C9: [INT]
B10: [CUSTOMER_CITY] | C10: [VARCHAR](100)
B11: [D_CUSTOMER_ADDRESS_01] | C11: [VARCHAR](500)
B12: [D_CUSTOMER_ADDRESS_02] | C12: [VARCHAR](500)
B13: [CUSTOMER_POSTAL_CODE] | C13: [INT]
B14: [F_CUSTOMER_DATE] | C14: [DATE]
B15: [O_CUSTOMER] | C15: [INT]
B16: [L_CUSTOMER] | C16: [INT]
C24: [SLSPSN_NO] | D24: [CUST_TYPE_CD] | E24: [COLLECTOR] | F24: [CURR_CD] | G24: [CMT_2] | H24: [CMT_1] | I24: [HOLD_FG]

Sheet CI_
A1: ??? | B1: L_DEBUG | C1: K_SISTEMA_EXE | D1: K_USUARIO_ACCION | E1: [K_CUSTOMER] | F1: [D_CUSTOMER] | G1: [C_CUSTOMER] | H1: [S_CUSTOMER] | I1: [K_CONTINENTE] | J1: [K_COUNTRY] | K1: [K_STATE_GEO] | L1: [CUSTOMER_CITY] | M1: [D_CUSTOMER_ADDRESS_01] | N1: [D_CUSTOMER_ADDRESS_02] | O1: [CUSTOMER_POSTAL_CODE] | P1: [F_CUSTOMER_DATE] | Q1: [O_CUSTOMER] | R1: [L_CUSTOMER] | S1: [EMAIL] | T1: [SLSPSN_NO] | U1: [CUST_TYPE_CD] | V1: [COLLECTOR] | W1: [CURR_CD] | X1: [CMT_2] | Y1: [CMT_1] | Z1: [HOLD_FG] | AB1: EXECUTE [dbo].[ | AC1: PG_CI_ARCUSFIL_SQL | AD1: ] | AE1: =CONCATENATE($AB$1,$AC$1,$AD$1,B3, ", ", C3, ", ", D3, ", ", ) -> EXECUTE [dbo].[PG_CI_ARCUSFIL_SQL] 0, 0, 0,
B2: 0 | C2: 0 | D2: 0 | E2: 1 | F2: CNI INC | G2: CNI INC | H2: CNII01 | I2: 200 | J2: 221 | K2: 54 | L2: TROY | M2: 1148 ROCHESTER ROAD | O2: 48083 | P2: 1998-05-22 | Q2: =E2 -> 1 | R2: 1 | T2: 2 | U2: MCUEX | W2: USD | X2: FOB ACUNA | Y2: N/A | Z2: N | AB2: =CONCATENATE(CI_!$AE$1,E2,", '",F2,"', '",G2,"' , '",H2,"' , ",I2,",",J2," , ",K2,", '",L2,"', '",M2,"' ,'",N2,"' , '",O2,"' , '",P2,"' , '",Q2,"' , '",R2,"','",S2,"','",T2,"','",U2,"','",V2,"','",W2,"','",X2,"','",Y2,"','",Z2,"'") -> EXECUTE [dbo].[PG_CI_ARCUSFIL_SQL] 0, 0, 0, 1, 'CNI INC', 'CNI INC' , 'CNII01' , 200,221 , 54, 'TROY', '1148 ROCHESTER ROAD' ,'' , '48083' , '1998-05-22' , '1' , '1','','2','MCUEX','','USD','FOB ACUNA','N/A','N'
B3: 0 | C3: 0 | D3: 0 | E3: 2 | F3: EBINGER BROTHERS LEATHER COMPANY | G3: EBINGER BROTHERS LEATHER COMPANY | H3: EBIN01 | I3: 200 | J3: 221 | K3: 53 | L3: MASSACHUSETTS | M3: 44 MITCHELL ROAD | N3: IPSWICH | O3: 1938 | P3: 2001-02-12 | Q3: =E3 -> 2 | R3: 1 | T3: 2 | U3: MSUEX | W3: USD | Y3: N/A | Z3: N | AB3: =CONCATENATE(CI_!$AE$1,E3,", '",F3,"', '",G3,"' , '",H3,"' , ",I3,",",J3," , ",K3,", '",L3,"', '",M3,"' ,'",N3,"' , '",O3,"' , '",P3,"' , '",Q3,"' , '",R3,"','",S3,"','",T3,"','",U3,"','",V3,"','",W3,"','",X3,"','",Y3,"','",Z3,"'") -> EXECUTE [dbo].[PG_CI_ARCUSFIL_SQL] 0, 0, 0, 2, 'EBINGER BROTHERS LEATHER COMPANY', 'EBINGER BROTHERS LEATHER COMPANY' , 'EBIN01' , 200,221 , 53, 'MASSACHUSETTS', '44 MITCHELL ROAD' ,'IPSWICH' , '1938' , '2001-02-12' , '2' , '1','','2','MSUEX','','USD','','N/A','N'
B4: 0 | C4: 0 | D4: 0 | E4: 3 | F4: ENSAMBLE DE INTERIORES AUTOMOTRICES | G4: ENSAMBLE DE INTERIORES AUTOMOTRICES | H4: ENSA01 | I4: 200 | J4: 260 | K4: 8 | L4: CD JUAREZ, CHIH. | M4: BLVD. OSCAR FLORES 4250 | O4: 32650 | P4: 2001-06-07 | Q4: =E4 -> 3 | R4: 1 | T4: 2 | U4: MISC | W4: USD | Y4: N/A | Z4: N | AB4: =CONCATENATE(CI_!$AE$1,E4,", '",F4,"', '",G4,"' , '",H4,"' , ",I4,",",J4," , ",K4,", '",L4,"', '",M4,"' ,'",N4,"' , '",O4,"' , '",P4,"' , '",Q4,"' , '",R4,"','",S4,"','",T4,"','",U4,"','",V4,"','",W4,"','",X4,"','",Y4,"','",Z4,"'") -> EXECUTE [dbo].[PG_CI_ARCUSFIL_SQL] 0, 0, 0, 3, 'ENSAMBLE DE INTERIORES AUTOMOTRICES', 'ENSAMBLE DE INTERIORES AUTOMOTRICES' , 'ENSA01' , 200,260 , 8, 'CD JUAREZ, CHIH.', 'BLVD. OSCAR FLORES 4250' ,'' , '32650' , '2001-06-07' , '3' , '1','','2','MISC ','','USD','','N/A','N'
B5: 0 | C5: 0 | D5: 0 | E5: 4 | F5: FINDLAY INDUSTRIES********* | G5: FINDLAY INDUSTRIES************* | H5: FIND01 | I5: 200 | J5: 221 | K5: 67 | L5: OHIO | M5: 4000 FOSTORIA ROAD | N5: FINDLAY 0410 45840 | O5: 45840 | P5: 1998-05-22 | Q5: =E5 -> 4 | R5: 1 | T5: 2 | U5: MCUEX | W5: USD | X5: NETT CIF | Y5: N/A | Z5: N | AB5: =CONCATENATE(CI_!$AE$1,E5,", '",F5,"', '",G5,"' , '",H5,"' , ",I5,",",J5," , ",K5,", '",L5,"', '",M5,"' ,'",N5,"' , '",O5,"' , '",P5,"' , '",Q5,"' , '",R5,"','",S5,"','",T5,"','",U5,"','",V5,"','",W5,"','",X5,"','",Y5,"','",Z5,"'") -> EXECUTE [dbo].[PG_CI_ARCUSFIL_SQL] 0, 0, 0, 4, 'FINDLAY INDUSTRIES*********', 'FINDLAY INDUSTRIES*************' , 'FIND01' , 200,221 , 67, 'OHIO', '4000 FOSTORIA ROAD' ,'FINDLAY 0410 45840' , '45840' , '1998-05-22' , '4' , '1','','2','MCUEX','','USD','NETT CIF','N/A','N'
B6: 0 | C6: 0 | D6: 0 | E6: 5 | F6: FINDLAY INDUSTRIES (FLORIDA)*********** | G6: FINDLAY INDUSTRIES (FLORIDA)************ | H6: FIND02 | I6: 200 | J6: 221 | K6: 41 | L6: FLORIDA | M6: PO BOX 1350 | N6: LAKE WALES | O6: 33853 | P6: 1999-09-02 | Q6: =E6 -> 5 | R6: 1 | T6: 2 | U6: MCUEX | W6: USD | X6: NETT CIF | Y6: N/A | Z6: N | AB6: =CONCATENATE(CI_!$AE$1,E6,", '",F6,"', '",G6,"' , '",H6,"' , ",I6,",",J6," , ",K6,", '",L6,"', '",M6,"' ,'",N6,"' , '",O6,"' , '",P6,"' , '",Q6,"' , '",R6,"','",S6,"','",T6,"','",U6,"','",V6,"','",W6,"','",X6,"','",Y6,"','",Z6,"'") -> EXECUTE [dbo].[PG_CI_ARCUSFIL_SQL] 0, 0, 0, 5, 'FINDLAY INDUSTRIES (FLORIDA)***********', 'FINDLAY INDUSTRIES (FLORIDA)************' , 'FIND02' , 200,221 , 41, 'FLORIDA', 'PO BOX 1350' ,'LAKE WALES' , '33853' , '1999-09-02' , '5' , '1','','2','MCUEX','','USD','NETT CIF','N/A','N'
B7: 0 | C7: 0 | D7: 0 | E7: 6 | F7: GLOBALTEX 2000 LTD | G7: GLOBALTEX 2000 LTD | H7: GLOB01 | I7: 200 | J7: 213 | K7: 0 | M7: UNIT C/735 PRINCE ROAD | N7: WINDSOR | O7: N9C2Z2 | P7: 2000-03-23 | Q7: =E7 -> 6 | R7: 1 | T7: 2 | U7: MCUEX | W7: USD | Y7: N/A | Z7: N | AB7: =CONCATENATE(CI_!$AE$1,E7,", '",F7,"', '",G7,"' , '",H7,"' , ",I7,",",J7," , ",K7,", '",L7,"', '",M7,"' ,'",N7,"' , '",O7,"' , '",P7,"' , '",Q7,"' , '",R7,"','",S7,"','",T7,"','",U7,"','",V7,"','",W7,"','",X7,"','",Y7,"','",Z7,"'") -> EXECUTE [dbo].[PG_CI_ARCUSFIL_SQL] 0, 0, 0, 6, 'GLOBALTEX 2000 LTD', 'GLOBALTEX 2000 LTD' , 'GLOB01' , 200,213 , 0, '', 'UNIT C/735 PRINCE ROAD' ,'WINDSOR' , 'N9C2Z2' , '2000-03-23' , '6' , '1','','2','MCUEX','','USD','','N/A','N'
B8: 0 | C8: 0 | D8: 0 | E8: 7 | F8: IRVIN AUTOMOTIVE PRODUCTS -PONTIAC | G8: IRVIN AUTOMOTIVE | H8: IRVI02 | I8: 200 | J8: 221 | K8: 54 | L8: PONTIAC | M8: 2600 CENTER POINT PARKWAY | O8: 48341 | P8: 2001-07-25 | Q8: =E8 -> 7 | R8: 1 | T8: 2 | U8: MFUEX | W8: USD | Y8: N/A | Z8: N | AB8: =CONCATENATE(CI_!$AE$1,E8,", '",F8,"', '",G8,"' , '",H8,"' , ",I8,",",J8," , ",K8,", '",L8,"', '",M8,"' ,'",N8,"' , '",O8,"' , '",P8,"' , '",Q8,"' , '",R8,"','",S8,"','",T8,"','",U8,"','",V8,"','",W8,"','",X8,"','",Y8,"','",Z8,"'") -> EXECUTE [dbo].[PG_CI_ARCUSFIL_SQL] 0, 0, 0, 7, 'IRVIN AUTOMOTIVE PRODUCTS -PONTIAC', 'IRVIN AUTOMOTIVE' , 'IRVI02' , 200,221 , 54, 'PONTIAC', '2600 CENTER POINT PARKWAY' ,'' , '48341' , '2001-07-25' , '7' , '1','','2','MFUEX','','USD','','N/A','N'
B9: 0 | C9: 0 | D9: 0 | E9: 8 | F9: AUTOSEAT S.A. DE C.V. | G9: AUTOSEAT S.A. DE C.V. | H9: JITC01 | I9: 200 | J9: 260 | K9: 15 | L9: NAUCALPA | M9: PLANT#18232 | N9: CALLE NEGRA MODELO #6A FRACC ALCE BLANCO | O9: 53370 | P9: 1999-11-11 | Q9: =E9 -> 8 | R9: 1 | T9: 2 | U9: MCUEX | W9: USD | Y9: N/A | Z9: N | AB9: =CONCATENATE(CI_!$AE$1,E9,", '",F9,"', '",G9,"' , '",H9,"' , ",I9,",",J9," , ",K9,", '",L9,"', '",M9,"' ,'",N9,"' , '",O9,"' , '",P9,"' , '",Q9,"' , '",R9,"','",S9,"','",T9,"','",U9,"','",V9,"','",W9,"','",X9,"','",Y9,"','",Z9,"'") -> EXECUTE [dbo].[PG_CI_ARCUSFIL_SQL] 0, 0, 0, 8, 'AUTOSEAT S.A. DE C.V.', 'AUTOSEAT S.A. DE C.V.' , 'JITC01' , 200,260 , 15, 'NAUCALPA', 'PLANT#18232' ,'CALLE NEGRA MODELO #6A FRACC ALCE BLANCO' , '53370' , '1999-11-11' , '8' , '1','','2','MCUEX','','USD','','N/A','N'
B10: 0 | C10: 0 | D10: 0 | E10: 9 | F10: Johnson Control Interiors LLC | G10: JOHNSON CONTROL INTERIORS LLC | H10: JOHN02 | I10: 200 | J10: 221 | K10: 75 | L10: El Paso | M10: 1320 Goodyear Dr | O10: 79936 | P10: 2001-03-04 | Q10: =E10 -> 9 | R10: 1 | T10: 2 | U10: MCUEX | W10: USD | Y10: N/A | Z10: N | AB10: =CONCATENATE(CI_!$AE$1,E10,", '",F10,"', '",G10,"' , '",H10,"' , ",I10,",",J10," , ",K10,", '",L10,"', '",M10,"' ,'",N10,"' , '",O10,"' , '",P10,"' , '",Q10,"' , '",R10,"','",S10,"','",T10,"','",U10,"','",V10,"','",W10,"','",X10,"','",Y10,"','",Z10,"'") -> EXECUTE [dbo].[PG_CI_ARCUSFIL_SQL] 0, 0, 0, 9, 'Johnson Control Interiors LLC', 'JOHNSON CONTROL INTERIORS LLC' , 'JOHN02' , 200,221 , 75, 'El Paso', '1320 Goodyear Dr' ,'' , '79936' , '2001-03-04' , '9' , '1','','2','MCUEX','','USD','','N/A','N'
B11: 0 | C11: 0 | D11: 0 | E11: 10 | F11: KRAFT AUTOMOTIVE GROUP, INC | G11: KRAFT AUTOMOTIVE GROUP, INC | H11: KRAF01 | I11: 200 | J11: 221 | K11: 54 | L11: HOWELL | M11: 955 GRAND OAKS DRIVE | O11: 48843 | P11: 2001-04-26 | Q11: =E11 -> 10 | R11: 1 | T11: 8 | U11: MFUEX | W11: USD | Y11: N/A | Z11: N | AB11: =CONCATENATE(CI_!$AE$1,E11,", '",F11,"', '",G11,"' , '",H11,"' , ",I11,",",J11," , ",K11,", '",L11,"', '",M11,"' ,'",N11,"' , '",O11,"' , '",P11,"' , '",Q11,"' , '",R11,"','",S11,"','",T11,"','",U11,"','",V11,"','",W11,"','",X11,"','",Y11,"','",Z11,"'") -> EXECUTE [dbo].[PG_CI_ARCUSFIL_SQL] 0, 0, 0, 10, 'KRAFT AUTOMOTIVE GROUP, INC', 'KRAFT AUTOMOTIVE GROUP, INC' , 'KRAF01' , 200,221 , 54, 'HOWELL', '955 GRAND OAKS DRIVE' ,'' , '48843' , '2001-04-26' , '10' , '1','','8','MFUEX','','USD','','N/A','N'
B12: 0 | C12: 0 | D12: 0 | E12: 11 | F12: LEAR NAB CORPORATION (FAVESA) | G12: LEAR NAB CORPORATION (FAVESA) | H12: LEAR05 | I12: 200 | J12: 221 | K12: 75 | L12: EL PASO | M12: 1440 DON HASKINS | O12: 79936 | P12: 1998-05-25 | Q12: =E12 -> 11 | R12: 1 | T12: 2 | U12: MCUEX | W12: USD | Y12: N/A | Z12: N | AB12: =CONCATENATE(CI_!$AE$1,E12,", '",F12,"', '",G12,"' , '",H12,"' , ",I12,",",J12," , ",K12,", '",L12,"', '",M12,"' ,'",N12,"' , '",O12,"' , '",P12,"' , '",Q12,"' , '",R12,"','",S12,"','",T12,"','",U12,"','",V12,"','",W12,"','",X12,"','",Y12,"','",Z12,"'") -> EXECUTE [dbo].[PG_CI_ARCUSFIL_SQL] 0, 0, 0, 11, 'LEAR NAB CORPORATION (FAVESA)', 'LEAR NAB CORPORATION (FAVESA)' , 'LEAR05' , 200,221 , 75, 'EL PASO', '1440 DON HASKINS' ,'' , '79936' , '1998-05-25' , '11' , '1','','2','MCUEX','','USD','','N/A','N'
B13: 0 | C13: 0 | D13: 0 | E13: 12 | F13: LEAR TECHNOLOGIES, LLC | G13: LEAR TECHNOLOGIES, LLC | H13: LEAT01 | I13: 200 | J13: 221 | K13: 79 | M13: PO BOX 4178 | N13: SOUTHFIELD | O13: 48086-4178 | P13: 2000-03-09 | Q13: =E13 -> 12 | R13: 1 | T13: 2 | U13: MFUEX | W13: USD | Y13: N/A | Z13: N | AB13: =CONCATENATE(CI_!$AE$1,E13,", '",F13,"', '",G13,"' , '",H13,"' , ",I13,",",J13," , ",K13,", '",L13,"', '",M13,"' ,'",N13,"' , '",O13,"' , '",P13,"' , '",Q13,"' , '",R13,"','",S13,"','",T13,"','",U13,"','",V13,"','",W13,"','",X13,"','",Y13,"','",Z13,"'") -> EXECUTE [dbo].[PG_CI_ARCUSFIL_SQL] 0, 0, 0, 12, 'LEAR TECHNOLOGIES, LLC', 'LEAR TECHNOLOGIES, LLC' , 'LEAT01' , 200,221 , 79, '', 'PO BOX 4178' ,'SOUTHFIELD' , '48086-4178' , '2000-03-09' , '12' , '1','','2','MFUEX','','USD','','N/A','N'
B14: 0 | C14: 0 | D14: 0 | E14: 13 | F14: LEAR MEXICAN SEATING CORP | G14: LEAR RIO BRAVO | H14: LEAV01 | I14: 200 | J14: 221 | K14: 75 | L14: EL PASO | M14: 9500 PLAZA CIRCLE | N14: P.O. BOX 17709 | O14: 79917-7709 | P14: 1999-02-25 | Q14: =E14 -> 13 | R14: 1 | T14: 2 | U14: MFUEX | W14: USD | Y14: N/A | Z14: N | AB14: =CONCATENATE(CI_!$AE$1,E14,", '",F14,"', '",G14,"' , '",H14,"' , ",I14,",",J14," , ",K14,", '",L14,"', '",M14,"' ,'",N14,"' , '",O14,"' , '",P14,"' , '",Q14,"' , '",R14,"','",S14,"','",T14,"','",U14,"','",V14,"','",W14,"','",X14,"','",Y14,"','",Z14,"'") -> EXECUTE [dbo].[PG_CI_ARCUSFIL_SQL] 0, 0, 0, 13, 'LEAR MEXICAN SEATING CORP', 'LEAR RIO BRAVO' , 'LEAV01' , 200,221 , 75, 'EL PASO', '9500 PLAZA CIRCLE' ,'P.O. BOX 17709' , '79917-7709' , '1999-02-25' , '13' , '1','','2','MFUEX','','USD','','N/A','N'
B15: 0 | C15: 0 | D15: 0 | E15: 14 | F15: Leatherworks LLC | G15: LEATHERWORKS LLC | H15: LEAW01 | I15: 200 | J15: 221 | K15: 54 | L15: ALLEN PARK | M15: ATTN Accounts Payable | N15: 16630 Southfield Road, Suite 3100 | O15: 48101 | P15: 2001-08-22 | Q15: =E15 -> 14 | R15: 1 | T15: 2 | U15: MFUEX | W15: USD | Y15: Duty Paid | Z15: N | AB15: =CONCATENATE(CI_!$AE$1,E15,", '",F15,"', '",G15,"' , '",H15,"' , ",I15,",",J15," , ",K15,", '",L15,"', '",M15,"' ,'",N15,"' , '",O15,"' , '",P15,"' , '",Q15,"' , '",R15,"','",S15,"','",T15,"','",U15,"','",V15,"','",W15,"','",X15,"','",Y15,"','",Z15,"'") -> EXECUTE [dbo].[PG_CI_ARCUSFIL_SQL] 0, 0, 0, 14, 'Leatherworks LLC', 'LEATHERWORKS LLC' , 'LEAW01' , 200,221 , 54, 'ALLEN PARK', 'ATTN Accounts Payable' ,'16630 Southfield Road, Suite 3100' , '48101' , '2001-08-22' , '14' , '1','','2','MFUEX','','USD','','Duty Paid','N'
B16: 0 | C16: 0 | D16: 0 | E16: 15 | F16: LEAR CORPORATION - GM DIVISION | G16: LEAR CORPORATION - GM DIVISION | H16: LEGM01 | I16: 200 | J16: 221 | K16: 54 | L16: WARREN | M16: 5800 ENTERPRISE DRIVE | O16: 48092 | P16: 1999-11-19 | Q16: =E16 -> 15 | R16: 1 | T16: 2 | U16: MFUEX | W16: USD | Y16: N/A | Z16: N | AB16: =CONCATENATE(CI_!$AE$1,E16,", '",F16,"', '",G16,"' , '",H16,"' , ",I16,",",J16," , ",K16,", '",L16,"', '",M16,"' ,'",N16,"' , '",O16,"' , '",P16,"' , '",Q16,"' , '",R16,"','",S16,"','",T16,"','",U16,"','",V16,"','",W16,"','",X16,"','",Y16,"','",Z16,"'") -> EXECUTE [dbo].[PG_CI_ARCUSFIL_SQL] 0, 0, 0, 15, 'LEAR CORPORATION - GM DIVISION', 'LEAR CORPORATION - GM DIVISION' , 'LEGM01' , 200,221 , 54, 'WARREN', '5800 ENTERPRISE DRIVE' ,'' , '48092' , '1999-11-19' , '15' , '1','','2','MFUEX','','USD','','N/A','N'
B17: 0 | C17: 0 | D17: 0 | E17: 16 | F17: LEAR CORP FORD DIVISION | G17: LEAR CORP FORD DIVISION | H17: LFOR01 | I17: 200 | J17: 221 | K17: 54 | L17: DEARBORN | M17: 5250 AUTO CLUB DRIVE ANNEX | O17: 48126 | P17: 1999-04-30 | Q17: =E17 -> 16 | R17: 1 | T17: 2 | U17: MFUEX | W17: USD | Y17: N/A | Z17: N | AB17: =CONCATENATE(CI_!$AE$1,E17,", '",F17,"', '",G17,"' , '",H17,"' , ",I17,",",J17," , ",K17,", '",L17,"', '",M17,"' ,'",N17,"' , '",O17,"' , '",P17,"' , '",Q17,"' , '",R17,"','",S17,"','",T17,"','",U17,"','",V17,"','",W17,"','",X17,"','",Y17,"','",Z17,"'") -> EXECUTE [dbo].[PG_CI_ARCUSFIL_SQL] 0, 0, 0, 16, 'LEAR CORP FORD DIVISION', 'LEAR CORP FORD DIVISION' , 'LFOR01' , 200,221 , 54, 'DEARBORN', '5250 AUTO CLUB DRIVE ANNEX' ,'' , '48126' , '1999-04-30' , '16' , '1','','2','MFUEX','','USD','','N/A','N'
B18: 0 | C18: 0 | D18: 0 | E18: 17 | F18: SEATING SYSTEMS OF SABINAS | G18: SEATING SYSTEMS OF SABINAS | H18: MAGN01 | I18: 200 | J18: 221 | K18: 75 | L18: EAGLE PASS | M18: A DIV OF Magna Seating of America, Inc. | N18: 540 SOUTH BIBB PMB #1 | O18: 78852 | P18: 1999-11-12 | Q18: =E18 -> 17 | R18: 1 | T18: 2 | U18: MCUEX | W18: USD | Y18: N/A | Z18: N | AB18: =CONCATENATE(CI_!$AE$1,E18,", '",F18,"', '",G18,"' , '",H18,"' , ",I18,",",J18," , ",K18,", '",L18,"', '",M18,"' ,'",N18,"' , '",O18,"' , '",P18,"' , '",Q18,"' , '",R18,"','",S18,"','",T18,"','",U18,"','",V18,"','",W18,"','",X18,"','",Y18,"','",Z18,"'") -> EXECUTE [dbo].[PG_CI_ARCUSFIL_SQL] 0, 0, 0, 17, 'SEATING SYSTEMS OF SABINAS', 'SEATING SYSTEMS OF SABINAS' , 'MAGN01' , 200,221 , 75, 'EAGLE PASS', 'A DIV OF Magna Seating of America, Inc.' ,'540 SOUTH BIBB PMB #1' , '78852' , '1999-11-12' , '17' , '1','','2','MCUEX','','USD','','N/A','N'
B19: 0 | C19: 0 | D19: 0 | E19: 18 | F19: MAGNA SEATING OF AMERICA INC (ACUÑA) | G19: MAGNA SEATING OF AMERICA | H19: MAGN02 | I19: 200 | J19: 221 | K19: 75 | L19: DEL RIO | M19: 2199 SPUR 239 | N19: MAILING TO: P.O BOX 420699 | O19: 78840 | P19: 2000-02-01 | Q19: =E19 -> 18 | R19: 1 | T19: 2 | U19: MCUEX | W19: USD | Y19: N/A | Z19: N | AB19: =CONCATENATE(CI_!$AE$1,E19,", '",F19,"', '",G19,"' , '",H19,"' , ",I19,",",J19," , ",K19,", '",L19,"', '",M19,"' ,'",N19,"' , '",O19,"' , '",P19,"' , '",Q19,"' , '",R19,"','",S19,"','",T19,"','",U19,"','",V19,"','",W19,"','",X19,"','",Y19,"','",Z19,"'") -> EXECUTE [dbo].[PG_CI_ARCUSFIL_SQL] 0, 0, 0, 18, 'MAGNA SEATING OF AMERICA INC (ACUÑA)', 'MAGNA SEATING OF AMERICA' , 'MAGN02' , 200,221 , 75, 'DEL RIO', '2199 SPUR 239' ,'MAILING TO: P.O BOX 420699' , '78840' , '2000-02-01' , '18' , '1','','2','MCUEX','','USD','','N/A','N'
B20: 0 | C20: 0 | D20: 0 | E20: 19 | F20: SEATING SYS.OF ACUNA DIV INTIER AUTO | G20: MAGNA SEATING SYSTEMS OF ACUNA | H20: MAGN03 | I20: 200 | J20: 221 | K20: 75 | L20: DEL RIO | M20: 2199 SPUR 239 | N20: P.O. BOX 420699 | O20: 78840 | P20: 2000-07-28 | Q20: =E20 -> 19 | R20: 1 | T20: 2 | U20: MCUEX | W20: USD | Y20: N/A | Z20: N | AB20: =CONCATENATE(CI_!$AE$1,E20,", '",F20,"', '",G20,"' , '",H20,"' , ",I20,",",J20," , ",K20,", '",L20,"', '",M20,"' ,'",N20,"' , '",O20,"' , '",P20,"' , '",Q20,"' , '",R20,"','",S20,"','",T20,"','",U20,"','",V20,"','",W20,"','",X20,"','",Y20,"','",Z20,"'") -> EXECUTE [dbo].[PG_CI_ARCUSFIL_SQL] 0, 0, 0, 19, 'SEATING SYS.OF ACUNA DIV INTIER AUTO', 'MAGNA SEATING SYSTEMS OF ACUNA' , 'MAGN03' , 200,221 , 75, 'DEL RIO', '2199 SPUR 239' ,'P.O. BOX 420699' , '78840' , '2000-07-28' , '19' , '1','','2','MCUEX','','USD','','N/A','N'
B21: 0 | C21: 0 | D21: 0 | E21: 20 | F21: MAZDA CANADA INC | G21: MAZDA CANADA INC | H21: MAZC01 | I21: 200 | J21: 213 | K21: 83 | L21: SCARBOROUGH | M21: 305 MILNER AVENUE, | N21: SUITE 400 | O21: MIB 3V4 | P21: 2000-03-22 | Q21: =E21 -> 20 | R21: 1 | T21: 2 | U21: MFUEX | W21: USD | Y21: N/A | Z21: N | AB21: =CONCATENATE(CI_!$AE$1,E21,", '",F21,"', '",G21,"' , '",H21,"' , ",I21,",",J21," , ",K21,", '",L21,"', '",M21,"' ,'",N21,"' , '",O21,"' , '",P21,"' , '",Q21,"' , '",R21,"','",S21,"','",T21,"','",U21,"','",V21,"','",W21,"','",X21,"','",Y21,"','",Z21,"'") -> EXECUTE [dbo].[PG_CI_ARCUSFIL_SQL] 0, 0, 0, 20, 'MAZDA CANADA INC', 'MAZDA CANADA INC' , 'MAZC01' , 200,213 , 83, 'SCARBOROUGH', '305 MILNER AVENUE,' ,'SUITE 400' , 'MIB 3V4' , '2000-03-22' , '20' , '1','','2','MFUEX','','USD','','N/A','N'
B22: 0 | C22: 0 | D22: 0 | E22: 21 | F22: MAZDA NORTH AMERICAN OPERATION | G22: MAZDA NORTH AMERICAN OPERATION | H22: MAZN01 | I22: 200 | J22: 221 | K22: 37 | L22: IRVINE | M22: 7755 IRVINE CENTRE DRIVE | O22: 92618-2922 | P22: 2000-03-22 | Q22: =E22 -> 21 | R22: 1 | T22: 2 | U22: MFUEX | W22: USD | Y22: N/A | Z22: N | AB22: =CONCATENATE(CI_!$AE$1,E22,", '",F22,"', '",G22,"' , '",H22,"' , ",I22,",",J22," , ",K22,", '",L22,"', '",M22,"' ,'",N22,"' , '",O22,"' , '",P22,"' , '",Q22,"' , '",R22,"','",S22,"','",T22,"','",U22,"','",V22,"','",W22,"','",X22,"','",Y22,"','",Z22,"'") -> EXECUTE [dbo].[PG_CI_ARCUSFIL_SQL] 0, 0, 0, 21, 'MAZDA NORTH AMERICAN OPERATION', 'MAZDA NORTH AMERICAN OPERATION' , 'MAZN01' , 200,221 , 37, 'IRVINE', '7755 IRVINE CENTRE DRIVE' ,'' , '92618-2922' , '2000-03-22' , '21' , '1','','2','MFUEX','','USD','','N/A','N'
B23: 0 | C23: 0 | D23: 0 | E23: 22 | F23: MCDONALD EXP-DO NOT USE | G23: MCDONALD EXPORTS -DO NOT USE | H23: MCDO01 | I23: 500 | J23: 501 | K23: 105 | L23: SOUTHPORT | M23: SUITE 1 SOUTHPORT CHASE | N23: 19 EXPO COURT | O23: 4215 | P23: 2001-08-03 | Q23: =E23 -> 22 | R23: 1 | T23: 2 | U23: MISC | W23: USD | Y23: ABN | Z23: N | AB23: =CONCATENATE(CI_!$AE$1,E23,", '",F23,"', '",G23,"' , '",H23,"' , ",I23,",",J23," , ",K23,", '",L23,"', '",M23,"' ,'",N23,"' , '",O23,"' , '",P23,"' , '",Q23,"' , '",R23,"','",S23,"','",T23,"','",U23,"','",V23,"','",W23,"','",X23,"','",Y23,"','",Z23,"'") -> EXECUTE [dbo].[PG_CI_ARCUSFIL_SQL] 0, 0, 0, 22, 'MCDONALD EXP-DO NOT USE', 'MCDONALD EXPORTS -DO NOT USE' , 'MCDO01' , 500,501 , 105, 'SOUTHPORT', 'SUITE 1 SOUTHPORT CHASE' ,'19 EXPO COURT' , '4215' , '2001-08-03' , '22' , '1','','2','MISC ','','USD','','ABN','N'
B24: 0 | C24: 0 | D24: 0 | E24: 23 | F24: MCDONALD EXPORTS (AUST) P/L | G24: MCDONALD EXPORTS (AUST) P/L | H24: MCDO02 | I24: 500 | J24: 501 | K24: 105 | L24: SOUTHPORT | M24: SUITE 1 SOUTHPORT CHASE | N24: 19 EXPO COURT | O24: 4215 | P24: 2001-08-03 | Q24: =E24 -> 23 | R24: 1 | T24: 2 | U24: MISC | W24: USD | Y24: ABN | Z24: N | AB24: =CONCATENATE(CI_!$AE$1,E24,", '",F24,"', '",G24,"' , '",H24,"' , ",I24,",",J24," , ",K24,", '",L24,"', '",M24,"' ,'",N24,"' , '",O24,"' , '",P24,"' , '",Q24,"' , '",R24,"','",S24,"','",T24,"','",U24,"','",V24,"','",W24,"','",X24,"','",Y24,"','",Z24,"'") -> EXECUTE [dbo].[PG_CI_ARCUSFIL_SQL] 0, 0, 0, 23, 'MCDONALD EXPORTS (AUST) P/L', 'MCDONALD EXPORTS (AUST) P/L' , 'MCDO02' , 500,501 , 105, 'SOUTHPORT', 'SUITE 1 SOUTHPORT CHASE' ,'19 EXPO COURT' , '4215' , '2001-08-03' , '23' , '1','','2','MISC ','','USD','','ABN','N'
B25: 0 | C25: 0 | D25: 0 | E25: 24 | F25: MEXICAN INDUSTRIES**DO NOT USE** | G25: MEXICAN INDUSTRIES**DO NOT USE** | H25: MEXI02 | I25: 200 | J25: 221 | K25: 54 | L25: DETROIT | M25: ATT : PATTY ODELL | N25: 1801 HOWARD STREET | O25: 48216 | P25: 1998-11-30 | Q25: =E25 -> 24 | R25: 1 | T25: 2 | U25: MCUEX | W25: USD | Y25: N/A | Z25: Y | AB25: =CONCATENATE(CI_!$AE$1,E25,", '",F25,"', '",G25,"' , '",H25,"' , ",I25,",",J25," , ",K25,", '",L25,"', '",M25,"' ,'",N25,"' , '",O25,"' , '",P25,"' , '",Q25,"' , '",R25,"','",S25,"','",T25,"','",U25,"','",V25,"','",W25,"','",X25,"','",Y25,"','",Z25,"'") -> EXECUTE [dbo].[PG_CI_ARCUSFIL_SQL] 0, 0, 0, 24, 'MEXICAN INDUSTRIES**DO NOT USE**', 'MEXICAN INDUSTRIES**DO NOT USE**' , 'MEXI02' , 200,221 , 54, 'DETROIT', 'ATT : PATTY ODELL' ,'1801 HOWARD STREET' , '48216' , '1998-11-30' , '24' , '1','','2','MCUEX','','USD','','N/A','Y'
B26: 0 | C26: 0 | D26: 0 | E26: 25 | F26: MORIDEN AMERICA, INC. | G26: MORIDEN | H26: MORI01 | I26: 200 | J26: 221 | K26: 46 | L26: INDIANAPOLIS | M26: 915 WESTERN DRIVE | O26: 46241 | P26: 1998-07-01 | Q26: =E26 -> 25 | R26: 1 | T26: 2 | U26: MCUEX | W26: USD | Y26: N/A | Z26: N | AB26: =CONCATENATE(CI_!$AE$1,E26,", '",F26,"', '",G26,"' , '",H26,"' , ",I26,",",J26," , ",K26,", '",L26,"', '",M26,"' ,'",N26,"' , '",O26,"' , '",P26,"' , '",Q26,"' , '",R26,"','",S26,"','",T26,"','",U26,"','",V26,"','",W26,"','",X26,"','",Y26,"','",Z26,"'") -> EXECUTE [dbo].[PG_CI_ARCUSFIL_SQL] 0, 0, 0, 25, 'MORIDEN AMERICA, INC.', 'MORIDEN' , 'MORI01' , 200,221 , 46, 'INDIANAPOLIS', '915 WESTERN DRIVE' ,'' , '46241' , '1998-07-01' , '25' , '1','','2','MCUEX','','USD','','N/A','N'
B27: 0 | C27: 0 | D27: 0 | E27: 26 | F27: 1004274 ONTARIO LTD | G27: ONTARIO LTD | H27: ONTA01 | I27: 200 | J27: 213 | K27: 83 | L27: ONTARIO | M27: 993 BUCKSKIN WAY | N27: ORLEANS | O27: 2Y7 | P27: 2000-06-22 | Q27: =E27 -> 26 | R27: 1 | T27: 8 | U27: MSUEX | W27: USD | X27: L/C | Y27: N/A | Z27: N | AB27: =CONCATENATE(CI_!$AE$1,E27,", '",F27,"', '",G27,"' , '",H27,"' , ",I27,",",J27," , ",K27,", '",L27,"', '",M27,"' ,'",N27,"' , '",O27,"' , '",P27,"' , '",Q27,"' , '",R27,"','",S27,"','",T27,"','",U27,"','",V27,"','",W27,"','",X27,"','",Y27,"','",Z27,"'") -> EXECUTE [dbo].[PG_CI_ARCUSFIL_SQL] 0, 0, 0, 26, '1004274 ONTARIO LTD', 'ONTARIO LTD' , 'ONTA01' , 200,213 , 83, 'ONTARIO', '993 BUCKSKIN WAY' ,'ORLEANS' , '2Y7' , '2000-06-22' , '26' , '1','','8','MSUEX','','USD','L/C','N/A','N'
B28: 0 | C28: 0 | D28: 0 | E28: 27 | F28: TECHNOTRIM | G28: TECHNOTRIM | H28: TECH01 | I28: 200 | J28: 221 | K28: 54 | L28: CANTON | M28: 42015 FORD ROAD BOX 358 | O28: 48187-3669 | P28: 2000-01-31 | Q28: =E28 -> 27 | R28: 1 | T28: 2 | U28: MCUEX | W28: USD | Y28: N/A | Z28: N | AB28: =CONCATENATE(CI_!$AE$1,E28,", '",F28,"', '",G28,"' , '",H28,"' , ",I28,",",J28," , ",K28,", '",L28,"', '",M28,"' ,'",N28,"' , '",O28,"' , '",P28,"' , '",Q28,"' , '",R28,"','",S28,"','",T28,"','",U28,"','",V28,"','",W28,"','",X28,"','",Y28,"','",Z28,"'") -> EXECUTE [dbo].[PG_CI_ARCUSFIL_SQL] 0, 0, 0, 27, 'TECHNOTRIM', 'TECHNOTRIM' , 'TECH01' , 200,221 , 54, 'CANTON', '42015 FORD ROAD BOX 358' ,'' , '48187-3669' , '2000-01-31' , '27' , '1','','2','MCUEX','','USD','','N/A','N'
B29: 0 | C29: 0 | D29: 0 | E29: 28 | F29: UNIVERSAL TRIM INC | G29: UNIVERSAL TRIM INC | H29: UNIV01 | I29: 200 | J29: 221 | K29: 54 | L29: MADISON HEIGHTS | M29: PO BOX 71541 | O29: 48071-0541 | P29: 2000-01-25 | Q29: =E29 -> 28 | R29: 1 | T29: 2 | U29: MCUEX | W29: USD | Y29: N/A | Z29: N | AB29: =CONCATENATE(CI_!$AE$1,E29,", '",F29,"', '",G29,"' , '",H29,"' , ",I29,",",J29," , ",K29,", '",L29,"', '",M29,"' ,'",N29,"' , '",O29,"' , '",P29,"' , '",Q29,"' , '",R29,"','",S29,"','",T29,"','",U29,"','",V29,"','",W29,"','",X29,"','",Y29,"','",Z29,"'") -> EXECUTE [dbo].[PG_CI_ARCUSFIL_SQL] 0, 0, 0, 28, 'UNIVERSAL TRIM INC', 'UNIVERSAL TRIM INC' , 'UNIV01' , 200,221 , 54, 'MADISON HEIGHTS', 'PO BOX 71541' ,'' , '48071-0541' , '2000-01-25' , '28' , '1','','2','MCUEX','','USD','','N/A','N'
B30: 0 | C30: 0 | D30: 0 | E30: 29 | F30: BAILEY MANAGEMENT CONSULTING SERVICES | G30: BAILEY MANAGEMENT CONSULTING SERVICES | H30: BMCS01 | I30: 200 | J30: 213 | K30: 83 | L30: ONTARIO | M30: 163 HERITAGE ROAD | N30: KINGSVILLE | O30: N9Y 2C7 | P30: 2001-10-08 | Q30: =E30 -> 29 | R30: 1 | T30: 2 | U30: MCUEX | W30: USD | Y30: N/A | Z30: N | AB30: =CONCATENATE(CI_!$AE$1,E30,", '",F30,"', '",G30,"' , '",H30,"' , ",I30,",",J30," , ",K30,", '",L30,"', '",M30,"' ,'",N30,"' , '",O30,"' , '",P30,"' , '",Q30,"' , '",R30,"','",S30,"','",T30,"','",U30,"','",V30,"','",W30,"','",X30,"','",Y30,"','",Z30,"'") -> EXECUTE [dbo].[PG_CI_ARCUSFIL_SQL] 0, 0, 0, 29, 'BAILEY MANAGEMENT CONSULTING SERVICES', 'BAILEY MANAGEMENT CONSULTING SERVICES' , 'BMCS01' , 200,213 , 83, 'ONTARIO', '163 HERITAGE ROAD' ,'KINGSVILLE' , 'N9Y 2C7' , '2001-10-08' , '29' , '1','','2','MCUEX','','USD','','N/A','N'
B31: 0 | C31: 0 | D31: 0 | E31: 30 | F31: LEAR HERMOSILLO | G31: LEAR HERMOSILLO | H31: LEAR07 | I31: 200 | J31: 260 | K31: 26 | L31: NOGALES | M31: LEAR CORPORATION MEXICO SA DE CV | N31: PO BOX 6323 | O31: 85621 | P31: 2001-10-18 | Q31: =E31 -> 30 | R31: 1 | T31: 2 | U31: MCUEX | W31: USD | Y31: ABN | Z31: N | AB31: =CONCATENATE(CI_!$AE$1,E31,", '",F31,"', '",G31,"' , '",H31,"' , ",I31,",",J31," , ",K31,", '",L31,"', '",M31,"' ,'",N31,"' , '",O31,"' , '",P31,"' , '",Q31,"' , '",R31,"','",S31,"','",T31,"','",U31,"','",V31,"','",W31,"','",X31,"','",Y31,"','",Z31,"'") -> EXECUTE [dbo].[PG_CI_ARCUSFIL_SQL] 0, 0, 0, 30, 'LEAR HERMOSILLO', 'LEAR HERMOSILLO' , 'LEAR07' , 200,260 , 26, 'NOGALES', 'LEAR CORPORATION MEXICO SA DE CV' ,'PO BOX 6323' , '85621' , '2001-10-18' , '30' , '1','','2','MCUEX','','USD','','ABN','N'
B32: 0 | C32: 0 | D32: 0 | E32: 31 | F32: VISUAL SERVICES | G32: VISUAL SERVICES | H32: VISU01 | I32: 200 | J32: 221 | K32: 54 | L32: BLOOMFIELD HILLS | M32: 41000 WOODWARD AVENUE | O32: 48304-2263 | P32: 2001-11-18 | Q32: =E32 -> 31 | R32: 1 | T32: 2 | U32: MFUEX | W32: USD | Y32: N/A | Z32: N | AB32: =CONCATENATE(CI_!$AE$1,E32,", '",F32,"', '",G32,"' , '",H32,"' , ",I32,",",J32," , ",K32,", '",L32,"', '",M32,"' ,'",N32,"' , '",O32,"' , '",P32,"' , '",Q32,"' , '",R32,"','",S32,"','",T32,"','",U32,"','",V32,"','",W32,"','",X32,"','",Y32,"','",Z32,"'") -> EXECUTE [dbo].[PG_CI_ARCUSFIL_SQL] 0, 0, 0, 31, 'VISUAL SERVICES', 'VISUAL SERVICES' , 'VISU01' , 200,221 , 54, 'BLOOMFIELD HILLS', '41000 WOODWARD AVENUE' ,'' , '48304-2263' , '2001-11-18' , '31' , '1','','2','MFUEX','','USD','','N/A','N'
B33: 0 | C33: 0 | D33: 0 | E33: 32 | F33: JCIM MEXICO PROPERTIES,S.de R.L. | G33: JOHNSON CONTROLS MEXICO | H33: JOHN01 | I33: 200 | J33: 260 | K33: 8 | L33: JUAREZ | M33: EPSILON 6525 | N33: PARQUE INDUSTRIAL OMEGA | O33: 32320 | P33: 2002-01-22 | Q33: =E33 -> 32 | R33: 1 | T33: 2 | U33: MFUEX | W33: USD | X33: RICARDO.PEREZ@JCI.COM | Y33: N/A | Z33: N | AB33: =CONCATENATE(CI_!$AE$1,E33,", '",F33,"', '",G33,"' , '",H33,"' , ",I33,",",J33," , ",K33,", '",L33,"', '",M33,"' ,'",N33,"' , '",O33,"' , '",P33,"' , '",Q33,"' , '",R33,"','",S33,"','",T33,"','",U33,"','",V33,"','",W33,"','",X33,"','",Y33,"','",Z33,"'") -> EXECUTE [dbo].[PG_CI_ARCUSFIL_SQL] 0, 0, 0, 32, 'JCIM MEXICO PROPERTIES,S.de R.L.', 'JOHNSON CONTROLS MEXICO' , 'JOHN01' , 200,260 , 8, 'JUAREZ', 'EPSILON 6525' ,'PARQUE INDUSTRIAL OMEGA' , '32320' , '2002-01-22' , '32' , '1','','2','MFUEX','','USD','RICARDO.PEREZ@JCI.COM','N/A','N'
B34: 0 | C34: 0 | D34: 0 | E34: 33 | F34: CASH SALES MEXICO | G34: CASH SALES MEXICO | H34: CASH01 | I34: 0 | J34: 0 | K34: 0 | O34: 0 | P34: 2002-01-28 | Q34: =E34 -> 33 | R34: 1 | T34: 2 | U34: MISC | W34: USD | Z34: N | AB34: =CONCATENATE(CI_!$AE$1,E34,", '",F34,"', '",G34,"' , '",H34,"' , ",I34,",",J34," , ",K34,", '",L34,"', '",M34,"' ,'",N34,"' , '",O34,"' , '",P34,"' , '",Q34,"' , '",R34,"','",S34,"','",T34,"','",U34,"','",V34,"','",W34,"','",X34,"','",Y34,"','",Z34,"'") -> EXECUTE [dbo].[PG_CI_ARCUSFIL_SQL] 0, 0, 0, 33, 'CASH SALES MEXICO', 'CASH SALES MEXICO' , 'CASH01' , 0,0 , 0, '', '' ,'' , '0' , '2002-01-28' , '33' , '1','','2','MISC ','','USD','','','N'
B35: 0 | C35: 0 | D35: 0 | E35: 34 | F35: IRVIN AUTOMOTIVE | G35: JAROPAMEX ACUNA, PLANT1 | H35: IRVI03 | I35: 200 | J35: 221 | K35: 75 | L35: DEL RIO | M35: 2A FAWCETT DRIVE | O35: 78840 | P35: 2003-11-06 | Q35: =E35 -> 34 | R35: 1 | T35: 2 | U35: MFUEX | W35: USD | X35: FOB SHIP POINT | Y35: N/A | Z35: N | AB35: =CONCATENATE(CI_!$AE$1,E35,", '",F35,"', '",G35,"' , '",H35,"' , ",I35,",",J35," , ",K35,", '",L35,"', '",M35,"' ,'",N35,"' , '",O35,"' , '",P35,"' , '",Q35,"' , '",R35,"','",S35,"','",T35,"','",U35,"','",V35,"','",W35,"','",X35,"','",Y35,"','",Z35,"'") -> EXECUTE [dbo].[PG_CI_ARCUSFIL_SQL] 0, 0, 0, 34, 'IRVIN AUTOMOTIVE', 'JAROPAMEX ACUNA, PLANT1' , 'IRVI03' , 200,221 , 75, 'DEL RIO', '2A FAWCETT DRIVE' ,'' , '78840' , '2003-11-06' , '34' , '1','','2','MFUEX','','USD','FOB SHIP POINT','N/A','N'
B36: 0 | C36: 0 | D36: 0 | E36: 35 | F36: TENNMEX INC | G36: TENNMEX INC | H36: TENN01 | I36: 200 | J36: 221 | K36: 75 | M36: 2262 SAN JUAN DRIVE | N36: EAGLE PASS | O36: 78852 | P36: 2005-08-15 | Q36: =E36 -> 35 | R36: 1 | T36: 2 | U36: MCUEX | W36: USD | Y36: N/A | Z36: N | AB36: =CONCATENATE(CI_!$AE$1,E36,", '",F36,"', '",G36,"' , '",H36,"' , ",I36,",",J36," , ",K36,", '",L36,"', '",M36,"' ,'",N36,"' , '",O36,"' , '",P36,"' , '",Q36,"' , '",R36,"','",S36,"','",T36,"','",U36,"','",V36,"','",W36,"','",X36,"','",Y36,"','",Z36,"'") -> EXECUTE [dbo].[PG_CI_ARCUSFIL_SQL] 0, 0, 0, 35, 'TENNMEX INC', 'TENNMEX INC' , 'TENN01' , 200,221 , 75, '', '2262 SAN JUAN DRIVE' ,'EAGLE PASS' , '78852' , '2005-08-15' , '35' , '1','','2','MCUEX','','USD','','N/A','N'
B37: 0 | C37: 0 | D37: 0 | E37: 36 | F37: WOODBRIDGE FOAM CORPORATION | G37: WOODBRIDGE FOAM CORPORATION | H37: WOOD01 | I37: 200 | J37: 260 | K37: 5 | L37: RAMOS ARIZPE | M37: SALTILLO MONTERREY KM1150 | N37: PARQUE INDUSTRIAL RAMOS ARIZPE | O37: 25900 | P37: 2006-01-30 | Q37: =E37 -> 36 | R37: 1 | T37: 2 | U37: MFUEX | W37: USD | Y37: N/A | Z37: N | AB37: =CONCATENATE(CI_!$AE$1,E37,", '",F37,"', '",G37,"' , '",H37,"' , ",I37,",",J37," , ",K37,", '",L37,"', '",M37,"' ,'",N37,"' , '",O37,"' , '",P37,"' , '",Q37,"' , '",R37,"','",S37,"','",T37,"','",U37,"','",V37,"','",W37,"','",X37,"','",Y37,"','",Z37,"'") -> EXECUTE [dbo].[PG_CI_ARCUSFIL_SQL] 0, 0, 0, 36, 'WOODBRIDGE FOAM CORPORATION', 'WOODBRIDGE FOAM CORPORATION' , 'WOOD01' , 200,260 , 5, 'RAMOS ARIZPE', 'SALTILLO MONTERREY KM1150' ,'PARQUE INDUSTRIAL RAMOS ARIZPE' , '25900' , '2006-01-30' , '36' , '1','','2','MFUEX','','USD','','N/A','N'
B38: 0 | C38: 0 | D38: 0 | E38: 37 | F38: JOHNSON CONTROLS-EDIASA 3 | G38: JOHNSON CONTROLS-EDIASA 3 | H38: JOHN03 | I38: 200 | J38: 221 | K38: 75 | L38: EL PASO | M38: JOHNSON CONTROLS INC | N38: SSC ACCOUNTS PAYABLE | O38: 981700 | P38: 2006-12-20 | Q38: =E38 -> 37 | R38: 1 | T38: 2 | U38: MCUEX | W38: USD | Y38: N/A | Z38: N | AB38: =CONCATENATE(CI_!$AE$1,E38,", '",F38,"', '",G38,"' , '",H38,"' , ",I38,",",J38," , ",K38,", '",L38,"', '",M38,"' ,'",N38,"' , '",O38,"' , '",P38,"' , '",Q38,"' , '",R38,"','",S38,"','",T38,"','",U38,"','",V38,"','",W38,"','",X38,"','",Y38,"','",Z38,"'") -> EXECUTE [dbo].[PG_CI_ARCUSFIL_SQL] 0, 0, 0, 37, 'JOHNSON CONTROLS-EDIASA 3', 'JOHNSON CONTROLS-EDIASA 3' , 'JOHN03' , 200,221 , 75, 'EL PASO', 'JOHNSON CONTROLS INC' ,'SSC ACCOUNTS PAYABLE' , '981700' , '2006-12-20' , '37' , '1','','2','MCUEX','','USD','','N/A','N'
B39: 0 | C39: 0 | D39: 0 | E39: 38 | F39: JOHNSON CONTROL SHANGAI | G39: JOHNSON CONTROL SHANGAI | H39: JOHN04 | I39: 200 | J39: 221 | K39: 75 | L39: EL PASO | M39: SSC ACCOUNTS PAYABLE -18438 | N39: PO BOX 981700 | O39: 79998 | P39: 2007-01-18 | Q39: =E39 -> 38 | R39: 1 | T39: 11 | U39: MCUEX | W39: USD | Z39: N | AB39: =CONCATENATE(CI_!$AE$1,E39,", '",F39,"', '",G39,"' , '",H39,"' , ",I39,",",J39," , ",K39,", '",L39,"', '",M39,"' ,'",N39,"' , '",O39,"' , '",P39,"' , '",Q39,"' , '",R39,"','",S39,"','",T39,"','",U39,"','",V39,"','",W39,"','",X39,"','",Y39,"','",Z39,"'") -> EXECUTE [dbo].[PG_CI_ARCUSFIL_SQL] 0, 0, 0, 38, 'JOHNSON CONTROL SHANGAI', 'JOHNSON CONTROL SHANGAI' , 'JOHN04' , 200,221 , 75, 'EL PASO', 'SSC ACCOUNTS PAYABLE -18438' ,'PO BOX 981700' , '79998' , '2007-01-18' , '38' , '1','','11','MCUEX','','USD','','','N'
B40: 0 | C40: 0 | D40: 0 | E40: 39 | F40: KONGSBERG AUTOMOTIVE | G40: KONGSBERG AUTOMOTIVE | H40: KONG01 | I40: 200 | J40: 221 | K40: 75 | L40: PHARR | M40: LAREDO FREIGHT - KONGSBERG AUTOMOTIVE | N40: 9208 SOUTH CAGE BLVD | O40: 78577 | P40: 2008-01-29 | Q40: =E40 -> 39 | R40: 1 | T40: 2 | U40: MCUEX | W40: USD | X40: EXW | Y40: N/A | Z40: N | AB40: =CONCATENATE(CI_!$AE$1,E40,", '",F40,"', '",G40,"' , '",H40,"' , ",I40,",",J40," , ",K40,", '",L40,"', '",M40,"' ,'",N40,"' , '",O40,"' , '",P40,"' , '",Q40,"' , '",R40,"','",S40,"','",T40,"','",U40,"','",V40,"','",W40,"','",X40,"','",Y40,"','",Z40,"'") -> EXECUTE [dbo].[PG_CI_ARCUSFIL_SQL] 0, 0, 0, 39, 'KONGSBERG AUTOMOTIVE', 'KONGSBERG AUTOMOTIVE' , 'KONG01' , 200,221 , 75, 'PHARR', 'LAREDO FREIGHT - KONGSBERG AUTOMOTIVE' ,'9208 SOUTH CAGE BLVD' , '78577' , '2008-01-29' , '39' , '1','','2','MCUEX','','USD','EXW','N/A','N'
...

Sheet ADDRESS
A1: ??? | B1: L_DEBUG | C1: K_SISTEMA_EXE | D1: K_USUARIO_ACCION | E1: [K_CUSTOMER] | F1: [K_ADDRESS_TYPE] | G1: [D_CUSTOMER_ADDRESS_NAME] | H1: [D_CUSTOMER_ADDRESS_01] | I1: [D_CUSTOMER_ADDRESS_02] | J1: [D_CUSTOMER_ADDRESS_03] | K1: [D_CUSTOMER_ADDRESS_04] | L1: [L_CUSTOMER_ADDRESS_MAIN] | N1: EXECUTE [dbo].[ | O1: =TABLE!A1 -> PG_CI_CUSTOMER | P1: ] | Q1: =CONCATENATE($N$1,$O$1,$P$1,B3, ", ", C3, ", ", D3, ", ", ) -> EXECUTE [dbo].[PG_CI_CUSTOMER] 0, 0, 0,
B2: - | C2: - | D2: - | E2: - | F2: - | G2: - | H2: - | I2: - | J2: - | K2: - | N2: ="-- ==========================================================" -> -- ==========================================================
B3: 0 | C3: 0 | D3: 0 | E3: 56 | F3: 1 | G3: DAIMAY AUTOMOTIVE INTERIOR, S DE R.L. DE | H3: AVE. CENZONTLE ESQ. HALCON | I3: CARRETERA MONCLOVA #7 | J3: PARQUE INDUSTRIAL FINSA | K3: RAMOS ARZIPE COAH | L3: 1 | N3: =CONCATENATE(ADDRESS!$Q$1,E3,", '",F3,"', '",G3,"' , '",H3,"' , '",I3,"' , '",J3,"', '",K3,"', '",L3,"'") -> EXECUTE [dbo].[PG_CI_CUSTOMER] 0, 0, 0, 56, '1', 'DAIMAY AUTOMOTIVE INTERIOR, S DE R.L. DE' , 'AVE. CENZONTLE ESQ. HALCON' , 'CARRETERA MONCLOVA #7' , 'PARQUE INDUSTRIAL FINSA', 'RAMOS ARZIPE COAH', '1'
B4: 0 | C4: 0 | D4: 0 | E4: 56 | F4: 2 | G4: DAIMAY AUTOMOTIVE INTERIOR, S DE R.L. DE | H4: AVE. CENZONTLE ESQ. HALCON | I4: CARRETERA MONCLOVA #7 | J4: PARQUE INDUSTRIAL FINSA | K4: RAMOS ARZIPE COAH | L4: 1 | N4: =CONCATENATE(ADDRESS!$Q$1,E4,", '",F4,"', '",G4,"' , '",H4,"' , '",I4,"' , '",J4,"', '",K4,"', '",L4,"'") -> EXECUTE [dbo].[PG_CI_CUSTOMER] 0, 0, 0, 56, '2', 'DAIMAY AUTOMOTIVE INTERIOR, S DE R.L. DE' , 'AVE. CENZONTLE ESQ. HALCON' , 'CARRETERA MONCLOVA #7' , 'PARQUE INDUSTRIAL FINSA', 'RAMOS ARZIPE COAH', '1'
B5: 0 | C5: 0 | D5: 0 | E5: 57 | F5: 1 | G5: Eissmann Automotive de Mexico | H5: Reforma Sur No. 27 | I5: Nave 1 | J5: Panzacola, 90796 | K5: MEXICO | L5: 1 | N5: =CONCATENATE(ADDRESS!$Q$1,E5,", '",F5,"', '",G5,"' , '",H5,"' , '",I5,"' , '",J5,"', '",K5,"', '",L5,"'") -> EXECUTE [dbo].[PG_CI_CUSTOMER] 0, 0, 0, 57, '1', 'Eissmann Automotive de Mexico' , 'Reforma Sur No. 27' , 'Nave 1' , 'Panzacola, 90796', 'MEXICO', '1'
B6: 0 | C6: 0 | D6: 0 | E6: 57 | F6: 2 | G6: Eissmann Automotive de Mexico | H6: Reforma Sur No. 27 | I6: Nave 1 | J6: Panzacola, 90796 | K6: MEXICO | L6: 1 | N6: =CONCATENATE(ADDRESS!$Q$1,E6,", '",F6,"', '",G6,"' , '",H6,"' , '",I6,"' , '",J6,"', '",K6,"', '",L6,"'") -> EXECUTE [dbo].[PG_CI_CUSTOMER] 0, 0, 0, 57, '2', 'Eissmann Automotive de Mexico' , 'Reforma Sur No. 27' , 'Nave 1' , 'Panzacola, 90796', 'MEXICO', '1'
B7: 0 | C7: 0 | D7: 0 | E7: 34 | F7: 1 | G7: Irvin Automotive Products, LLC | H7: 2A Fawcett Dr. | I7: Del Rio, TX 78840 | J7: United States | L7: 1 | N7: =CONCATENATE(ADDRESS!$Q$1,E7,", '",F7,"', '",G7,"' , '",H7,"' , '",I7,"' , '",J7,"', '",K7,"', '",L7,"'") -> EXECUTE [dbo].[PG_CI_CUSTOMER] 0, 0, 0, 34, '1', 'Irvin Automotive Products, LLC' , '2A Fawcett Dr.' , 'Del Rio, TX 78840' , 'United States', '', '1'
B8: 0 | C8: 0 | D8: 0 | E8: 34 | F8: 2 | G8: Irvin Automotive Products, LLC | H8: 2A Fawcett Dr. | I8: Del Rio, TX 78840 | J8: United States | L8: 1 | N8: =CONCATENATE(ADDRESS!$Q$1,E8,", '",F8,"', '",G8,"' , '",H8,"' , '",I8,"' , '",J8,"', '",K8,"', '",L8,"'") -> EXECUTE [dbo].[PG_CI_CUSTOMER] 0, 0, 0, 34, '2', 'Irvin Automotive Products, LLC' , '2A Fawcett Dr.' , 'Del Rio, TX 78840' , 'United States', '', '1'
B9: 0 | C9: 0 | D9: 0 | E9: 18 | F9: 1 | G9: MAGNA SEATING OF AMERICA INC | H9: 2199 SPUR 239 | I9: MAILING TO: P.O. BOX 420699 | J9: DEL RIO TX 78840 | K9: USA | L9: 1 | N9: =CONCATENATE(ADDRESS!$Q$1,E9,", '",F9,"', '",G9,"' , '",H9,"' , '",I9,"' , '",J9,"', '",K9,"', '",L9,"'") -> EXECUTE [dbo].[PG_CI_CUSTOMER] 0, 0, 0, 18, '1', 'MAGNA SEATING OF AMERICA INC' , '2199 SPUR 239' , 'MAILING TO: P.O. BOX 420699' , 'DEL RIO TX 78840', 'USA', '1'
B10: 0 | C10: 0 | D10: 0 | E10: 18 | F10: 2 | G10: MAGNA SEATING OF AMERICA INC | H10: 2199 SPUR 239 | I10: MAILING TO: P.O. BOX 420699 | J10: DEL RIO TX 78840 | K10: USA | L10: 1 | N10: =CONCATENATE(ADDRESS!$Q$1,E10,", '",F10,"', '",G10,"' , '",H10,"' , '",I10,"' , '",J10,"', '",K10,"', '",L10,"'") -> EXECUTE [dbo].[PG_CI_CUSTOMER] 0, 0, 0, 18, '2', 'MAGNA SEATING OF AMERICA INC' , '2199 SPUR 239' , 'MAILING TO: P.O. BOX 420699' , 'DEL RIO TX 78840', 'USA', '1'
B11: 0 | C11: 0 | D11: 0 | E11: 19 | F11: 1 | G11: SEATING SYS.OF ACUNA DIV INTIER AUTO | H11: 2199 SPUR 239 | I11: P.O. BOX 420699 | J11: DEL RIO, TX 78840 | K11: USA | L11: 1 | N11: =CONCATENATE(ADDRESS!$Q$1,E11,", '",F11,"', '",G11,"' , '",H11,"' , '",I11,"' , '",J11,"', '",K11,"', '",L11,"'") -> EXECUTE [dbo].[PG_CI_CUSTOMER] 0, 0, 0, 19, '1', 'SEATING SYS.OF ACUNA DIV INTIER AUTO' , '2199 SPUR 239' , 'P.O. BOX 420699' , 'DEL RIO, TX 78840', 'USA', '1'
B12: 0 | C12: 0 | D12: 0 | E12: 19 | F12: 2 | G12: SEATING SYS.OF ACUNA DIV INTIER AUTO | H12: 2199 SPUR 239 | I12: P.O. BOX 420699 | J12: DEL RIO, TX 78840 | K12: USA | L12: 1 | N12: =CONCATENATE(ADDRESS!$Q$1,E12,", '",F12,"', '",G12,"' , '",H12,"' , '",I12,"' , '",J12,"', '",K12,"', '",L12,"'") -> EXECUTE [dbo].[PG_CI_CUSTOMER] 0, 0, 0, 19, '2', 'SEATING SYS.OF ACUNA DIV INTIER AUTO' , '2199 SPUR 239' , 'P.O. BOX 420699' , 'DEL RIO, TX 78840', 'USA', '1'
B13: 0 | C13: 0 | D13: 0 | E13: 36 | F13: 1 | G13: SALTILLO INTERIOR TRIM SA DE CV | H13: AUTOPISTA SALTILLO-MONTERREY KM 11.50 | I13: PARQUE INDUSTRIAL RAMOS ARIZPE | J13: COAHUILA, CP 25900 | L13: 1 | N13: =CONCATENATE(ADDRESS!$Q$1,E13,", '",F13,"', '",G13,"' , '",H13,"' , '",I13,"' , '",J13,"', '",K13,"', '",L13,"'") -> EXECUTE [dbo].[PG_CI_CUSTOMER] 0, 0, 0, 36, '1', 'SALTILLO INTERIOR TRIM SA DE CV' , 'AUTOPISTA SALTILLO-MONTERREY KM 11.50' , 'PARQUE INDUSTRIAL RAMOS ARIZPE' , 'COAHUILA, CP 25900', '', '1'
B14: 0 | C14: 0 | D14: 0 | E14: 36 | F14: 2 | G14: SALTILLO INTERIOR TRIM SA DE CV | H14: AUTOPISTA SALTILLO-MONTERREY KM 11.50 | I14: PARQUE INDUSTRIAL RAMOS ARIZPE | J14: COAHUILA, CP 25900 | L14: 1 | N14: =CONCATENATE(ADDRESS!$Q$1,E14,", '",F14,"', '",G14,"' , '",H14,"' , '",I14,"' , '",J14,"', '",K14,"', '",L14,"'") -> EXECUTE [dbo].[PG_CI_CUSTOMER] 0, 0, 0, 36, '2', 'SALTILLO INTERIOR TRIM SA DE CV' , 'AUTOPISTA SALTILLO-MONTERREY KM 11.50' , 'PARQUE INDUSTRIAL RAMOS ARIZPE' , 'COAHUILA, CP 25900', '', '1'
B15: 0 | C15: 0 | D15: 0 | E15: 55 | F15: 1 | G15: WPI | H15: 845 PROGRESS CT. WILLIAMSTON, MI 48895 | I15: WILLIAMSTON, MI | L15: 1 | N15: =CONCATENATE(ADDRESS!$Q$1,E15,", '",F15,"', '",G15,"' , '",H15,"' , '",I15,"' , '",J15,"', '",K15,"', '",L15,"'") -> EXECUTE [dbo].[PG_CI_CUSTOMER] 0, 0, 0, 55, '1', 'WPI' , '845 PROGRESS CT. WILLIAMSTON, MI 48895' , 'WILLIAMSTON, MI' , '', '', '1'
B16: 0 | C16: 0 | D16: 0 | E16: 55 | F16: 2 | G16: WPI | H16: 845 PROGRESS CT. WILLIAMSTON, MI 48895 | I16: WILLIAMSTON, MI | L16: 1 | N16: =CONCATENATE(ADDRESS!$Q$1,E16,", '",F16,"', '",G16,"' , '",H16,"' , '",I16,"' , '",J16,"', '",K16,"', '",L16,"'") -> EXECUTE [dbo].[PG_CI_CUSTOMER] 0, 0, 0, 55, '2', 'WPI' , '845 PROGRESS CT. WILLIAMSTON, MI 48895' , 'WILLIAMSTON, MI' , '', '', '1'
B17: 0 | C17: 0 | D17: 0 | E17: 53 | F17: 1 | G17: Yanfeng Mexico | H17: PO BOX 7148 | I17: 48376 Novi MI | J17: UNITED STATES | L17: 1 | N17: =CONCATENATE(ADDRESS!$Q$1,E17,", '",F17,"', '",G17,"' , '",H17,"' , '",I17,"' , '",J17,"', '",K17,"', '",L17,"'") -> EXECUTE [dbo].[PG_CI_CUSTOMER] 0, 0, 0, 53, '1', 'Yanfeng Mexico' , 'PO BOX 7148' , '48376 Novi MI' , 'UNITED STATES', '', '1'
B18: 0 | C18: 0 | D18: 0 | E18: 53 | F18: 2 | G18: Yanfeng Mexico | H18: PO BOX 7148 | I18: 48376 Novi MI | J18: UNITED STATES | L18: 1 | N18: =CONCATENATE(ADDRESS!$Q$1,E18,", '",F18,"', '",G18,"' , '",H18,"' , '",I18,"' , '",J18,"', '",K18,"', '",L18,"'") -> EXECUTE [dbo].[PG_CI_CUSTOMER] 0, 0, 0, 53, '2', 'Yanfeng Mexico' , 'PO BOX 7148' , '48376 Novi MI' , 'UNITED STATES', '', '1'
B19: 0 | C19: 0 | D19: 0 | E19: 58 | F19: 1 | G19: YANGFENG AUTOMOTIVE INTERIOR SYSTEMS(THAILAND) CO.,LTD | H19: 700/20 WHA EASTERN SEABOARD INDUSTRIAL | I19: 1 M00 7 Tambol Khao Khan Song, Amphur Sriracha | J19: CHONBURI, 700/20 | K19: THAILAND TAX ID:0205562018045 | L19: 1 | N19: =CONCATENATE(ADDRESS!$Q$1,E19,", '",F19,"', '",G19,"' , '",H19,"' , '",I19,"' , '",J19,"', '",K19,"', '",L19,"'") -> EXECUTE [dbo].[PG_CI_CUSTOMER] 0, 0, 0, 58, '1', 'YANGFENG AUTOMOTIVE INTERIOR SYSTEMS(THAILAND) CO.,LTD' , '700/20 WHA EASTERN SEABOARD INDUSTRIAL' , '1 M00 7 Tambol Khao Khan Song, Amphur Sriracha' , 'CHONBURI, 700/20', 'THAILAND TAX ID:0205562018045', '1'
B20: 0 | C20: 0 | D20: 0 | E20: 58 | F20: 2 | G20: YANGFENG AUTOMOTIVE INTERIOR SYSTEMS(THAILAND) CO.,LTD | H20: 700/20 WHA EASTERN SEABOARD INDUSTRIAL | I20: 1 M00 7 Tambol Khao Khan Song, Amphur Sriracha | J20: CHONBURI, 700/20 | K20: THAILAND TAX ID:0205562018045 | L20: 1 | N20: =CONCATENATE(ADDRESS!$Q$1,E20,", '",F20,"', '",G20,"' , '",H20,"' , '",I20,"' , '",J20,"', '",K20,"', '",L20,"'") -> EXECUTE [dbo].[PG_CI_CUSTOMER] 0, 0, 0, 58, '2', 'YANGFENG AUTOMOTIVE INTERIOR SYSTEMS(THAILAND) CO.,LTD' , '700/20 WHA EASTERN SEABOARD INDUSTRIAL' , '1 M00 7 Tambol Khao Khan Song, Amphur Sriracha' , 'CHONBURI, 700/20', 'THAILAND TAX ID:0205562018045', '1'

Sheet CONTACT
A1: ??? | B1: L_DEBUG | C1: K_SISTEMA_EXE | D1: K_USUARIO_ACCION | E1: [K_CUSTOMER] | F1: [D_CUSTOMER_CONTACT_NAME] | G1: [CUSTOMER_CONTACT_PHONE_01] | H1: [CUSTOMER_CONTACT_PHONE_01_EXT] | I1: [CUSTOMER_CONTACT_EMAIL_01] | J1: [CUSTOMER_CONTACT_FAX_01] | K1: [C_CUSTOMER_CONTACT] | M1: EXECUTE [dbo].[ | N1: =TABLE!A1 -> PG_CI_CUSTOMER | O1: ] | P1: =CONCATENATE($M$1,$N$1,$O$1,B3, ", ", C3, ", ", D3, ", ", ) -> EXECUTE [dbo].[PG_CI_CUSTOMER] 0, 0, 0,
B2: - | C2: - | D2: - | E2: - | F2: - | G2: - | H2: - | I2: - | J2: - | K2: - | M2: ="-- ==========================================================" -> -- ==========================================================
B3: 0 | C3: 0 | D3: 0 | E3: 59 | F3: MAURICIO ESPINOSA | G3: 18773348706 | M3: =CONCATENATE(CONTACT!$P$1,E3,", '",F3,"', '",G3,"' , '",H3,"' , '",I3,"' , '",J3,"', '",K3,"'") -> EXECUTE [dbo].[PG_CI_CUSTOMER] 0, 0, 0, 59, 'MAURICIO ESPINOSA', '18773348706' , '' , '' , '', ''
B4: 0 | C4: 0 | D4: 0 | E4: 46 | I4: bkamali@kamaligroup.com | M4: =CONCATENATE(CONTACT!$P$1,E4,", '",F4,"', '",G4,"' , '",H4,"' , '",I4,"' , '",J4,"', '",K4,"'") -> EXECUTE [dbo].[PG_CI_CUSTOMER] 0, 0, 0, 46, '', '' , '' , 'bkamali@kamaligroup.com' , '', ''
B5: 0 | C5: 0 | D5: 0 | E5: 49 | F5: RUTH KAMALI | G5: 5166274000 | M5: =CONCATENATE(CONTACT!$P$1,E5,", '",F5,"', '",G5,"' , '",H5,"' , '",I5,"' , '",J5,"', '",K5,"'") -> EXECUTE [dbo].[PG_CI_CUSTOMER] 0, 0, 0, 49, 'RUTH KAMALI', '5166274000' , '' , '' , '', ''
B6: 0 | C6: 0 | D6: 0 | E6: 29 | G6: 5197333713 | J6: 5197335887 | M6: =CONCATENATE(CONTACT!$P$1,E6,", '",F6,"', '",G6,"' , '",H6,"' , '",I6,"' , '",J6,"', '",K6,"'") -> EXECUTE [dbo].[PG_CI_CUSTOMER] 0, 0, 0, 29, '', '5197333713' , '' , '' , '5197335887', ''
B7: 0 | C7: 0 | D7: 0 | E7: 33 | M7: =CONCATENATE(CONTACT!$P$1,E7,", '",F7,"', '",G7,"' , '",H7,"' , '",I7,"' , '",J7,"', '",K7,"'") -> EXECUTE [dbo].[PG_CI_CUSTOMER] 0, 0, 0, 33, '', '' , '' , '' , '', ''
B8: 0 | C8: 0 | D8: 0 | E8: 42 | F8: ROGELIO CORRAL | G8: 6563827522 | M8: =CONCATENATE(CONTACT!$P$1,E8,", '",F8,"', '",G8,"' , '",H8,"' , '",I8,"' , '",J8,"', '",K8,"'") -> EXECUTE [dbo].[PG_CI_CUSTOMER] 0, 0, 0, 42, 'ROGELIO CORRAL', '6563827522' , '' , '' , '', ''
B9: 0 | C9: 0 | D9: 0 | E9: 1 | F9: NIKKI OSTERLAND | G9: 2485857700 | J9: 2485855800 | M9: =CONCATENATE(CONTACT!$P$1,E9,", '",F9,"', '",G9,"' , '",H9,"' , '",I9,"' , '",J9,"', '",K9,"'") -> EXECUTE [dbo].[PG_CI_CUSTOMER] 0, 0, 0, 1, 'NIKKI OSTERLAND', '2485857700' , '' , '' , '2485855800', ''
B10: 0 | C10: 0 | D10: 0 | E10: 56 | I10: Office@daimayus.com | M10: =CONCATENATE(CONTACT!$P$1,E10,", '",F10,"', '",G10,"' , '",H10,"' , '",I10,"' , '",J10,"', '",K10,"'") -> EXECUTE [dbo].[PG_CI_CUSTOMER] 0, 0, 0, 56, '', '' , '' , 'Office@daimayus.com' , '', ''
B11: 0 | C11: 0 | D11: 0 | E11: 2 | G11: 9783565701 | J11: 9783569832 | M11: =CONCATENATE(CONTACT!$P$1,E11,", '",F11,"', '",G11,"' , '",H11,"' , '",I11,"' , '",J11,"', '",K11,"'") -> EXECUTE [dbo].[PG_CI_CUSTOMER] 0, 0, 0, 2, '', '9783565701' , '' , '' , '9783569832', ''
B12: 0 | C12: 0 | D12: 0 | E12: 57 | M12: =CONCATENATE(CONTACT!$P$1,E12,", '",F12,"', '",G12,"' , '",H12,"' , '",I12,"' , '",J12,"', '",K12,"'") -> EXECUTE [dbo].[PG_CI_CUSTOMER] 0, 0, 0, 57, '', '' , '' , '' , '', ''
B13: 0 | C13: 0 | D13: 0 | E13: 3 | F13: LUIS ENRIQUE HERNANDEZ | M13: =CONCATENATE(CONTACT!$P$1,E13,", '",F13,"', '",G13,"' , '",H13,"' , '",I13,"' , '",J13,"', '",K13,"'") -> EXECUTE [dbo].[PG_CI_CUSTOMER] 0, 0, 0, 3, 'LUIS ENRIQUE HERNANDEZ', '' , '' , '' , '', ''
B14: 0 | C14: 0 | D14: 0 | E14: 51 | F14: ACCOUNTS PAYABLE | M14: =CONCATENATE(CONTACT!$P$1,E14,", '",F14,"', '",G14,"' , '",H14,"' , '",I14,"' , '",J14,"', '",K14,"'") -> EXECUTE [dbo].[PG_CI_CUSTOMER] 0, 0, 0, 51, 'ACCOUNTS PAYABLE', '' , '' , '' , '', ''
B15: 0 | C15: 0 | D15: 0 | E15: 4 | G15: 4194245429 | J15: 4194223164 | M15: =CONCATENATE(CONTACT!$P$1,E15,", '",F15,"', '",G15,"' , '",H15,"' , '",I15,"' , '",J15,"', '",K15,"'") -> EXECUTE [dbo].[PG_CI_CUSTOMER] 0, 0, 0, 4, '', '4194245429' , '' , '' , '4194223164', ''
B16: 0 | C16: 0 | D16: 0 | E16: 5 | F16: WILLIS I SIMMONS | G16: 9416766081 | J16: 9416766463 | M16: =CONCATENATE(CONTACT!$P$1,E16,", '",F16,"', '",G16,"' , '",H16,"' , '",I16,"' , '",J16,"', '",K16,"'") -> EXECUTE [dbo].[PG_CI_CUSTOMER] 0, 0, 0, 5, 'WILLIS I SIMMONS', '9416766081' , '' , '' , '9416766463', ''
B17: 0 | C17: 0 | D17: 0 | E17: 6 | F17: ROSA BOURDEAU | M17: =CONCATENATE(CONTACT!$P$1,E17,", '",F17,"', '",G17,"' , '",H17,"' , '",I17,"' , '",J17,"', '",K17,"'") -> EXECUTE [dbo].[PG_CI_CUSTOMER] 0, 0, 0, 6, 'ROSA BOURDEAU', '' , '' , '' , '', ''
B18: 0 | C18: 0 | D18: 0 | E18: 40 | F18: CLEMENCIA VIVEROS | G18: 522414184600 | H18: 3654 | J18: 522414127291 | M18: =CONCATENATE(CONTACT!$P$1,E18,", '",F18,"', '",G18,"' , '",H18,"' , '",I18,"' , '",J18,"', '",K18,"'") -> EXECUTE [dbo].[PG_CI_CUSTOMER] 0, 0, 0, 40, 'CLEMENCIA VIVEROS', '522414184600' , '3654' , '' , '522414127291', ''
B19: 0 | C19: 0 | D19: 0 | E19: 54 | M19: =CONCATENATE(CONTACT!$P$1,E19,", '",F19,"', '",G19,"' , '",H19,"' , '",I19,"' , '",J19,"', '",K19,"'") -> EXECUTE [dbo].[PG_CI_CUSTOMER] 0, 0, 0, 54, '', '' , '' , '' , '', ''
B20: 0 | C20: 0 | D20: 0 | E20: 7 | F20: MARIA CLABORN | G20: 12484514216 | M20: =CONCATENATE(CONTACT!$P$1,E20,", '",F20,"', '",G20,"' , '",H20,"' , '",I20,"' , '",J20,"', '",K20,"'") -> EXECUTE [dbo].[PG_CI_CUSTOMER] 0, 0, 0, 7, 'MARIA CLABORN', '12484514216' , '' , '' , '', ''
B21: 0 | C21: 0 | D21: 0 | E21: 34 | F21: LISA BETH RUMPL | G21: 2484514276 | J21: 2484514230 | M21: =CONCATENATE(CONTACT!$P$1,E21,", '",F21,"', '",G21,"' , '",H21,"' , '",I21,"' , '",J21,"', '",K21,"'") -> EXECUTE [dbo].[PG_CI_CUSTOMER] 0, 0, 0, 34, 'LISA BETH RUMPL', '2484514276' , '' , '' , '2484514230', ''
B22: 0 | C22: 0 | D22: 0 | E22: 8 | G22: 5252847224 | J22: 5252847231 | M22: =CONCATENATE(CONTACT!$P$1,E22,", '",F22,"', '",G22,"' , '",H22,"' , '",I22,"' , '",J22,"', '",K22,"'") -> EXECUTE [dbo].[PG_CI_CUSTOMER] 0, 0, 0, 8, '', '5252847224' , '' , '' , '5252847231', ''
B23: 0 | C23: 0 | D23: 0 | E23: 32 | F23: RICARDO PEREZ | G23: 015552847154 | J23: 015552847210 | M23: =CONCATENATE(CONTACT!$P$1,E23,", '",F23,"', '",G23,"' , '",H23,"' , '",I23,"' , '",J23,"', '",K23,"'") -> EXECUTE [dbo].[PG_CI_CUSTOMER] 0, 0, 0, 32, 'RICARDO PEREZ', '015552847154' , '' , '' , '015552847210', ''
B24: 0 | C24: 0 | D24: 0 | E24: 9 | M24: =CONCATENATE(CONTACT!$P$1,E24,", '",F24,"', '",G24,"' , '",H24,"' , '",I24,"' , '",J24,"', '",K24,"'") -> EXECUTE [dbo].[PG_CI_CUSTOMER] 0, 0, 0, 9, '', '' , '' , '' , '', ''
B25: 0 | C25: 0 | D25: 0 | E25: 37 | F25: BETHANY SCOTT | M25: =CONCATENATE(CONTACT!$P$1,E25,", '",F25,"', '",G25,"' , '",H25,"' , '",I25,"' , '",J25,"', '",K25,"'") -> EXECUTE [dbo].[PG_CI_CUSTOMER] 0, 0, 0, 37, 'BETHANY SCOTT', '' , '' , '' , '', ''
B26: 0 | C26: 0 | D26: 0 | E26: 38 | F26: MIKE CHOPSON | M26: =CONCATENATE(CONTACT!$P$1,E26,", '",F26,"', '",G26,"' , '",H26,"' , '",I26,"' , '",J26,"', '",K26,"'") -> EXECUTE [dbo].[PG_CI_CUSTOMER] 0, 0, 0, 38, 'MIKE CHOPSON', '' , '' , '' , '', ''
B27: 0 | C27: 0 | D27: 0 | E27: 48 | F27: RUTH KAMALI | M27: =CONCATENATE(CONTACT!$P$1,E27,", '",F27,"', '",G27,"' , '",H27,"' , '",I27,"' , '",J27,"', '",K27,"'") -> EXECUTE [dbo].[PG_CI_CUSTOMER] 0, 0, 0, 48, 'RUTH KAMALI', '' , '' , '' , '', ''
B28: 0 | C28: 0 | D28: 0 | E28: 39 | F28: DAVE SCHUTTER | G28: 12486153090 | J28: 12486153098 | M28: =CONCATENATE(CONTACT!$P$1,E28,", '",F28,"', '",G28,"' , '",H28,"' , '",I28,"' , '",J28,"', '",K28,"'") -> EXECUTE [dbo].[PG_CI_CUSTOMER] 0, 0, 0, 39, 'DAVE SCHUTTER', '12486153090' , '' , '' , '12486153098', ''
B29: 0 | C29: 0 | D29: 0 | E29: 10 | F29: STEVE KRAFT | G29: 5175457500 | J29: 5175458199 | M29: =CONCATENATE(CONTACT!$P$1,E29,", '",F29,"', '",G29,"' , '",H29,"' , '",I29,"' , '",J29,"', '",K29,"'") -> EXECUTE [dbo].[PG_CI_CUSTOMER] 0, 0, 0, 10, 'STEVE KRAFT', '5175457500' , '' , '' , '5175458199', ''
B30: 0 | C30: 0 | D30: 0 | E30: 11 | G30: 9154994545 | J30: 9158495610 | M30: =CONCATENATE(CONTACT!$P$1,E30,", '",F30,"', '",G30,"' , '",H30,"' , '",I30,"' , '",J30,"', '",K30,"'") -> EXECUTE [dbo].[PG_CI_CUSTOMER] 0, 0, 0, 11, '', '9154994545' , '' , '' , '9158495610', ''
B31: 0 | C31: 0 | D31: 0 | E31: 30 | F31: DAVID RAMOS | M31: =CONCATENATE(CONTACT!$P$1,E31,", '",F31,"', '",G31,"' , '",H31,"' , '",I31,"' , '",J31,"', '",K31,"'") -> EXECUTE [dbo].[PG_CI_CUSTOMER] 0, 0, 0, 30, 'DAVID RAMOS', '' , '' , '' , '', ''
B32: 0 | C32: 0 | D32: 0 | E32: 12 | F32: CATHY SADLER | M32: =CONCATENATE(CONTACT!$P$1,E32,", '",F32,"', '",G32,"' , '",H32,"' , '",I32,"' , '",J32,"', '",K32,"'") -> EXECUTE [dbo].[PG_CI_CUSTOMER] 0, 0, 0, 12, 'CATHY SADLER', '' , '' , '' , '', ''
B33: 0 | C33: 0 | D33: 0 | E33: 13 | M33: =CONCATENATE(CONTACT!$P$1,E33,", '",F33,"', '",G33,"' , '",H33,"' , '",I33,"' , '",J33,"', '",K33,"'") -> EXECUTE [dbo].[PG_CI_CUSTOMER] 0, 0, 0, 13, '', '' , '' , '' , '', ''
B34: 0 | C34: 0 | D34: 0 | E34: 14 | F34: Ms Daniela Olejnik | G34: 13137554909 | J34: 13137554898 | M34: =CONCATENATE(CONTACT!$P$1,E34,", '",F34,"', '",G34,"' , '",H34,"' , '",I34,"' , '",J34,"', '",K34,"'") -> EXECUTE [dbo].[PG_CI_CUSTOMER] 0, 0, 0, 14, 'Ms Daniela Olejnik', '13137554909' , '' , '' , '13137554898', ''
B35: 0 | C35: 0 | D35: 0 | E35: 15 | G35: 8105780400 | M35: =CONCATENATE(CONTACT!$P$1,E35,", '",F35,"', '",G35,"' , '",H35,"' , '",I35,"' , '",J35,"', '",K35,"'") -> EXECUTE [dbo].[PG_CI_CUSTOMER] 0, 0, 0, 15, '', '8105780400' , '' , '' , '', ''
B36: 0 | C36: 0 | D36: 0 | E36: 16 | F36: LILA MACKEY | G36: 3135939000 | J36: 3132535041 | M36: =CONCATENATE(CONTACT!$P$1,E36,", '",F36,"', '",G36,"' , '",H36,"' , '",I36,"' , '",J36,"', '",K36,"'") -> EXECUTE [dbo].[PG_CI_CUSTOMER] 0, 0, 0, 16, 'LILA MACKEY', '3135939000' , '' , '' , '3132535041', ''
B37: 0 | C37: 0 | D37: 0 | E37: 17 | F37: DOUG DEATON | G37: 0115286130319 | M37: =CONCATENATE(CONTACT!$P$1,E37,", '",F37,"', '",G37,"' , '",H37,"' , '",I37,"' , '",J37,"', '",K37,"'") -> EXECUTE [dbo].[PG_CI_CUSTOMER] 0, 0, 0, 17, 'DOUG DEATON', '0115286130319' , '' , '' , '', ''
B38: 0 | C38: 0 | D38: 0 | E38: 18 | M38: =CONCATENATE(CONTACT!$P$1,E38,", '",F38,"', '",G38,"' , '",H38,"' , '",I38,"' , '",J38,"', '",K38,"'") -> EXECUTE [dbo].[PG_CI_CUSTOMER] 0, 0, 0, 18, '', '' , '' , '' , '', ''
B39: 0 | C39: 0 | D39: 0 | E39: 19 | F39: MARILY BURKE | M39: =CONCATENATE(CONTACT!$P$1,E39,", '",F39,"', '",G39,"' , '",H39,"' , '",I39,"' , '",J39,"', '",K39,"'") -> EXECUTE [dbo].[PG_CI_CUSTOMER] 0, 0, 0, 19, 'MARILY BURKE', '' , '' , '' , '', ''
B40: 0 | C40: 0 | D40: 0 | E40: 47 | M40: =CONCATENATE(CONTACT!$P$1,E40,", '",F40,"', '",G40,"' , '",H40,"' , '",I40,"' , '",J40,"', '",K40,"'") -> EXECUTE [dbo].[PG_CI_CUSTOMER] 0, 0, 0, 47, '', '' , '' , '' , '', ''
...

Sheet Hoja1
A1: A4GLIdentity | B1: cus_no | D1: cus_name | E1: addr_1 | F1: addr_2 | G1: city | I1: state | J1: zip | K1: country | L1: contact | M1: contact_2 | N1: phone_no | O1: phone_no_2 | P1: phone_ext | Q1: phone_ext_2 | R1: fax_no | S1: start_dt | T1: slspsn_no | U1: cus_type_cd | V1: bal_meth | W1: stm_freq | X1: cr_lmt | Y1: cr_rating | Z1: hold_fg | AA1: collector | AB1: fin_chg_fg | AC1: cus_origin | AD1: filler_0003 | AE1: terr | AF1: curr_cd | AG1: par_cus_no | AH1: par_cus_fg | AI1: ship_via_cd | AJ1: ups_zone | AK1: ar_terms_cd | AL1: dsc_pct | AM1: ytd_dsc_given | AN1: txbl_fg | AO1: tax_cd | AP1: tax_cd_2 | AQ1: tax_cd_3 | AR1: exempt_no | AS1: sls_ptd | AT1: sls_ytd | AU1: sls_last_yr | AV1: cost_ptd | AW1: cost_ytd | AX1: cost_last_yr | AY1: balance | AZ1: high_balance | BA1: last_sale_dt | BB1: last_sale_amt | BC1: inv_ytd | BD1: inv_last_yr | BE1: paid_inv_ytd | BF1: last_pay_dt | BG1: last_pay_amt | BH1: avg_pay_ytd | BI1: avg_pay_last_yr | BJ1: last_stm_age_dt | BK1: amt_age_prd_1 | BL1: amt_age_prd_2 | BM1: amt_age_prd_3 | BN1: amt_age_prd_4 | BO1: allow_sb_item | BP1: allow_bo | BQ1: allow_part_ship | BR1: print_dunn_fg | BS1: cmt_1 | BT1: cmt_2 | BU1: vend_no | BV1: tax_sched | BW1: cr_card_1_desc | BX1: cr_card_1_acct | BY1: cr_card_1_exp_dt | BZ1: cr_card_2_desc | CA1: cr_card_2_acct | CB1: cr_card_2_exp_dt | CC1: user_def_fld_1 | CD1: user_def_fld_2 | CE1: user_def_fld_3 | CF1: user_def_fld_4 | CG1: user_def_fld_5 | CH1: dflt_inv_form | CI1: loc | CJ1: note_1 | CK1: note_2 | CL1: note_3 | CM1: note_4 | CN1: note_5 | CO1: user_dt | CP1: user_amount | CQ1: amt_age_oe_term | CR1: cus_alt_adr_cd | CS1: rfc_no | CT1: email_addr | CU1: filler_0002 | CV1: A4GLIdentity
A2: 59 | B2: ADIE01 | C2: ADIE01 | D2: 49200 | E2: 49200 HALYARD DRIVE.PLYMOUTH, | G2: PLYMOUTH | H2: PLYMOUTH | I2: MI | J2: 49200 | K2: EU | L2: MAURICIO ESPINOSA | N2: 18773348706 | S2: 20201216 | T2: 2 | U2: MCUEX | V2: O | W2: M | X2: 3000000 | Y2: =LEFT(S2,4) -> 2020 | Z2: =RIGHT(S2,4) -> 1216 | AA2: =LEFT(Z2,2) -> 12 | AB2: =RIGHT(Z2,2) -> 16 | AC2: =CONCATENATE(Y2,"-",AA2,"-",AB2) -> 2020-12-16 | AD2: NULL | AE2: US | AF2: USD | AG2: NULL | AH2: N | AI2: EXP | AJ2: NULL | AK2: 60 | AL2: 0 | AM2: 0 | AN2: N | AO2: 0 | AP2: NULL | AQ2: NULL | AR2: NULL | AS2: 0 | AT2: 0 | AU2: 0 | AV2: 0 | AW2: 0 | AX2: 0 | AY2: 0 | AZ2: 0 | BA2: 0 | BB2: 0 | BC2: 0 | BD2: 0 | BE2: 0 | BF2: 0 | BG2: 0 | BH2: NULL | BI2: NULL | BJ2: 0 | BK2: 0 | BL2: 0 | BM2: 0 | BN2: 0 | BO2: N | BP2: Y | BQ2: Y | BR2: N | BS2: NULL | BT2: NULL | BU2: NULL | BV2: NULL | BW2: NULL | BX2: NULL | BY2: 0 | BZ2: NULL | CA2: NULL | CB2: 0 | CC2: NULL | CD2: NULL | CE2: NULL | CF2: NULL | CG2: NULL | CH2: 26 | CI2: MFP | CJ2: NULL | CK2: NULL | CL2: NULL | CM2: NULL | CN2: NULL | CO2: 0 | CP2: 0 | CQ2: 0 | CR2: NULL | CS2: NULL | CU2: NULL | CV2: 59
A3: 46 | B3: ALGRP1 | C3: ALGRP1 | D3: 11021 | E3: 17 BARSTOWN ROAD | F3: NULL | G3: GREAT NECK STATES | H3: GREAT NECK STATES | I3: NY | J3: 11021 | K3: USA | L3: NULL | M3: NULL | O3: NULL | P3: NULL | Q3: NULL | R3: NULL | S3: 20150831 | T3: 2 | U3: MCUEX | V3: O | W3: M | X3: 3000000 | Y3: =LEFT(S3,4) -> 2015 | Z3: =RIGHT(S3,4) -> 0831 | AA3: =LEFT(Z3,2) -> 08 | AB3: =RIGHT(Z3,2) -> 31 | AC3: =CONCATENATE(Y3,"-",AA3,"-",AB3) -> 2015-08-31 | AD3: NULL | AE3: US | AF3: USD | AG3: NULL | AH3: N | AI3: LOC | AJ3: NULL | AK3: 5 | AL3: 0 | AM3: 0 | AN3: N | AO3: 0 | AP3: NULL | AQ3: NULL | AR3: NULL | AS3: 0 | AT3: 0 | AU3: 0 | AV3: 0 | AW3: 0 | AX3: 0 | AY3: 0 | AZ3: 0 | BA3: 20160531 | BB3: 0 | BC3: 0 | BD3: 0 | BE3: 0 | BF3: 0 | BG3: 0 | BH3: NULL | BI3: NULL | BJ3: 0 | BK3: 0 | BL3: 0 | BM3: 0 | BN3: 0 | BO3: N | BP3: Y | BQ3: Y | BR3: N | BS3: NULL | BT3: NULL | BU3: NULL | BV3: NULL | BW3: NULL | BX3: NULL | BY3: 0 | BZ3: NULL | CA3: NULL | CB3: 0 | CC3: NULL | CD3: 69000000 | CE3: NULL | CF3: NULL | CG3: NULL | CH3: 26 | CI3: MFP | CJ3: NULL | CK3: NULL | CL3: NULL | CM3: NULL | CN3: NULL | CO3: 0 | CP3: 0 | CQ3: 0 | CR3: NULL | CS3: NULL | CT3: bkamali@kamaligroup.com | CU3: NULL | CV3: 46
A4: 49 | B4: BILT01 | C4: BILT01 | D4: 11021 | E4: 17 BARSTOW RD. | F4: SUITE 206 | G4: GREAT NECK | H4: GREAT NECK | I4: NY | J4: 11021 | K4: USA | L4: RUTH KAMALI | M4: NULL | N4: 516-627-4000 | O4: NULL | P4: NULL | Q4: NULL | R4: NULL | S4: 20161208 | T4: 2 | U4: MISC | V4: O | W4: M | X4: NULL | Y4: =LEFT(S4,4) -> 2016 | Z4: =RIGHT(S4,4) -> 1208 | AA4: =LEFT(Z4,2) -> 12 | AB4: =RIGHT(Z4,2) -> 08 | AC4: =CONCATENATE(Y4,"-",AA4,"-",AB4) -> 2016-12-08 | AD4: NULL | AE4: NULL | AF4: AUD | AG4: NULL | AH4: N | AI4: LOC | AJ4: NULL | AK4: COD | AL4: 0 | AM4: 0 | AN4: N | AO4: 0 | AP4: NULL | AQ4: NULL | AR4: NULL | AS4: 0 | AT4: 0 | AU4: 0 | AV4: 0 | AW4: 0 | AX4: 0 | AY4: 3440 | AZ4: 3440 | BA4: 20170406 | BB4: 1940 | BC4: 0 | BD4: 0 | BE4: 0 | BF4: 0 | BG4: 0 | BH4: NULL | BI4: NULL | BJ4: 0 | BK4: 0 | BL4: 0 | BM4: 0 | BN4: 0 | BO4: N | BP4: Y | BQ4: Y | BR4: N | BS4: NULL | BT4: NULL | BU4: NULL | BV4: NULL | BW4: NULL | BX4: NULL | BY4: 0 | BZ4: NULL | CA4: NULL | CB4: 0 | CC4: NULL | CD4: 69000000 | CE4: NULL | CF4: NULL | CG4: NULL | CH4: 26 | CI4: NULL | CJ4: NULL | CK4: NULL | CL4: NULL | CM4: NULL | CN4: NULL | CO4: 0 | CP4: 0 | CQ4: 0 | CR4: NULL | CS4: NULL | CT4: NULL | CU4: NULL | CV4: 49
