Workbook

Sheet Hoja1
A5: #NO | B5: A4GLIdentity | C5: cus_no | D5: modelno/PROGRAMA | E5: modeldesc | F5: OPCIÓN 1 | H5: ,
A6: 1 | B6: 46 | C6: ALGRP1 | D6: WD7 | E6: 2021 WL DL 75 VPD | F6: 46 | G6: EXECUTE [dbo].[PG_CI_ARCUSFIL_PROGRAM] 0, 0, | H6: =_xlfn.CONCAT(G6,"'",D6,"'",$H$5,"'",TRIM(E6),"'",$H$5,F6) -> EXECUTE [dbo].[PG_CI_ARCUSFIL_PROGRAM] 0, 0, 'WD7','2021 WL DL 75 VPD',46
A7: 2 | B7: 1 | C7: CNII01 | D7: 77H | E7: U377 FORD HEADREST | F7: 1 | G7: EXECUTE [dbo].[PG_CI_ARCUSFIL_PROGRAM] 0, 0, | H7: =_xlfn.CONCAT(G7,"'",D7,"'",$H$5,"'",TRIM(E7),"'",$H$5,F7) -> EXECUTE [dbo].[PG_CI_ARCUSFIL_PROGRAM] 0, 0, '77H','U377 FORD HEADREST',1
A8: 3 | B8: 56 | C8: DAIM05 | D8: WDK | E8: 2021 WK WD 2ND ROW ARMREST | F8: 56 | G8: EXECUTE [dbo].[PG_CI_ARCUSFIL_PROGRAM] 0, 0, | H8: =_xlfn.CONCAT(G8,"'",D8,"'",$H$5,"'",TRIM(E8),"'",$H$5,F8) -> EXECUTE [dbo].[PG_CI_ARCUSFIL_PROGRAM] 0, 0, 'WDK','2021 WK WD 2ND ROW ARMREST',56
A9: 4 | B9: 57 | C9: EISS01 | D9: WLE | E9: 2021 WL EISMANN | F9: 57 | G9: EXECUTE [dbo].[PG_CI_ARCUSFIL_PROGRAM] 0, 0, | H9: =_xlfn.CONCAT(G9,"'",D9,"'",$H$5,"'",TRIM(E9),"'",$H$5,F9) -> EXECUTE [dbo].[PG_CI_ARCUSFIL_PROGRAM] 0, 0, 'WLE','2021 WL EISMANN',57
A10: 5 | B10: 51 | C10: FAUR01 | D10: C3A | E10: 2021 WS BL-GL EEP 3RD ROW | F10: 51 | G10: EXECUTE [dbo].[PG_CI_ARCUSFIL_PROGRAM] 0, 0, | H10: =_xlfn.CONCAT(G10,"'",D10,"'",$H$5,"'",TRIM(E10),"'",$H$5,F10) -> EXECUTE [dbo].[PG_CI_ARCUSFIL_PROGRAM] 0, 0, 'C3A','2021 WS BL-GL EEP 3RD ROW',51
A11: 6 | B11: 51 | C11: FAUR01 | D11: C3B | E11: 2021 WS AL JEEP 3RD ROW | F11: 51 | G11: EXECUTE [dbo].[PG_CI_ARCUSFIL_PROGRAM] 0, 0, | H11: =_xlfn.CONCAT(G11,"'",D11,"'",$H$5,"'",TRIM(E11),"'",$H$5,F11) -> EXECUTE [dbo].[PG_CI_ARCUSFIL_PROGRAM] 0, 0, 'C3B','2021 WS AL JEEP 3RD ROW',51
A12: 7 | B12: 51 | C12: FAUR01 | D12: FW2 | E12: 2021 WS JEEP SL NEVER QUILTED | F12: 51 | G12: EXECUTE [dbo].[PG_CI_ARCUSFIL_PROGRAM] 0, 0, | H12: =_xlfn.CONCAT(G12,"'",D12,"'",$H$5,"'",TRIM(E12),"'",$H$5,F12) -> EXECUTE [dbo].[PG_CI_ARCUSFIL_PROGRAM] 0, 0, 'FW2','2021 WS JEEP SL NEVER QUILTED',51
A13: 8 | B13: 51 | C13: FAUR01 | D13: FWS | E13: 2021 WS AL JEEP BASE | F13: 51 | G13: EXECUTE [dbo].[PG_CI_ARCUSFIL_PROGRAM] 0, 0, | H13: =_xlfn.CONCAT(G13,"'",D13,"'",$H$5,"'",TRIM(E13),"'",$H$5,F13) -> EXECUTE [dbo].[PG_CI_ARCUSFIL_PROGRAM] 0, 0, 'FWS','2021 WS AL JEEP BASE',51
A14: 9 | B14: 51 | C14: FAUR01 | D14: S3S | E14: 2021 WS SL JEEP 3RD ROW | F14: 51 | G14: EXECUTE [dbo].[PG_CI_ARCUSFIL_PROGRAM] 0, 0, | H14: =_xlfn.CONCAT(G14,"'",D14,"'",$H$5,"'",TRIM(E14),"'",$H$5,F14) -> EXECUTE [dbo].[PG_CI_ARCUSFIL_PROGRAM] 0, 0, 'S3S','2021 WS SL JEEP 3RD ROW',51
A15: 10 | B15: 51 | C15: FAUR01 | D15: S3U | E15: 2021 WS UL JEEP 3RD ROW | F15: 51 | G15: EXECUTE [dbo].[PG_CI_ARCUSFIL_PROGRAM] 0, 0, | H15: =_xlfn.CONCAT(G15,"'",D15,"'",$H$5,"'",TRIM(E15),"'",$H$5,F15) -> EXECUTE [dbo].[PG_CI_ARCUSFIL_PROGRAM] 0, 0, 'S3U','2021 WS UL JEEP 3RD ROW',51
A16: 11 | B16: 51 | C16: FAUR01 | D16: WS3 | E16: 2021 WS UL ALWAYS QUILTED | F16: 51 | G16: EXECUTE [dbo].[PG_CI_ARCUSFIL_PROGRAM] 0, 0, | H16: =_xlfn.CONCAT(G16,"'",D16,"'",$H$5,"'",TRIM(E16),"'",$H$5,F16) -> EXECUTE [dbo].[PG_CI_ARCUSFIL_PROGRAM] 0, 0, 'WS3','2021 WS UL ALWAYS QUILTED',51
A17: 12 | B17: 5 | C17: FIND02 | D17: MCY | E17: U364 MERCURY LTD FINDALY | F17: 5 | G17: EXECUTE [dbo].[PG_CI_ARCUSFIL_PROGRAM] 0, 0, | H17: =_xlfn.CONCAT(G17,"'",D17,"'",$H$5,"'",TRIM(E17),"'",$H$5,F17) -> EXECUTE [dbo].[PG_CI_ARCUSFIL_PROGRAM] 0, 0, 'MCY','U364 MERCURY LTD FINDALY',5
... A24: 19 | B24: 54 | C24: GRAM04 | D24: GWS | E24: 2021 WS GRAN WAGONNER | F24: 54 | G24: EXECUTE [dbo].[PG_CI_ARCUSFIL_PROGRAM] 0, 0, | H24: =_xlfn.CONCAT(G24,"'",D24,"'",$H$5,"'",TRIM(E24),"'",$H$5,F24) -> EXECUTE [dbo].[PG_CI_ARCUSFIL_PROGRAM] 0, 0, 'GWS','2021 WS GRAN WAGONNER',54
A25: 20 | B25: 7 | C25: IRVI02 | D25: 193 | E25: GMT 193 2007 | F25: 7 | G25: EXECUTE [dbo].[PG_CI_ARCUSFIL_PROGRAM] 0, 0, | H25: =_xlfn.CONCAT(G25,"'",D25,"'",$H$5,"'",TRIM(E25),"'",$H$5,F25) -> EXECUTE [dbo].[PG_CI_ARCUSFIL_PROGRAM] 0, 0, '193','GMT 193 2007',7
A26: 21 | B26: 7 | C26: IRVI02 | D26: 87C | E26: U387 FORD CUTTING EDGE | F26: 7 | G26: EXECUTE [dbo].[PG_CI_ARCUSFIL_PROGRAM] 0, 0, | H26: =_xlfn.CONCAT(G26,"'",D26,"'",$H$5,"'",TRIM(E26),"'",$H$5,F26) -> EXECUTE [dbo].[PG_CI_ARCUSFIL_PROGRAM] 0, 0, '87C','U387 FORD CUTTING EDGE',7
A27: 22 | B27: 7 | C27: IRVI02 | D27: 87P | E27: U387 FORD PREMIUM | F27: 7 | G27: EXECUTE [dbo].[PG_CI_ARCUSFIL_PROGRAM] 0, 0, | H27: =_xlfn.CONCAT(G27,"'",D27,"'",$H$5,"'",TRIM(E27),"'",$H$5,F27) -> EXECUTE [dbo].[PG_CI_ARCUSFIL_PROGRAM] 0, 0, '87P','U387 FORD PREMIUM',7
A28: 23 | B28: 7 | C28: IRVI02 | D28: 88A | E28: U388 LINCOLN ARMREST | F28: 7 | G28: EXECUTE [dbo].[PG_CI_ARCUSFIL_PROGRAM] 0, 0, | H28: =_xlfn.CONCAT(G28,"'",D28,"'",$H$5,"'",TRIM(E28),"'",$H$5,F28) -> EXECUTE [dbo].[PG_CI_ARCUSFIL_PROGRAM] 0, 0, '88A','U388 LINCOLN ARMREST',7
A29: 24 | B29: 7 | C29: IRVI02 | D29: 88H | E29: U388 HEADREST | F29: 7 | G29: EXECUTE [dbo].[PG_CI_ARCUSFIL_PROGRAM] 0, 0, | H29: =_xlfn.CONCAT(G29,"'",D29,"'",$H$5,"'",TRIM(E29),"'",$H$5,F29) -> EXECUTE [dbo].[PG_CI_ARCUSFIL_PROGRAM] 0, 0, '88H','U388 HEADREST',7
A30: 25 | B30: 7 | C30: IRVI02 | D30: 88L | E30: U388 LINCOLN LIMITED | F30: 7 | G30: EXECUTE [dbo].[PG_CI_ARCUSFIL_PROGRAM] 0, 0, | H30: =_xlfn.CONCAT(G30,"'",D30,"'",$H$5,"'",TRIM(E30),"'",$H$5,F30) -> EXECUTE [dbo].[PG_CI_ARCUSFIL_PROGRAM] 0, 0, '88L','U388 LINCOLN LIMITED',7
A31: 26 | B31: 7 | C31: IRVI02 | D31: GM1 | E31: GMT 191 PONTIAC TORRENT | F31: 7 | G31: EXECUTE [dbo].[PG_CI_ARCUSFIL_PROGRAM] 0, 0, | H31: =_xlfn.CONCAT(G31,"'",D31,"'",$H$5,"'",TRIM(E31),"'",$H$5,F31) -> EXECUTE [dbo].[PG_CI_ARCUSFIL_PROGRAM] 0, 0, 'GM1','GMT 191 PONTIAC TORRENT',7
A32: 27 | B32: 7 | C32: IRVI02 | D32: GM2 | E32: GMT 192 PONTIAC PERSUIT | F32: 7 | G32: EXECUTE [dbo].[PG_CI_ARCUSFIL_PROGRAM] 0, 0, | H32: =_xlfn.CONCAT(G32,"'",D32,"'",$H$5,"'",TRIM(E32),"'",$H$5,F32) -> EXECUTE [dbo].[PG_CI_ARCUSFIL_PROGRAM] 0, 0, 'GM2','GMT 192 PONTIAC PERSUIT',7
A33: 28 | B33: 7 | C33: IRVI02 | D33: GM3 | E33: ARMREST GMT 193 | F33: 7 | G33: EXECUTE [dbo].[PG_CI_ARCUSFIL_PROGRAM] 0, 0, | H33: =_xlfn.CONCAT(G33,"'",D33,"'",$H$5,"'",TRIM(E33),"'",$H$5,F33) -> EXECUTE [dbo].[PG_CI_ARCUSFIL_PROGRAM] 0, 0, 'GM3','ARMREST GMT 193',7
A34: 29 | B34: 7 | C34: IRVI02 | D34: GXP | E34: GMT 192 GXP 2008 | F34: 7 | G34: EXECUTE [dbo].[PG_CI_ARCUSFIL_PROGRAM] 0, 0, | H34: =_xlfn.CONCAT(G34,"'",D34,"'",$H$5,"'",TRIM(E34),"'",$H$5,F34) -> EXECUTE [dbo].[PG_CI_ARCUSFIL_PROGRAM] 0, 0, 'GXP','GMT 192 GXP 2008',7
A35: 30 | B35: 7 | C35: IRVI02 | D35: JJT | E35: 2019 JEEP JT | F35: 7 | G35: EXECUTE [dbo].[PG_CI_ARCUSFIL_PROGRAM] 0, 0, | H35: =_xlfn.CONCAT(G35,"'",D35,"'",$H$5,"'",TRIM(E35),"'",$H$5,F35) -> EXECUTE [dbo].[PG_CI_ARCUSFIL_PROGRAM] 0, 0, 'JJT','2019 JEEP JT',7
A36: 31 | B36: 7 | C36: IRVI02 | D36: JLI | E36: 2018 JEEP JL | F36: 7 | G36: EXECUTE [dbo].[PG_CI_ARCUSFIL_PROGRAM] 0, 0, | H36: =_xlfn.CONCAT(G36,"'",D36,"'",$H$5,"'",TRIM(E36),"'",$H$5,F36) -> EXECUTE [dbo].[PG_CI_ARCUSFIL_PROGRAM] 0, 0, 'JLI','2018 JEEP JL',7
A37: 32 | B37: 7 | C37: IRVI02 | D37: JPH | E37: 2020 JEEP JL PHEV | F37: 7 | G37: EXECUTE [dbo].[PG_CI_ARCUSFIL_PROGRAM] 0, 0, | H37: =_xlfn.CONCAT(G37,"'",D37,"'",$H$5,"'",TRIM(E37),"'",$H$5,F37) -> EXECUTE [dbo].[PG_CI_ARCUSFIL_PROGRAM] 0, 0, 'JPH','2020 JEEP JL PHEV',7
... A46: 41 | B46: 7 | C46: IRVI02 | D46: WLS | E46: WLS JEEP 2020 | F46: 7 | G46: EXECUTE [dbo].[PG_CI_ARCUSFIL_PROGRAM] 0, 0, | H46: =_xlfn.CONCAT(G46,"'",D46,"'",$H$5,"'",TRIM(E46),"'",$H$5,F46) -> EXECUTE [dbo].[PG_CI_ARCUSFIL_PROGRAM] 0, 0, 'WLS','WLS JEEP 2020',7
A47: 42 | B47: 34 | C47: IRVI03 | D47: 191 | E47: GMT 191 2008 | F47: 34 | G47: EXECUTE [dbo].[PG_CI_ARCUSFIL_PROGRAM] 0, 0, | H47: =_xlfn.CONCAT(G47,"'",D47,"'",$H$5,"'",TRIM(E47),"'",$H$5,F47) -> EXECUTE [dbo].[PG_CI_ARCUSFIL_PROGRAM] 0, 0, '191','GMT 191 2008',34
A48: 43 | B48: 34 | C48: IRVI03 | D48: 192 | E48: GMT 192 2008 | F48: 34 | G48: EXECUTE [dbo].[PG_CI_ARCUSFIL_PROGRAM] 0, 0, | H48: =_xlfn.CONCAT(G48,"'",D48,"'",$H$5,"'",TRIM(E48),"'",$H$5,F48) -> EXECUTE [dbo].[PG_CI_ARCUSFIL_PROGRAM] 0, 0, '192','GMT 192 2008',34
A49: 44 | B49: 34 | C49: IRVI03 | D49: ARM | E49: ARMREST GMT 193 | F49: 34 | G49: EXECUTE [dbo].[PG_CI_ARCUSFIL_PROGRAM] 0, 0, | H49: =_xlfn.CONCAT(G49,"'",D49,"'",$H$5,"'",TRIM(E49),"'",$H$5,F49) -> EXECUTE [dbo].[PG_CI_ARCUSFIL_PROGRAM] 0, 0, 'ARM','ARMREST GMT 193',34
A50: 45 | B50: 34 | C50: IRVI03 | D50: G93 | E50: GMT 193 2008 | F50: 34 | G50: EXECUTE [dbo].[PG_CI_ARCUSFIL_PROGRAM] 0, 0, | H50: =_xlfn.CONCAT(G50,"'",D50,"'",$H$5,"'",TRIM(E50),"'",$H$5,F50) -> EXECUTE [dbo].[PG_CI_ARCUSFIL_PROGRAM] 0, 0, 'G93','GMT 193 2008',34
A51: 46 | B51: 34 | C51: IRVI03 | D51: GX2 | E51: GMT 192 GXP 2008 | F51: 34 | G51: EXECUTE [dbo].[PG_CI_ARCUSFIL_PROGRAM] 0, 0, | H51: =_xlfn.CONCAT(G51,"'",D51,"'",$H$5,"'",TRIM(E51),"'",$H$5,F51) -> EXECUTE [dbo].[PG_CI_ARCUSFIL_PROGRAM] 0, 0, 'GX2','GMT 192 GXP 2008',34
A52: 47 | B52: 32 | C52: JOHN01 | D52: PL0 | E52: U388 CONSOLE | F52: 32 | G52: EXECUTE [dbo].[PG_CI_ARCUSFIL_PROGRAM] 0, 0, | H52: =_xlfn.CONCAT(G52,"'",D52,"'",$H$5,"'",TRIM(E52),"'",$H$5,F52) -> EXECUTE [dbo].[PG_CI_ARCUSFIL_PROGRAM] 0, 0, 'PL0','U388 CONSOLE',32
A53: 48 | B53: 9 | C53: JOHN02 | D53: 114 | E53: EN114 CONSOLE JCI | F53: 9 | G53: EXECUTE [dbo].[PG_CI_ARCUSFIL_PROGRAM] 0, 0, | H53: =_xlfn.CONCAT(G53,"'",D53,"'",$H$5,"'",TRIM(E53),"'",$H$5,F53) -> EXECUTE [dbo].[PG_CI_ARCUSFIL_PROGRAM] 0, 0, '114','EN114 CONSOLE JCI',9
A54: 49 | B54: 9 | C54: JOHN02 | D54: CHI | E54: GM360 CHEVY / ISUZU /GMC CHINA | F54: 9 | G54: EXECUTE [dbo].[PG_CI_ARCUSFIL_PROGRAM] 0, 0, | H54: =_xlfn.CONCAT(G54,"'",D54,"'",$H$5,"'",TRIM(E54),"'",$H$5,F54) -> EXECUTE [dbo].[PG_CI_ARCUSFIL_PROGRAM] 0, 0, 'CHI','GM360 CHEVY / ISUZU /GMC CHINA',9
A55: 50 | B55: 9 | C55: JOHN02 | D55: JCT | E55: JCI-TESLA | F55: 9 | G55: EXECUTE [dbo].[PG_CI_ARCUSFIL_PROGRAM] 0, 0, | H55: =_xlfn.CONCAT(G55,"'",D55,"'",$H$5,"'",TRIM(E55),"'",$H$5,F55) -> EXECUTE [dbo].[PG_CI_ARCUSFIL_PROGRAM] 0, 0, 'JCT','JCI-TESLA',9
A56: 51 | B56: 37 | C56: JOHN03 | D56: 228 | E56: U228 NAVIGATOR LUX/ULT | F56: 37 | G56: EXECUTE [dbo].[PG_CI_ARCUSFIL_PROGRAM] 0, 0, | H56: =_xlfn.CONCAT(G56,"'",D56,"'",$H$5,"'",TRIM(E56),"'",$H$5,F56) -> EXECUTE [dbo].[PG_CI_ARCUSFIL_PROGRAM] 0, 0, '228','U228 NAVIGATOR LUX/ULT',37
A57: 52 | B57: 37 | C57: JOHN03 | D57: 415 | E57: P415 PLATINIUM | F57: 37 | G57: EXECUTE [dbo].[PG_CI_ARCUSFIL_PROGRAM] 0, 0, | H57: =_xlfn.CONCAT(G57,"'",D57,"'",$H$5,"'",TRIM(E57),"'",$H$5,F57) -> EXECUTE [dbo].[PG_CI_ARCUSFIL_PROGRAM] 0, 0, '415','P415 PLATINIUM',37
A58: 53 | B58: 37 | C58: JOHN03 | D58: BUI | E58: GM 360 BUICK | F58: 37 | G58: EXECUTE [dbo].[PG_CI_ARCUSFIL_PROGRAM] 0, 0, | H58: =_xlfn.CONCAT(G58,"'",D58,"'",$H$5,"'",TRIM(E58),"'",$H$5,F58) -> EXECUTE [dbo].[PG_CI_ARCUSFIL_PROGRAM] 0, 0, 'BUI','GM 360 BUICK',37
...

Sheet PROGRAMAS
A2: A4GLIdentity | B2: CUSTOMER | C2: PROGRAM
A3: 46 | B3: ALGRP1 | C3: WL
A4: 1 | B4: CNII01 | C4: U377
A5: 56 | B5: DAIM05 | C5: WK
A6: 57 | B6: EISS01 | C6: WL
A7: 51 | B7: FAUR01 | C7: WS
A8: 5 | B8: FIND02 | C8: U364
A9: 40 | B9: GRAM01 | C9: U388
A10: 54 | B10: GRAM04 | C10: WL
A11: 54 | B11: GRAM04 | C11: WS
A12: 7 | B12: IRVI02 | C12: GMT
A13: 7 | B13: IRVI02 | C13: JL
A14: 7 | B14: IRVI02 | C14: JT
... A52: 58 | B52: YANG03 | C52: WL

Sheet MODELOS
A2: A4GLIdentity | B2: CUSTOMER | C2: FILTRO X | D2: PROGRAM | F2: MODEL | G2: DESCRIPTION_MODEL | J2: INSER PARA CI_PROGRAMAS SE ACTIVAS EL FILTRO X
A3: 46 | B3: ALGRP1 | C3: X | D3: WL | E3: 1 | F3: WD7 | G3: 2021 WL DL 75 VPD | I3: EXECUTE [dbo].[PG_CI_ARCUSFIL_PROGRAM] 0, 0, | J3: =_xlfn.CONCAT(I3,A3,", '",TRIM(D3),"'") -> EXECUTE [dbo].[PG_CI_ARCUSFIL_PROGRAM] 0, 0, 46, 'WL' | K3: . | L3: EXECUTE [dbo].[PG_CI_ARCUSFIL_PROGRAM_MODEL] 0, 0, | M3: =_xlfn.CONCAT(L3,E3,", '",TRIM(F3),"', '",TRIM(G3),"'") -> EXECUTE [dbo].[PG_CI_ARCUSFIL_PROGRAM_MODEL] 0, 0, 1, 'WD7', '2021 WL DL 75 VPD'
A4: 1 | B4: CNII01 | C4: X | D4: U377 | E4: 2 | F4: 77H | G4: U377 FORD HEADREST | I4: EXECUTE [dbo].[PG_CI_ARCUSFIL_PROGRAM] 0, 0, | J4: =_xlfn.CONCAT(I4,A4,", '",TRIM(D4),"'") -> EXECUTE [dbo].[PG_CI_ARCUSFIL_PROGRAM] 0, 0, 1, 'U377' | K4: . | L4: EXECUTE [dbo].[PG_CI_ARCUSFIL_PROGRAM_MODEL] 0, 0, | M4: =_xlfn.CONCAT(L4,E4,", '",TRIM(F4),"', '",TRIM(G4),"'") -> EXECUTE [dbo].[PG_CI_ARCUSFIL_PROGRAM_MODEL] 0, 0, 2, '77H', 'U377 FORD HEADREST'
A5: 56 | B5: DAIM05 | C5: X | D5: WK | E5: 3 | F5: WDK | G5: 2021 WK WD 2ND ROW ARMREST | I5: EXECUTE [dbo].[PG_CI_ARCUSFIL_PROGRAM] 0, 0, | J5: =_xlfn.CONCAT(I5,A5,", '",TRIM(D5),"'") -> EXECUTE [dbo].[PG_CI_ARCUSFIL_PROGRAM] 0, 0, 56, 'WK' | K5: . | L5: EXECUTE [dbo].[PG_CI_ARCUSFIL_PROGRAM_MODEL] 0, 0, | M5: =_xlfn.CONCAT(L5,E5,", '",TRIM(F5),"', '",TRIM(G5),"'") -> EXECUTE [dbo].[PG_CI_ARCUSFIL_PROGRAM_MODEL] 0, 0, 3, 'WDK', '2021 WK WD 2ND ROW ARMREST'
A6: 57 | B6: EISS01 | C6: X | D6: WL | E6: 4 | F6: WLE | G6: 2021 WL EISMANN | I6: EXECUTE [dbo].[PG_CI_ARCUSFIL_PROGRAM] 0, 0, | J6: =_xlfn.CONCAT(I6,A6,", '",TRIM(D6),"'") -> EXECUTE [dbo].[PG_CI_ARCUSFIL_PROGRAM] 0, 0, 57, 'WL' | K6: . | L6: EXECUTE [dbo].[PG_CI_ARCUSFIL_PROGRAM_MODEL] 0, 0, | M6: =_xlfn.CONCAT(L6,E6,", '",TRIM(F6),"', '",TRIM(G6),"'") -> EXECUTE [dbo].[PG_CI_ARCUSFIL_PROGRAM_MODEL] 0, 0, 4, 'WLE', '2021 WL EISMANN'
A7: 51 | B7: FAUR01 | C7: X | D7: WS | E7: 5 | F7: C3A | G7: 2021 WS BL-GL EEP 3RD ROW | I7: EXECUTE [dbo].[PG_CI_ARCUSFIL_PROGRAM] 0, 0, | J7: =_xlfn.CONCAT(I7,A7,", '",TRIM(D7),"'") -> EXECUTE [dbo].[PG_CI_ARCUSFIL_PROGRAM] 0, 0, 51, 'WS' | K7: . | L7: EXECUTE [dbo].[PG_CI_ARCUSFIL_PROGRAM_MODEL] 0, 0, | M7: =_xlfn.CONCAT(L7,E7,", '",TRIM(F7),"', '",TRIM(G7),"'") -> EXECUTE [dbo].[PG_CI_ARCUSFIL_PROGRAM_MODEL] 0, 0, 5, 'C3A', '2021 WS BL-GL EEP 3RD ROW'
A8: 51 | B8: FAUR01 | D8: WS | E8: 5 | F8: C3B | G8: 2021 WS AL JEEP 3RD ROW | K8: . | L8: EXECUTE [dbo].[PG_CI_ARCUSFIL_PROGRAM_MODEL] 0, 0, | M8: =_xlfn.CONCAT(L8,E8,", '",TRIM(F8),"', '",TRIM(G8),"'") -> EXECUTE [dbo].[PG_CI_ARCUSFIL_PROGRAM_MODEL] 0, 0, 5, 'C3B', '2021 WS AL JEEP 3RD ROW'
A9: 51 | B9: FAUR01 | D9: WS | E9: 5 | F9: FW2 | G9: 2021 WS JEEP SL NEVER QUILTED | K9: . | L9: EXECUTE [dbo].[PG_CI_ARCUSFIL_PROGRAM_MODEL] 0, 0, | M9: =_xlfn.CONCAT(L9,E9,", '",TRIM(F9),"', '",TRIM(G9),"'") -> EXECUTE [dbo].[PG_CI_ARCUSFIL_PROGRAM_MODEL] 0, 0, 5, 'FW2', '2021 WS JEEP SL NEVER QUILTED'
A10: 51 | B10: FAUR01 | D10: WS | E10: 5 | F10: FWS | G10: 2021 WS AL JEEP BASE | K10: . | L10: EXECUTE [dbo].[PG_CI_ARCUSFIL_PROGRAM_MODEL] 0, 0, | M10: =_xlfn.CONCAT(L10,E10,", '",TRIM(F10),"', '",TRIM(G10),"'") -> EXECUTE [dbo].[PG_CI_ARCUSFIL_PROGRAM_MODEL] 0, 0, 5, 'FWS', '2021 WS AL JEEP BASE'
A11: 51 | B11: FAUR01 | D11: WS | E11: 5 | F11: S3S | G11: 2021 WS SL JEEP 3RD ROW | K11: . | L11: EXECUTE [dbo].[PG_CI_ARCUSFIL_PROGRAM_MODEL] 0, 0, | M11: =_xlfn.CONCAT(L11,E11,", '",TRIM(F11),"', '",TRIM(G11),"'") -> EXECUTE [dbo].[PG_CI_ARCUSFIL_PROGRAM_MODEL] 0, 0, 5, 'S3S', '2021 WS SL JEEP 3RD ROW'
A12: 51 | B12: FAUR01 | D12: WS | E12: 5 | F12: S3U | G12: 2021 WS UL JEEP 3RD ROW | K12: . | L12: EXECUTE [dbo].[PG_CI_ARCUSFIL_PROGRAM_MODEL] 0, 0, | M12: =_xlfn.CONCAT(L12,E12,", '",TRIM(F12),"', '",TRIM(G12),"'") -> EXECUTE [dbo].[PG_CI_ARCUSFIL_PROGRAM_MODEL] 0, 0, 5, 'S3U', '2021 WS UL JEEP 3RD ROW'
A13: 51 | B13: FAUR01 | D13: WS | E13: 5 | F13: WS3 | G13: 2021 WS UL ALWAYS QUILTED | K13: . | L13: EXECUTE [dbo].[PG_CI_ARCUSFIL_PROGRAM_MODEL] 0, 0, | M13: =_xlfn.CONCAT(L13,E13,", '",TRIM(F13),"', '",TRIM(G13),"'") -> EXECUTE [dbo].[PG_CI_ARCUSFIL_PROGRAM_MODEL] 0, 0, 5, 'WS3', '2021 WS UL ALWAYS QUILTED'
A14: 5 | B14: FIND02 | C14: X | D14: U364 | E14: 6 | F14: MCY | G14: U364 MERCURY LTD FINDALY | I14: EXECUTE [dbo].[PG_CI_ARCUSFIL_PROGRAM] 0, 0, | J14: =_xlfn.CONCAT(I14,A14,", '",TRIM(D14),"'") -> EXECUTE [dbo].[PG_CI_ARCUSFIL_PROGRAM] 0, 0, 5, 'U364' | K14: . | L14: EXECUTE [dbo].[PG_CI_ARCUSFIL_PROGRAM_MODEL] 0, 0, | M14: =_xlfn.CONCAT(L14,E14,", '",TRIM(F14),"', '",TRIM(G14),"'") -> EXECUTE [dbo].[PG_CI_ARCUSFIL_PROGRAM_MODEL] 0, 0, 6, 'MCY', 'U364 MERCURY LTD FINDALY'
A15: 40 | B15: GRAM01 | C15: X | D15: U388 | E15: 7 | F15: GAR | G15: U388 LINCOLN ARMREST | I15: EXECUTE [dbo].[PG_CI_ARCUSFIL_PROGRAM] 0, 0, | J15: =_xlfn.CONCAT(I15,A15,", '",TRIM(D15),"'") -> EXECUTE [dbo].[PG_CI_ARCUSFIL_PROGRAM] 0, 0, 40, 'U388' | K15: . | L15: EXECUTE [dbo].[PG_CI_ARCUSFIL_PROGRAM_MODEL] 0, 0, | M15: =_xlfn.CONCAT(L15,E15,", '",TRIM(F15),"', '",TRIM(G15),"'") -> EXECUTE [dbo].[PG_CI_ARCUSFIL_PROGRAM_MODEL] 0, 0, 7, 'GAR', 'U388 LINCOLN ARMREST'
A16: 54 | B16: GRAM04 | C16: X | D16: WL | E16: 8 | F16: GR1 | G16: 2021 WL 75 QUADS 2ND. ROW ARMR | I16: EXECUTE [dbo].[PG_CI_ARCUSFIL_PROGRAM] 0, 0, | J16: =_xlfn.CONCAT(I16,A16,", '",TRIM(D16),"'") -> EXECUTE [dbo].[PG_CI_ARCUSFIL_PROGRAM] 0, 0, 54, 'WL' | K16: . | L16: EXECUTE [dbo].[PG_CI_ARCUSFIL_PROGRAM_MODEL] 0, 0, | M16: =_xlfn.CONCAT(L16,E16,", '",TRIM(F16),"', '",TRIM(G16),"'") -> EXECUTE [dbo].[PG_CI_ARCUSFIL_PROGRAM_MODEL] 0, 0, 8, 'GR1', '2021 WL 75 QUADS 2ND. ROW ARMR'
A17: 54 | B17: GRAM04 | D17: WL | E17: 8 | F17: GRM | G17: 2021 WL 74/75 2ND. ROW ARMREST | K17: . | L17: EXECUTE [dbo].[PG_CI_ARCUSFIL_PROGRAM_MODEL] 0, 0, | M17: =_xlfn.CONCAT(L17,E17,", '",TRIM(F17),"', '",TRIM(G17),"'") -> EXECUTE [dbo].[PG_CI_ARCUSFIL_PROGRAM_MODEL] 0, 0, 8, 'GRM', '2021 WL 74/75 2ND. ROW ARMREST'
A18: 54 | B18: GRAM04 | D18: WL | E18: 8 | F18: GW2 | G18: 2021 WL 75 QUADS 2ND. ROW AR | K18: . | L18: EXECUTE [dbo].[PG_CI_ARCUSFIL_PROGRAM_MODEL] 0, 0, | M18: =_xlfn.CONCAT(L18,E18,", '",TRIM(F18),"', '",TRIM(G18),"'") -> EXECUTE [dbo].[PG_CI_ARCUSFIL_PROGRAM_MODEL] 0, 0, 8, 'GW2', '2021 WL 75 QUADS 2ND. ROW AR'
A19: 54 | B19: GRAM04 | D19: WL | E19: 8 | F19: GWL | G19: 2021 WL 74/75 2ND. ROW ARMRE | K19: . | L19: EXECUTE [dbo].[PG_CI_ARCUSFIL_PROGRAM_MODEL] 0, 0, | M19: =_xlfn.CONCAT(L19,E19,", '",TRIM(F19),"', '",TRIM(G19),"'") -> EXECUTE [dbo].[PG_CI_ARCUSFIL_PROGRAM_MODEL] 0, 0, 8, 'GWL', '2021 WL 74/75 2ND. ROW ARMRE'
A20: 54 | B20: GRAM04 | C20: X | D20: WS | E20: 9 | F20: GR2 | G20: WS FOLDING 2ND-ROW ARM REST | I20: EXECUTE [dbo].[PG_CI_ARCUSFIL_PROGRAM] 0, 0, | J20: =_xlfn.CONCAT(I20,A20,", '",TRIM(D20),"'") -> EXECUTE [dbo].[PG_CI_ARCUSFIL_PROGRAM] 0, 0, 54, 'WS' | K20: . | L20: EXECUTE [dbo].[PG_CI_ARCUSFIL_PROGRAM_MODEL] 0, 0, | M20: =_xlfn.CONCAT(L20,E20,", '",TRIM(F20),"', '",TRIM(G20),"'") -> EXECUTE [dbo].[PG_CI_ARCUSFIL_PROGRAM_MODEL] 0, 0, 9, 'GR2', 'WS FOLDING 2ND-ROW ARM REST'
A21: 54 | B21: GRAM04 | D21: WS | E21: 9 | F21: GWS | G21: 2021 WS GRAN WAGONNER | K21: . | L21: EXECUTE [dbo].[PG_CI_ARCUSFIL_PROGRAM_MODEL] 0, 0, | M21: =_xlfn.CONCAT(L21,E21,", '",TRIM(F21),"', '",TRIM(G21),"'") -> EXECUTE [dbo].[PG_CI_ARCUSFIL_PROGRAM_MODEL] 0, 0, 9, 'GWS', '2021 WS GRAN WAGONNER'
A22: 7 | B22: IRVI02 | C22: X | D22: GMT | E22: 10 | F22: 193 | G22: GMT 193 2007 | I22: EXECUTE [dbo].[PG_CI_ARCUSFIL_PROGRAM] 0, 0, | J22: =_xlfn.CONCAT(I22,A22,", '",TRIM(D22),"'") -> EXECUTE [dbo].[PG_CI_ARCUSFIL_PROGRAM] 0, 0, 7, 'GMT' | K22: . | L22: EXECUTE [dbo].[PG_CI_ARCUSFIL_PROGRAM_MODEL] 0, 0, | M22: =_xlfn.CONCAT(L22,E22,", '",TRIM(F22),"', '",TRIM(G22),"'") -> EXECUTE [dbo].[PG_CI_ARCUSFIL_PROGRAM_MODEL] 0, 0, 10, '193', 'GMT 193 2007'
A23: 7 | B23: IRVI02 | D23: GMT | E23: 10 | F23: GM1 | G23: GMT 191 PONTIAC TORRENT | K23: . | L23: EXECUTE [dbo].[PG_CI_ARCUSFIL_PROGRAM_MODEL] 0, 0, | M23: =_xlfn.CONCAT(L23,E23,", '",TRIM(F23),"', '",TRIM(G23),"'") -> EXECUTE [dbo].[PG_CI_ARCUSFIL_PROGRAM_MODEL] 0, 0, 10, 'GM1', 'GMT 191 PONTIAC TORRENT'
A24: 7 | B24: IRVI02 | D24: GMT | E24: 10 | F24: GM2 | G24: GMT 192 PONTIAC PERSUIT | K24: . | L24: EXECUTE [dbo].[PG_CI_ARCUSFIL_PROGRAM_MODEL] 0, 0, | M24: =_xlfn.CONCAT(L24,E24,", '",TRIM(F24),"', '",TRIM(G24),"'") -> EXECUTE [dbo].[PG_CI_ARCUSFIL_PROGRAM_MODEL] 0, 0, 10, 'GM2', 'GMT 192 PONTIAC PERSUIT'
A25: 7 | B25: IRVI02 | D25: GMT | E25: 10 | F25: GM3 | G25: ARMREST GMT 193 | K25: . | L25: EXECUTE [dbo].[PG_CI_ARCUSFIL_PROGRAM_MODEL] 0, 0, | M25: =_xlfn.CONCAT(L25,E25,", '",TRIM(F25),"', '",TRIM(G25),"'") -> EXECUTE [dbo].[PG_CI_ARCUSFIL_PROGRAM_MODEL] 0, 0, 10, 'GM3', 'ARMREST GMT 193'
A26: 7 | B26: IRVI02 | D26: GMT | E26: 10 | F26: GXP | G26: GMT 192 GXP 2008 | K26: . | L26: EXECUTE [dbo].[PG_CI_ARCUSFIL_PROGRAM_MODEL] 0, 0, | M26: =_xlfn.CONCAT(L26,E26,", '",TRIM(F26),"', '",TRIM(G26),"'") -> EXECUTE [dbo].[PG_CI_ARCUSFIL_PROGRAM_MODEL] 0, 0, 10, 'GXP', 'GMT 192 GXP 2008'
A27: 7 | B27: IRVI02 | C27: X | D27: JL | E27: 11 | F27: JLI | G27: 2018 JEEP JL | I27: EXECUTE [dbo].[PG_CI_ARCUSFIL_PROGRAM] 0, 0, | J27: =_xlfn.CONCAT(I27,A27,", '",TRIM(D27),"'") -> EXECUTE [dbo].[PG_CI_ARCUSFIL_PROGRAM] 0, 0, 7, 'JL' | K27: . | L27: EXECUTE [dbo].[PG_CI_ARCUSFIL_PROGRAM_MODEL] 0, 0, | M27: =_xlfn.CONCAT(L27,E27,", '",TRIM(F27),"', '",TRIM(G27),"'") -> EXECUTE [dbo].[PG_CI_ARCUSFIL_PROGRAM_MODEL] 0, 0, 11, 'JLI', '2018 JEEP JL'
A28: 7 | B28: IRVI02 | D28: JL | E28: 11 | F28: JPH | G28: 2020 JEEP JL PHEV | K28: . | L28: EXECUTE [dbo].[PG_CI_ARCUSFIL_PROGRAM_MODEL] 0, 0, | M28: =_xlfn.CONCAT(L28,E28,", '",TRIM(F28),"', '",TRIM(G28),"'") -> EXECUTE [dbo].[PG_CI_ARCUSFIL_PROGRAM_MODEL] 0, 0, 11, 'JPH', '2020 JEEP JL PHEV'
A29: 7 | B29: IRVI02 | D29: JL | E29: 11 | F29: JPS | G29: 2021 JEEP JL PHEV SUMMIT | K29: . | L29: EXECUTE [dbo].[PG_CI_ARCUSFIL_PROGRAM_MODEL] 0, 0, | M29: =_xlfn.CONCAT(L29,E29,", '",TRIM(F29),"', '",TRIM(G29),"'") -> EXECUTE [dbo].[PG_CI_ARCUSFIL_PROGRAM_MODEL] 0, 0, 11, 'JPS', '2021 JEEP JL PHEV SUMMIT'
A30: 7 | B30: IRVI02 | D30: JL | E30: 11 | F30: JSU | G30: JEEPJL SUMMIT | K30: . | L30: EXECUTE [dbo].[PG_CI_ARCUSFIL_PROGRAM_MODEL] 0, 0, | M30: =_xlfn.CONCAT(L30,E30,", '",TRIM(F30),"', '",TRIM(G30),"'") -> EXECUTE [dbo].[PG_CI_ARCUSFIL_PROGRAM_MODEL] 0, 0, 11, 'JSU', 'JEEPJL SUMMIT'
A31: 7 | B31: IRVI02 | C31: X | D31: JT | E31: 12 | F31: JJT | G31: 2019 JEEP JT | I31: EXECUTE [dbo].[PG_CI_ARCUSFIL_PROGRAM] 0, 0, | J31: =_xlfn.CONCAT(I31,A31,", '",TRIM(D31),"'") -> EXECUTE [dbo].[PG_CI_ARCUSFIL_PROGRAM] 0, 0, 7, 'JT' | K31: . | L31: EXECUTE [dbo].[PG_CI_ARCUSFIL_PROGRAM_MODEL] 0, 0, | M31: =_xlfn.CONCAT(L31,E31,", '",TRIM(F31),"', '",TRIM(G31),"'") -> EXECUTE [dbo].[PG_CI_ARCUSFIL_PROGRAM_MODEL] 0, 0, 12, 'JJT', '2019 JEEP JT'
A32: 7 | B32: IRVI02 | D32: JT | E32: 12 | F32: JTM | G32: 2019 JEEP JT MOJAVE | K32: . | L32: EXECUTE [dbo].[PG_CI_ARCUSFIL_PROGRAM_MODEL] 0, 0, | M32: =_xlfn.CONCAT(L32,E32,", '",TRIM(F32),"', '",TRIM(G32),"'") -> EXECUTE [dbo].[PG_CI_ARCUSFIL_PROGRAM_MODEL] 0, 0, 12, 'JTM', '2019 JEEP JT MOJAVE'
A33: 7 | B33: IRVI02 | D33: JT | E33: 12 | F33: JTS | G33: 2021 JEEP JT SUMMIT | K33: . | L33: EXECUTE [dbo].[PG_CI_ARCUSFIL_PROGRAM_MODEL] 0, 0, | M33: =_xlfn.CONCAT(L33,E33,", '",TRIM(F33),"', '",TRIM(G33),"'") -> EXECUTE [dbo].[PG_CI_ARCUSFIL_PROGRAM_MODEL] 0, 0, 12, 'JTS', '2021 JEEP JT SUMMIT'
A34: 7 | B34: IRVI02 | C34: X | D34: U387 | E34: 13 | F34: 87C | G34: U387 FORD CUTTING EDGE | I34: EXECUTE [dbo].[PG_CI_ARCUSFIL_PROGRAM] 0, 0, | J34: =_xlfn.CONCAT(I34,A34,", '",TRIM(D34),"'") -> EXECUTE [dbo].[PG_CI_ARCUSFIL_PROGRAM] 0, 0, 7, 'U387' | K34: . | L34: EXECUTE [dbo].[PG_CI_ARCUSFIL_PROGRAM_MODEL] 0, 0, | M34: =_xlfn.CONCAT(L34,E34,", '",TRIM(F34),"', '",TRIM(G34),"'") -> EXECUTE [dbo].[PG_CI_ARCUSFIL_PROGRAM_MODEL] 0, 0, 13, '87C', 'U387 FORD CUTTING EDGE'
A35: 7 | B35: IRVI02 | D35: U387 | E35: 13 | F35: 87P | G35: U387 FORD PREMIUM | K35: . | L35: EXECUTE [dbo].[PG_CI_ARCUSFIL_PROGRAM_MODEL] 0, 0, | M35: =_xlfn.CONCAT(L35,E35,", '",TRIM(F35),"', '",TRIM(G35),"'") -> EXECUTE [dbo].[PG_CI_ARCUSFIL_PROGRAM_MODEL] 0, 0, 13, '87P', 'U387 FORD PREMIUM'
A36: 7 | B36: IRVI02 | C36: X | D36: U388 | E36: 14 | F36: 88A | G36: U388 LINCOLN ARMREST | I36: EXECUTE [dbo].[PG_CI_ARCUSFIL_PROGRAM] 0, 0, | J36: =_xlfn.CONCAT(I36,A36,", '",TRIM(D36),"'") -> EXECUTE [dbo].[PG_CI_ARCUSFIL_PROGRAM] 0, 0, 7, 'U388' | K36: . | L36: EXECUTE [dbo].[PG_CI_ARCUSFIL_PROGRAM_MODEL] 0, 0, | M36: =_xlfn.CONCAT(L36,E36,", '",TRIM(F36),"', '",TRIM(G36),"'") -> EXECUTE [dbo].[PG_CI_ARCUSFIL_PROGRAM_MODEL] 0, 0, 14, '88A', 'U388 LINCOLN ARMREST'
A37: 7 | B37: IRVI02 | D37: U388 | E37: 14 | F37: 88H | G37: U388 HEADREST | K37: . | L37: EXECUTE [dbo].[PG_CI_ARCUSFIL_PROGRAM_MODEL] 0, 0, | M37: =_xlfn.CONCAT(L37,E37,", '",TRIM(F37),"', '",TRIM(G37),"'") -> EXECUTE [dbo].[PG_CI_ARCUSFIL_PROGRAM_MODEL] 0, 0, 14, '88H', 'U388 HEADREST'
A38: 7 | B38: IRVI02 | D38: U388 | E38: 14 | F38: 88L | G38: U388 LINCOLN LIMITED | K38: . | L38: EXECUTE [dbo].[PG_CI_ARCUSFIL_PROGRAM_MODEL] 0, 0, | M38: =_xlfn.CONCAT(L38,E38,", '",TRIM(F38),"', '",TRIM(G38),"'") -> EXECUTE [dbo].[PG_CI_ARCUSFIL_PROGRAM_MODEL] 0, 0, 14, '88L', 'U388 LINCOLN LIMITED'
A39: 7 | B39: IRVI02 | C39: X | D39: V229 | E39: 15 | F39: VFL | G39: V229 FORD FREESTAR LTD | I39: EXECUTE [dbo].[PG_CI_ARCUSFIL_PROGRAM] 0, 0, | J39: =_xlfn.CONCAT(I39,A39,", '",TRIM(D39),"'") -> EXECUTE [dbo].[PG_CI_ARCUSFIL_PROGRAM] 0, 0, 7, 'V229' | K39: . | L39: EXECUTE [dbo].[PG_CI_ARCUSFIL_PROGRAM_MODEL] 0, 0, | M39: =_xlfn.CONCAT(L39,E39,", '",TRIM(F39),"', '",TRIM(G39),"'") -> EXECUTE [dbo].[PG_CI_ARCUSFIL_PROGRAM_MODEL] 0, 0, 15, 'VFL', 'V229 FORD FREESTAR LTD'
A40: 7 | B40: IRVI02 | D40: V229 | E40: 15 | F40: VML | G40: V229 FREESTAR MERCURY LTD | K40: . | L40: EXECUTE [dbo].[PG_CI_ARCUSFIL_PROGRAM_MODEL] 0, 0, | M40: =_xlfn.CONCAT(L40,E40,", '",TRIM(F40),"', '",TRIM(G40),"'") -> EXECUTE [dbo].[PG_CI_ARCUSFIL_PROGRAM_MODEL] 0, 0, 15, 'VML', 'V229 FREESTAR MERCURY LTD'
A41: 7 | B41: IRVI02 | D41: V229 | E41: 15 | F41: VMP | G41: V229 FREESTAR MPA | K41: . | L41: EXECUTE [dbo].[PG_CI_ARCUSFIL_PROGRAM_MODEL] 0, 0, | M41: =_xlfn.CONCAT(L41,E41,", '",TRIM(F41),"', '",TRIM(G41),"'") -> EXECUTE [dbo].[PG_CI_ARCUSFIL_PROGRAM_MODEL] 0, 0, 15, 'VMP', 'V229 FREESTAR MPA'
...

Sheet Hoja4
F2: K_ARCUSFIL_PROGRAM | G2: S_ARCUSFIL_PROGRAM
F3: 1 | G3: WL | H3: WL | I3: ALGRP1 | J3: X
F4: 2 | G4: U377 | H4: U377 | I4: CNII01 | J4: X
F5: 3 | G5: WK | H5: WK | I5: DAIM05 | J5: X
F6: 4 | G6: WL | H6: WL | I6: EISS01 | J6: X
F7: 5 | G7: WS | H7: WS | I7: FAUR01 | J7: X
F8: 6 | G8: U364 | H8: U364 | I8: FIND02 | J8: X
F9: 7 | G9: U388 | H9: U388 | I9: GRAM01 | J9: X
F10: 8 | G10: WL | H10: WL | I10: GRAM04 | J10: X
F11: 9 | G11: WS | H11: WS | I11: GRAM04 | J11: X
F12: 10 | G12: GMT | H12: GMT | I12: IRVI02 | J12: X
F13: 11 | G13: JL | H13: JL | I13: IRVI02 | J13: X
F14: 12 | G14: JT | H14: JT | I14: IRVI02 | J14: X
... F52: 50 | G52: WL | H52: WL | I52: YANG03 | J52: X

Sheet DATA_02
D2: cus_no | E2: modelno | F2: modeldesc | G2: versionno | H2: versiondesc | I2: changetype | J2: duedate | K2: contractutil | L2: custchglevel | M2: status | N2: currcode | O2: uom | P2: specstatus | Q2: CustRFQDate | R2: CustRFQNo | S2: notes1 | T2: notes2 | U2: notes3 | V2: notes4 | W2: notes5 | X2: spec_edit_fg | Y2: price_edit_fg | Z2: maint_edit_fg | AA2: modver_inherited | AB2: NoAPQP
A3: =VLOOKUP(E3,COTI!F:F,1,FALSE) -> 77H | D3: CNII01 | E3: 77H | F3: U377 FORD HEADREST | G3: 7 | H3: Pricing & Engineering Change | I3: B | J3: 20090505 | K3: 56 | L3: N/A | M3: L | N3: USD | O3: SF | P3: U | Q3: 20090505 | R3: N/A | S3: Engineering Change Folio 0309-191 | X3: Y | AA3: 77H0006 | AB3: NULL
A4: =VLOOKUP(E4,COTI!F:F,1,FALSE) -> WDK | D4: DAIM05 | E4: WDK | F4: 2021 WK WD 2ND ROW ARMREST | G4: 6 | H4: QUOTE SYSTE, | I4: B | J4: 20210621 | K4: 36 | L4: N/A | M4: L | N4: USD | O4: SF | P4: U | Q4: 20210621 | R4: N/A | W4: Model was entered from [TRIM_LEVEL]# 203 | Y4: NULL | AA4: WDK5 | AB4: NULL
A5: =VLOOKUP(E5,COTI!F:F,1,FALSE) -> WLE | D5: EISS01 | E5: WLE | F5: 2021 WL EISMANN | G5: 6 | H5: SORTED/STYLE | I5: B | J5: 20210805 | K5: 30 | L5: N/A | M5: L | N5: USD | O5: SF | P5: U | Q5: 20210805 | R5: TBC | W5: Model was entered from [TRIM_LEVEL]# 258 | X5: NULL | Y5: NULL | AA5: WLE5 | AB5: NULL
A6: =VLOOKUP(E6,COTI!F:F,1,FALSE) -> C3A | D6: FAUR01 | E6: C3A | F6: 2021 WS BL-GL EEP 3RD ROW | G6: 7 | H6: ADD SORTED/STYLE | I6: B | J6: 20210730 | K6: 100 | L6: N/A | M6: L | N6: USD | O6: SF | P6: U | Q6: 20210730 | R6: NA | W6: Model was entered from [TRIM_LEVEL]# 227 | AA6: C3A6 | AB6: NULL
A7: =VLOOKUP(E7,COTI!F:F,1,FALSE) -> C3B | D7: FAUR01 | E7: C3B | F7: 2021 WS AL JEEP 3RD ROW | G7: 7 | H7: ADD SORTED/STYLE | I7: B | J7: 20210730 | K7: 100 | L7: N/A | M7: L | N7: USD | O7: SF | P7: U | Q7: 20210730 | R7: NA | W7: Model was entered from [TRIM_LEVEL]# 228 | X7: NULL | AA7: C3B6 | AB7: NULL
A8: =VLOOKUP(E8,COTI!F:F,1,FALSE) -> FW2 | D8: FAUR01 | E8: FW2 | F8: 2021 WS JEEP SL NEVER QUILTED | G8: 7 | H8: ADD SORTED/STYLE | I8: B | J8: 20210730 | K8: 46 | L8: N/A | M8: L | N8: USD | O8: SF | P8: U | Q8: 20210730 | R8: ECR161958 | W8: Model was entered from [TRIM_LEVEL]# 229 | X8: NULL | Y8: NULL | AA8: FW26 | AB8: NULL
A9: =VLOOKUP(E9,COTI!F:F,1,FALSE) -> FWS | D9: FAUR01 | E9: FWS | F9: 2021 WS AL JEEP BASE | G9: 5 | H9: ADD SORTED/STYLE | I9: B | J9: 20210730 | K9: 53 | L9: N/A | M9: L | N9: USD | O9: SF | P9: U | Q9: 20210730 | R9: N/A | W9: Model was entered from [TRIM_LEVEL]# 230 | X9: NULL | Y9: NULL | AA9: FWS4 | AB9: NULL
A10: =VLOOKUP(E10,COTI!F:F,1,FALSE) -> S3S | D10: FAUR01 | E10: S3S | F10: 2021 WS SL JEEP 3RD ROW | G10: 6 | H10: ADD SORTED/STYLE | I10: B | J10: 20210730 | K10: 100 | L10: N/A | M10: L | N10: USD | O10: SF | P10: U | Q10: 20210730 | R10: NA | W10: Model was entered from [TRIM_LEVEL]# 231 | X10: NULL | AA10: S3S5 | AB10: NULL
A11: =VLOOKUP(E11,COTI!F:F,1,FALSE) -> S3U | D11: FAUR01 | E11: S3U | F11: 2021 WS UL JEEP 3RD ROW | G11: 9 | H11: ADD SORTED/STYLE | I11: B | J11: 20210730 | K11: 100 | L11: N/A | M11: L | N11: USD | O11: SF | P11: U | Q11: 20210730 | R11: NA | W11: Model was entered from [TRIM_LEVEL]# 232 | X11: NULL | AA11: S3U8 | AB11: NULL
A12: =VLOOKUP(E12,COTI!F:F,1,FALSE) -> WS3 | D12: FAUR01 | E12: WS3 | F12: 2021 WS UL ALWAYS QUILTED | G12: 6 | H12: ADD SORTED / STYLE | I12: B | J12: 20210816 | K12: 46 | L12: N/A | M12: L | N12: USD | O12: SF | P12: U | Q12: 20210816 | R12: ECR161958 | W12: Model was entered from [TRIM_LEVEL]# 273 | X12: NULL | Y12: NULL | AA12: WS35 | AB12: NULL
A13: =VLOOKUP(E13,COTI!F:F,1,FALSE) -> MCY | D13: FIND02 | E13: MCY | F13: U364 MERCURY LTD FINDALY | G13: 1 | H13: New Model | I13: N | J13: 20070418 | K13: 50 | L13: N/A | M13: L | N13: USD | O13: SF | P13: U | Q13: 20070418 | R13: N/A | S13: U364 MERCURY LTD FINDLAY FOLIO 01071 | AA13: MCY | AB13: NULL
A14: =VLOOKUP(E14,COTI!F:F,1,FALSE) -> GAR | D14: GRAM01 | E14: GAR | F14: U388 LINCOLN ARMREST | G14: 14 | H14: EC DW#052913 | I14: B | J14: 20110914 | K14: 60 | L14: n/a | M14: L | N14: USD | O14: SF | P14: U | Q14: 20130718 | R14: n/a | S14: CAMBIO ING TEMPORAL | AA14: GAR0013 | AB14: NULL
A15: =VLOOKUP(E15,COTI!F:F,1,FALSE) -> GR1 | D15: GRAM04 | E15: GR1 | F15: 2021 WL 75 QUADS 2ND. ROW ARMR | G15: 2 | H15: QUOTE SYSTEM | I15: B | J15: 20210713 | K15: 39 | L15: N/A | M15: L | N15: USD | O15: SF | P15: U | Q15: 20210713 | R15: TBC | W15: Model was entered from [TRIM_LEVEL]# 235 | X15: NULL | Y15: NULL | AA15: GR11 | AB15: NULL
A16: =VLOOKUP(E16,COTI!F:F,1,FALSE) -> GR2 | D16: GRAM04 | E16: GR2 | F16: WS FOLDING 2ND-ROW ARM REST | G16: 2 | H16: SORTED /STYLE | I16: B | J16: 20210805 | K16: 44 | L16: N/A | M16: L | N16: USD | O16: SF | P16: U | Q16: 20210805 | R16: TBC | W16: Model was entered from [TRIM_LEVEL]# 252 | X16: NULL | Y16: NULL | AA16: GR21 | AB16: NULL
A17: =VLOOKUP(E17,COTI!F:F,1,FALSE) -> GRM | D17: GRAM04 | E17: GRM | F17: 2021 WL 74/75 2ND. ROW ARMREST | G17: 2 | H17: SORTED/ STYLE | I17: B | J17: 20210805 | K17: 40 | L17: N/A | M17: L | N17: USD | O17: SF | P17: U | Q17: 20210805 | R17: TBC | W17: Model was entered from [TRIM_LEVEL]# 253 | X17: NULL | Y17: NULL | AA17: GRM1 | AB17: NULL
A18: =VLOOKUP(E18,COTI!F:F,1,FALSE) -> GW2 | B18: VERSION CREADA EN ENGINEERING | C18: REEMPLAZADAS POR CAMBIO DE PIEL | D18: GRAM04 | E18: GW2 | F18: 2021 WL 75 QUADS 2ND. ROW AR | G18: 2 | H18: Pricing & Engineering Change | I18: B | J18: 20200915 | K18: 39 | L18: 1 | M18: L | N18: USD | O18: SF | P18: U | Q18: 20200915 | R18: 4202020 | S18: NULL | T18: NULL | U18: NULL | V18: NULL | W18: NULL | X18: Y | AA18: GW20001 | AB18: NULL
A19: =VLOOKUP(E19,COTI!F:F,1,FALSE) -> GWL | B19: VERSION CREADA EN ENGINEERING | C19: REEMPLAZADAS POR CAMBIO DE PIEL | D19: GRAM04 | E19: GWL | F19: 2021 WL 74/75 2ND. ROW ARMRE | G19: 2 | H19: Pricing & Engineering Change | I19: B | J19: 20200915 | K19: 40 | L19: 1 | M19: L | N19: USD | O19: SF | P19: U | Q19: 20200915 | R19: TBC | S19: NULL | T19: NULL | U19: NULL | V19: NULL | W19: NULL | AA19: GWL0001 | AB19: NULL
A20: =VLOOKUP(E20,COTI!F:F,1,FALSE) -> GWS | B20: *** | C20: REEMPLAZADAS POR CAMBIO DE PIEL | D20: GRAM04 | E20: GWS | F20: 2021 WS GRAN WAGONNER | G20: 2 | H20: NEW MODEL-PRICING ACORDING BPO | I20: B | J20: 20210223 | K20: 44 | L20: N/A | M20: L | N20: USD | O20: SF | P20: U | Q20: 20210223 | R20: N/A | W20: Model was entered from [TRIM_LEVEL]# 133 | AA20: GWS1 | AB20: NULL
A21: =VLOOKUP(E21,COTI!F:F,1,FALSE) -> 193 | D21: IRVI02 | E21: 193 | F21: GMT 193 2007 | G21: 12 | H21: Pricing Change | I21: B | J21: 20080103 | K21: 58 | L21: N/A | M21: L | N21: USD | O21: SF | P21: U | Q21: 20080103 | R21: N/A | S21: 0.065 Cents Increase FOLIO 1207-193 | AA21: 1930011 | AB21: NULL
A22: =VLOOKUP(E22,COTI!F:F,1,FALSE) -> 87C | D22: IRVI02 | E22: 87C | F22: U387 FORD CUTTING EDGE | G22: 7 | H22: Pricing & Engineering Change | I22: B | J22: 20080821 | K22: 62 | L22: n/a | M22: L | N22: USD | O22: SF | P22: U | Q22: 20080821 | R22: n/a | X22: Y | AA22: 87C0005 | AB22: NULL
A23: =VLOOKUP(E23,COTI!F:F,1,FALSE) -> 87P | D23: IRVI02 | E23: 87P | F23: U387 FORD PREMIUM | G23: 6 | H23: Change Howe part number | I23: B | J23: 20080121 | K23: 62 | L23: n/a | M23: L | N23: USD | O23: SF | P23: U | Q23: 20080121 | R23: n/a | S23: change howe part number | AA23: 87P0005 | AB23: NULL
A24: =VLOOKUP(E24,COTI!F:F,1,FALSE) -> 88L | D24: IRVI02 | E24: 88L | F24: U388 LINCOLN LIMITED | G24: 4 | H24: Pricing Change | I24: B | J24: 20080314 | K24: 62 | L24: N/A | M24: L | N24: USD | O24: SF | P24: U | Q24: 20080314 | R24: N/A | S24: Price change | AA24: 88L0003 | AB24: NULL
A25: =VLOOKUP(E25,COTI!F:F,1,FALSE) -> GM1 | D25: IRVI02 | E25: GM1 | F25: GMT 191 PONTIAC TORRENT | G25: 10 | H25: Pricing & Engineering Change | I25: B | J25: 20080103 | K25: 60 | L25: n/a | M25: L | N25: USD | O25: SF | P25: U | Q25: 20080103 | R25: n/a | S25: 0.065 Cents Increase | AA25: GM10009 | AB25: NULL
A26: =VLOOKUP(E26,COTI!F:F,1,FALSE) -> GM2 | D26: IRVI02 | E26: GM2 | F26: GMT 192 PONTIAC PERSUIT | G26: 7 | H26: Pricing Change | I26: B | J26: 20080103 | K26: 60 | L26: N/A | M26: L | N26: USD | O26: SF | P26: U | Q26: 20080103 | R26: N/A | S26: 0.065 Cents Increase FOLIO 1207-092 | AA26: GM20006 | AB26: NULL
A27: =VLOOKUP(E27,COTI!F:F,1,FALSE) -> GM3 | D27: IRVI02 | E27: GM3 | F27: ARMREST GMT 193 | G27: 2 | H27: Pricing & Engineering Change | I27: B | J27: 20060905 | K27: 60 | L27: N/A | M27: L | N27: USD | O27: SF | P27: U | Q27: 20060905 | R27: N/A | S27: MODIFY PROD CATEGORY | AA27: GM3 | AB27: NULL
A28: =VLOOKUP(E28,COTI!F:F,1,FALSE) -> GXP | D28: IRVI02 | E28: GXP | F28: GMT 192 GXP 2008 | G28: 4 | H28: Pricing Change | I28: B | J28: 20080103 | K28: 59 | L28: N/A | M28: L | N28: USD | O28: SF | P28: U | Q28: 20080103 | R28: N/A | S28: 0.065 Cents Increase FOLIO 1207-195 | AA28: GXP0003 | AB28: NULL
A29: =VLOOKUP(E29,COTI!F:F,1,FALSE) -> JJT | D29: IRVI02 | E29: JJT | F29: 2019 JEEP JT | G29: 17 | H29: Pricing & Engineering Change | I29: B | J29: 20210625 | K29: 57 | L29: AD | M29: L | N29: USD | O29: SF | P29: U | Q29: 20210625 | R29: 1012021 | S29: NULL | T29: NULL | U29: NULL | V29: NULL | W29: NULL | AA29: JJT0016 | AB29: NULL
A30: =VLOOKUP(E30,COTI!F:F,1,FALSE) -> JLI | D30: IRVI02 | E30: JLI | F30: 2018 JEEP JL | G30: 51 | H30: Pricing & Engineering Change | I30: B | J30: 20210622 | K30: 57 | L30: AD | M30: L | N30: USD | O30: SF | P30: U | Q30: 20210622 | R30: TBC | S30: NULL | T30: NULL | U30: NULL | V30: NULL | W30: NULL | X30: Y | AA30: JLI0050 | AB30: NULL
A31: =VLOOKUP(E31,COTI!F:F,1,FALSE) -> JPH | D31: IRVI02 | E31: JPH | F31: 2020 JEEP JL PHEV | G31: 8 | H31: Pricing & Engineering Change | I31: B | J31: 20210623 | K31: 57 | L31: AD | M31: L | N31: USD | O31: SF | P31: U | Q31: 20210623 | R31: 121719 | S31: NULL | T31: NULL | U31: NULL | V31: NULL | W31: NULL | AA31: JPH0007 | AB31: NULL
A32: =VLOOKUP(E32,COTI!F:F,1,FALSE) -> JPS | D32: IRVI02 | E32: JPS | F32: 2021 JEEP JL PHEV SUMMIT | G32: 5 | H32: Pricing & Engineering Change | I32: B | J32: 20210628 | K32: 49 | L32: AD | M32: L | N32: USD | O32: SF | P32: U | Q32: 20210628 | R32: 121819 | S32: NULL | T32: NULL | U32: NULL | V32: NULL | W32: NULL | AA32: JPS0004 | AB32: NULL
A33: =VLOOKUP(E33,COTI!F:F,1,FALSE) -> JSU | D33: IRVI02 | E33: JSU | F33: JEEPJL SUMMIT | G33: 9 | H33: Pricing & Engineering Change | I33: B | J33: 20210623 | K33: 49 | L33: AD | M33: L | N33: USD | O33: SF | P33: U | Q33: 20210623 | R33: DWO2020255 | S33: NULL | T33: NULL | U33: NULL | V33: NULL | W33: NULL | AA33: JSU0008 | AB33: NULL
A34: =VLOOKUP(E34,COTI!F:F,1,FALSE) -> JTM | D34: IRVI02 | E34: JTM | F34: 2019 JEEP JT MOJAVE | G34: 9 | H34: Pricing & Engineering Change | I34: B | J34: 20210623 | K34: 57 | L34: AD | M34: L | N34: USD | O34: SF | P34: U | Q34: 20210623 | R34: SR2020255 | S34: NULL | T34: NULL | U34: NULL | V34: NULL | W34: NULL | AA34: JTM0008 | AB34: NULL
A35: =VLOOKUP(E35,COTI!F:F,1,FALSE) -> JTS | D35: IRVI02 | E35: JTS | F35: 2021 JEEP JT SUMMIT | G35: 7 | H35: Pricing & Engineering Change | I35: B | J35: 20210629 | K35: 49 | L35: AD | M35: L | N35: USD | O35: SF | P35: U | Q35: 20210629 | R35: DW0315 | S35: NULL | T35: NULL | U35: NULL | V35: NULL | W35: NULL | AA35: JTS0006 | AB35: NULL
A36: =VLOOKUP(E36,COTI!F:F,1,FALSE) -> VFL | D36: IRVI02 | E36: VFL | F36: V229 FORD FREESTAR LTD | G36: 2 | H36: Pricing & Engineering Change | I36: B | J36: 20060717 | K36: 62 | L36: N/A | M36: L | N36: USD | O36: SF | P36: U | Q36: 20060717 | R36: N/A | S36: TO FIX MISTAKE IN V1 | X36: Y | AA36: VFL0001 | AB36: NULL
A37: =VLOOKUP(E37,COTI!F:F,1,FALSE) -> VML | D37: IRVI02 | E37: VML | F37: V229 FREESTAR MERCURY LTD | G37: 1 | H37: New Model | I37: N | J37: 20060629 | K37: 60 | L37: N/A | M37: L | N37: USD | O37: SF | P37: U | Q37: 20060629 | R37: N/A | S37: V229 FREESTAR MERCURY LTD FOLIO 01204 | AA37: VML | AB37: NULL
A38: =VLOOKUP(E38,COTI!F:F,1,FALSE) -> VMP | D38: IRVI02 | E38: VMP | F38: V229 FREESTAR MPA | G38: 1 | H38: New Model | I38: N | J38: 20060719 | K38: 55 | L38: N/A | M38: L | N38: USD | O38: SF | P38: U | Q38: 20060719 | R38: N/A | S38: V229 FREESTAR MPA FOLIO 01203 | X38: Y | AA38: VMP | AB38: NULL
A39: =VLOOKUP(E39,COTI!F:F,1,FALSE) -> VMX | D39: IRVI02 | E39: VMX | F39: V229 FREESTAR MXA | G39: 1 | H39: New Model | I39: N | J39: 20060719 | K39: 60 | L39: N/A | M39: L | N39: USD | O39: SF | P39: U | Q39: 20060719 | R39: N/A | S39: V229 FREESTAR MXA FOLIO 1202-A | Z39: Y | AA39: VMX | AB39: NULL
A40: =VLOOKUP(E40,COTI!F:F,1,FALSE) -> 191 | D40: IRVI03 | E40: 191 | F40: GMT 191 2008 | G40: 2 | H40: Change only product category | I40: B | J40: 20090114 | K40: 60 | L40: n/a | M40: L | N40: USD | O40: SF | P40: U | Q40: 20090114 | R40: n/a | S40: Change only product category | AA40: 191 | AB40: NULL
A41: =VLOOKUP(E41,COTI!F:F,1,FALSE) -> 192 | D41: IRVI03 | E41: 192 | F41: GMT 192 2008 | G41: 2 | H41: Change Only Product Category | I41: B | J41: 20090114 | K41: 60 | L41: n/a | M41: L | N41: USD | O41: SF | P41: U | Q41: 20090120 | R41: n/a | S41: Change Only Product Category | AA41: 192 | AB41: NULL
...

Sheet COTI
B3: CUS_NAME | C3: CUS_NO | D3: S_ARCUSFIL_PROGRAM | E3: D_ARCUSFIL_PROGRAM_MODEL | F3: S_ARCUSFIL_PROGRAM_MODEL | G3: PROD_CAT_DESC
B4: AUTOMOTIVE LEATHER GROUP | C4: ALGRP1 | D4: WL | E4: 2021 WL DL 75 VPD | F4: WD7
B5: CNI INC | C5: CNII01 | D5: U377 | E5: U377 FORD HEADREST | F5: 77H
B6: DAIMAY AUTOMOTIVE INTERIOR, S. DE R.L. D | C6: DAIM05 | D6: WK WD | E6: 2021 WK WD 2ND ROW ARMREST | F6: WDK | G6: 2021 WD WK ARMR
B7: Eissmann Automotive de Mexico | C7: EISS01 | D7: WL | E7: 2021 WL EISMANN | F7: WLE | G7: 2021 WL EISMANN
B8: FAURECIA AUTOMOTIVE SEATING INC. | C8: FAUR01 | D8: WS | E8: 2021 WS BL-GL EEP 3RD ROW | F8: C3A | G8: WS 3RD ROW AL
B9: FAURECIA AUTOMOTIVE SEATING INC. | C9: FAUR01 | D9: WS | E9: 2021 WS AL JEEP 3RD ROW | F9: C3B | G9: WS 3RD ROW BLGL
B10: FAURECIA AUTOMOTIVE SEATING INC. | C10: FAUR01 | D10: WS | E10: 2021 WS JEEP SL NEVER QUILTED | F10: FW2 | G10: WS SL NEV QUILT
B11: FAURECIA AUTOMOTIVE SEATING INC. | C11: FAUR01 | D11: WS | E11: 2021 WS AL JEEP BASE | F11: FWS | G11: 2021 WS AL JEEP
B12: FAURECIA AUTOMOTIVE SEATING INC. | C12: FAUR01 | D12: WS | E12: 2021 WS SL JEEP 3RD ROW | F12: S3S | G12: WS 3RD ROW SL
B13: FAURECIA AUTOMOTIVE SEATING INC. | C13: FAUR01 | D13: WS | E13: 2021 WS UL JEEP 3RD ROW | F13: S3U | G13: WS 3RD ROW UL
B14: FAURECIA AUTOMOTIVE SEATING INC. | C14: FAUR01 | D14: WS | E14: 2021 WS UL ALWAYS QUILTED | F14: WS3 | G14: WS UL ALWAYS QU
B15: FINDLAY INDUSTRIES (FLORIDA)*********** | C15: FIND02 | D15: U364 | E15: U364 MERCURY LTD FINDALY | F15: MCY
B16: GRAMMER AUTOMOTIVE PUEBLA | C16: GRAM01 | D16: U388 | E16: U388 LINCOLN ARMREST | F16: GAR
B17: GRAMMER INDUSTRIES, INC | C17: GRAM04 | D17: WL | E17: 2021 WL 75 QUADS 2ND. ROW ARMR | F17: GR1 | G17: WL 75 CAPTAIN A
B18: GRAMMER INDUSTRIES, INC | C18: GRAM04 | D18: WL | E18: 2021 WL 74/75 2ND. ROW ARMREST | F18: GRM | G18: 2021 WL FOLDING
B19: GRAMMER INDUSTRIES, INC | C19: GRAM04 | D19: WL | E19: 2021 WL 75 QUADS 2ND. ROW AR | F19: GW2 | G19: WL 75 CAPTAIN ARMREST
B20: GRAMMER INDUSTRIES, INC | C20: GRAM04 | D20: WL | E20: 2021 WL 74/75 2ND. ROW ARMRE | F20: GWL | G20: 2021 WL FOLDING ARMREST
B21: GRAMMER INDUSTRIES, INC | C21: GRAM04 | D21: WS | E21: WS FOLDING 2ND-ROW ARM REST | F21: GR2 | G21: WS FOLDING ARMR
B22: GRAMMER INDUSTRIES, INC | C22: GRAM04 | D22: WS | E22: 2021 WS GRAN WAGONNER | F22: GWS | G22: 2021 WS GRAN WA
B23: IRVIN AUTOMOTIVE | C23: IRVI03 | D23: GMT | E23: GMT 191 2008 | F23: 191
B24: IRVIN AUTOMOTIVE | C24: IRVI03 | D24: GMT | E24: GMT 192 2008 | F24: 192
B25: IRVIN AUTOMOTIVE | C25: IRVI03 | D25: GMT | E25: ARMREST GMT 193 | F25: ARM
B26: IRVIN AUTOMOTIVE | C26: IRVI03 | D26: GMT | E26: GMT 193 2008 | F26: G93
B27: IRVIN AUTOMOTIVE | C27: IRVI03 | D27: GMT | E27: GMT 192 GXP 2008 | F27: GX2
B28: IRVIN AUTOMOTIVE PRODUCTS -PONTIAC | C28: IRVI02 | D28: GMT | E28: GMT 193 2007 | F28: 193
B29: IRVIN AUTOMOTIVE PRODUCTS -PONTIAC | C29: IRVI02 | D29: GMT | E29: GMT 191 PONTIAC TORRENT | F29: GM1
B30: IRVIN AUTOMOTIVE PRODUCTS -PONTIAC | C30: IRVI02 | D30: GMT | E30: GMT 192 PONTIAC PERSUIT | F30: GM2
B31: IRVIN AUTOMOTIVE PRODUCTS -PONTIAC | C31: IRVI02 | D31: GMT | E31: ARMREST GMT 193 | F31: GM3
B32: IRVIN AUTOMOTIVE PRODUCTS -PONTIAC | C32: IRVI02 | D32: GMT | E32: GMT 192 GXP 2008 | F32: GXP
B33: IRVIN AUTOMOTIVE PRODUCTS -PONTIAC | C33: IRVI02 | D33: JL | E33: 2018 JEEP JL | F33: JLI
B34: IRVIN AUTOMOTIVE PRODUCTS -PONTIAC | C34: IRVI02 | D34: JL | E34: 2020 JEEP JL PHEV | F34: JPH
B35: IRVIN AUTOMOTIVE PRODUCTS -PONTIAC | C35: IRVI02 | D35: JL | E35: 2021 JEEP JL PHEV SUMMIT | F35: JPS | G35: JL PHEV SUMMIT
B36: IRVIN AUTOMOTIVE PRODUCTS -PONTIAC | C36: IRVI02 | D36: JL | E36: JEEPJL SUMMIT | F36: JSU | G36: JEEP JL SUMMIT
B37: IRVIN AUTOMOTIVE PRODUCTS -PONTIAC | C37: IRVI02 | D37: JT | E37: 2019 JEEP JT | F37: JJT | G37: 2019 JEEP JT
B38: IRVIN AUTOMOTIVE PRODUCTS -PONTIAC | C38: IRVI02 | D38: JT | E38: 2019 JEEP JT MOJAVE | F38: JTM | G38: JT MOJAVE
B39: IRVIN AUTOMOTIVE PRODUCTS -PONTIAC | C39: IRVI02 | D39: JT | E39: 2021 JEEP JT SUMMIT | F39: JTS | G39: JEEP JT SUMMIT
B40: IRVIN AUTOMOTIVE PRODUCTS -PONTIAC | C40: IRVI02 | D40: U387 | E40: U387 FORD CUTTING EDGE | F40: 87C
B41: IRVIN AUTOMOTIVE PRODUCTS -PONTIAC | C41: IRVI02 | D41: U387 | E41: U387 FORD PREMIUM | F41: 87P
B42: IRVIN AUTOMOTIVE PRODUCTS -PONTIAC | C42: IRVI02 | D42: U388 | E42: U388 LINCOLN ARMREST | F42: 88A
...

Sheet Hoja5
B3: ESPACIO_01 | C3: CLIENTE_01 | D3: CUS_NO | E3: S_PROGRAM | F3: MODELNO | G3: VERSIONNO | H3: K_QUOTE_TRIM_LEVEL | I3: K_QUOTE_TRIM_COLOR | J3: S_COLOR | K3: D_COLOR_1 | L3: D_COLOR_2 | M3: YIELD | N3: YIELD_ADITIONAL | O3: QUOTE_DATE | P3: PCN | Q3: VPY | R3: VPW | S3: VPD | T3: D_LEATHER | U3: CRUST_COST | V3: CUTTING_COST | W3: SHRINK_COST | X3: DENIM_RESISTANCE_COST | Y3: FINISHING_COST | Z3: TOTAL_COST_DRIVERS | AA3: TOTAL_PATTERN | AB3: TOTAL_NET_AREA | AC3: TOTAL_GRO_AREA | AD3: TOTAL_CAR_SET_PRICE | AE3: TOTAL_CAR_SET_PRICE_PLM | AF3: D_LAMINATION | AG3: D_PERFORATION | AH3: SPECIAL_PROCESS | AI3: CANTIDAD_PATTERNS_LAMINADOS | AJ3: AREA_NET_LAMINADOS | AK3: CANTIDAD_PATTERNS_PERFORADOS | AL3: AREA_NET_PERFORADOS | AM3: MENSAJE
B4: 10 | C4: 1 | D4: DAIM05 | E4: WK WD | F4: WDK | G4: 6 | H4: 203 | I4: 478 | J4: FDNPDX9 | K4: NAPPA DX9 (BLACK) | L4: BLACK | M4: 36 | N4: 0 | O4: 44366 | P4: TBC | Q4: 2200 | R4: 45 | S4: 9 | T4: NAPPA | U4: 2.05 | V4: 0.4 | W4: 0 | X4: 0 | Y4: 0 | Z4: 2.45 | AA4: 12 | AB4: 4.61 | AC4: 12.82 | AD4: 31.4 | AE4: 5.13 | AI4: 0 | AJ4: 0 | AK4: 0 | AL4: 0
B5: 0 | C5: 1 | H5: 203 | I5: 479 | J5: FDNPJRR | K5: NAPPA JRR (RADAR RED) | L5: RADAR RED | O5: NULL | U5: 2.05 | V5: 0.4 | W5: 0 | X5: 0 | Y5: 0 | Z5: 2.45 | AA5: 4 | AB5: 1.54 | AC5: 4.27 | AD5: 10.47 | AE5: 1.71 | AI5: 0 | AJ5: 0 | AK5: 0 | AL5: 0
B6: 0 | C6: 1 | H6: 203 | I6: 477 | J6: FDNPWU9 | K6: NAPPA WU9 (EBONY RED) | L6: EBONY RED | O6: NULL | U6: 2.05 | V6: 0.4 | W6: 0 | X6: 0 | Y6: 0 | Z6: 2.45 | AA6: 4 | AB6: 1.54 | AC6: 4.27 | AD6: 10.47 | AE6: 1.71 | AI6: 0 | AJ6: 0 | AK6: 0 | AL6: 0
B7: 10 | C7: 2 | D7: EISS01 | E7: WL | F7: WLE | G7: 6 | H7: 258 | I7: 609 | J7: FYPATX7 | K7: PALERMO CHROME FREE TX7 (GLOBAL BLACK) | L7: GLOBAL BLACK | M7: 30 | N7: 25 | O7: 44413 | P7: TBC | Q7: 4500 | R7: 95 | S7: 19 | T7: PALERMO | U7: 3.704 | V7: 0.4 | W7: 0 | X7: 0 | Y7: 0 | Z7: 4.104 | AA7: 6 | AB7: 2.51 | AC7: 8.36 | AD7: 34.32 | AE7: 3.35 | AI7: 0 | AJ7: 0 | AK7: 0 | AL7: 0
B8: 0 | C8: 2 | H8: 258 | I8: 610 | J8: FYPAWT5 | K8: PALERMO CHROME FREE WT5 (TUPELO) | L8: TUPELO | O8: NULL | U8: 3.704 | V8: 0.4 | W8: 0 | X8: 0 | Y8: 0 | Z8: 4.104 | AA8: 6 | AB8: 2.51 | AC8: 8.36 | AD8: 34.32 | AE8: 3.35 | AI8: 0 | AJ8: 0 | AK8: 0 | AL8: 0
B9: 10 | C9: 3 | D9: FAUR01 | E9: WS | F9: C3A | G9: 7 | H9: 227 | I9: 532 | J9: FVCCAD4 | K9: VINYL CAPRICE-SD4 (CTN3120HD -DDT BLACK FABRIC CAPRICE SD4) | L9: CTN3120HD -DDT BLACK FABRIC CAPRICE SD4 | M9: 100 | N9: 0 | O9: 44385 | P9: NA | Q9: 87792 | R9: 1865 | S9: 373 | T9: VINYL CAPRICE | U9: 1.35 | V9: 0 | W9: 0 | X9: 0 | Y9: 0 | Z9: 1.35 | AA9: 8 | AB9: 4.86 | AC9: 4.86 | AD9: 17.59 | AE9: 10.45 | AF9: FXI A200060EL 6MM FOAM // LAMINATION | AG9: REGISTERED PERFORATION | AH9: RECUT | AI9: 8 | AJ9: 4.86 | AK9: 8 | AL9: 4.86
B10: 0 | C10: 3 | H10: 227 | I10: 531 | J10: FVCCAX7 | K10: VINYL CAPRICE-TX7 (CTN3117HD BLACK FABRIC CAPRICE TX7) | L10: CTN3117HD BLACK FABRIC CAPRICE TX7 | O10: NULL | U10: 1.35 | V10: 0 | W10: 0 | X10: 0 | Y10: 0 | Z10: 1.35 | AA10: 8 | AB10: 4.86 | AC10: 4.86 | AD10: 17 | AE10: 10.45 | AI10: 8 | AJ10: 4.86 | AK10: 8 | AL10: 4.86
B11: 10 | C11: 3 | D11: FAUR01 | E11: WS | F11: C3B | G11: 7 | H11: 228 | I11: 534 | J11: FVCCPD4 | K11: VINYL CAPRI-SD4 (CTN3120HD-DDT BLACK FABRIC CAPRI SD4) | L11: CTN3120HD-DDT BLACK FABRIC CAPRI SD4 | M11: 100 | N11: 0 | O11: 44385 | P11: NA | Q11: 24096 | R11: 510 | S11: 102 | T11: VINYL CAPRI | U11: 1.35 | V11: 0 | W11: 0 | X11: 0 | Y11: 0 | Z11: 1.35 | AA11: 8 | AB11: 4.86 | AC11: 4.86 | AD11: 17.59 | AE11: 10.45 | AF11: FXI A200060EL 6MM FOAM // LAMINATION | AG11: REGISTERED PERFORATION | AH11: RECUT | AI11: 8 | AJ11: 4.86 | AK11: 8 | AL11: 4.86
B12: 0 | C12: 3 | H12: 228 | I12: 533 | J12: FVCCPX7 | K12: VINYL CAPRI-TX7 (CTN3117HD BLACK FABRIC CAPRI - TX7) | L12: CTN3117HD BLACK FABRIC CAPRI - TX7 | O12: NULL | U12: 1.35 | V12: 0 | W12: 0 | X12: 0 | Y12: 0 | Z12: 1.35 | AA12: 8 | AB12: 4.86 | AC12: 4.86 | AD12: 17 | AE12: 10.45 | AI12: 8 | AJ12: 4.86 | AK12: 8 | AL12: 4.86
B13: 10 | C13: 3 | D13: FAUR01 | E13: WS | F13: FW2 | G13: 7 | H13: 229 | I13: 535 | J13: FWSPAA6 | K13: PALERMO WA6 (AGAVE) | L13: AGAVE | M13: 46 | N13: 0 | O13: 44385 | P13: ECR161958 | Q13: 7500 | R13: 155 | S13: 31 | T13: PALERMO | U13: 2.8883 | V13: 0.35 | W13: 0 | X13: 0 | Y13: 0 | Z13: 3.2383 | AA13: 52 | AB13: 29.58 | AC13: 64.3 | AD13: 240.69 | AE13: 54.98 | AF13: KUFNER R179G46 // KUFNER TX9080 | AG13: AXIS II // REGISTERED | AH13: RECUT // QUILTING COST PER PIECE | AI13: 22 | AJ13: 14.95 | AK13: 30 | AL13: 18.3
B14: 0 | C14: 3 | H14: 229 | I14: 536 | J14: FWSPAD4 | K14: PALERMO SD4 (SEA SALT) | L14: SEA SALT | O14: NULL | U14: 2.8883 | V14: 0.35 | W14: 0 | X14: 0 | Y14: 0 | Z14: 3.2383 | AA14: 54 | AB14: 30.62 | AC14: 66.56 | AD14: 248.01 | AE14: 55.77 | AI14: 22 | AJ14: 14.95 | AK14: 30 | AL14: 18.3
B15: 0 | C15: 3 | H15: 229 | I15: 537 | J15: FWSPAX7 | K15: PALERMO TX7 (GLOBAL BLACK) | L15: GLOBAL BLACK | O15: NULL | U15: 2.8883 | V15: 0.35 | W15: 0 | X15: 0 | Y15: 0 | Z15: 3.2383 | AA15: 52 | AB15: 29.58 | AC15: 64.3 | AD15: 240.69 | AE15: 54.98 | AI15: 22 | AJ15: 14.95 | AK15: 30 | AL15: 18.3
B16: 10 | C16: 3 | D16: FAUR01 | E16: WS | F16: FWS | G16: 5 | H16: 230 | I16: 539 | J16: FWSCPD4 | K16: CAPRI SD4 (SEA SALT) | L16: SEA SALT | M16: 53 | N16: 0 | O16: 44385 | P16: N/A | Q16: 37500 | R16: 795 | S16: 159 | T16: CAPRI | U16: 1.9143 | V16: 0.35 | W16: 0 | X16: 0 | Y16: 0 | Z16: 2.2643 | AA16: 48 | AB16: 26.74 | AC16: 50.45 | AD16: 139 | AE16: 42.42 | AF16: KUFNER TX9080 | AG16: AXIS II // REGISTERED PERFORATION | AI16: 20 | AJ16: 12.34 | AK16: 24 | AL16: 15.43
B17: 0 | C17: 3 | H17: 230 | I17: 538 | J17: FWSCPX7 | K17: CAPRI TX7 (GLOBAL BLACK) | L17: GLOBAL BLACK | O17: NULL | U17: 1.9143 | V17: 0.35 | W17: 0 | X17: 0 | Y17: 0 | Z17: 2.2643 | AA17: 48 | AB17: 26.74 | AC17: 50.45 | AD17: 139 | AE17: 42.42 | AI17: 20 | AJ17: 12.34 | AK17: 24 | AL17: 15.43
B18: 10 | C18: 3 | D18: FAUR01 | E18: WS | F18: S3S | G18: 6 | H18: 231 | I18: 541 | J18: FVSBWA6 | K18: SICILY GRAIN-WA6 (HEAVY WEIGHT PU WITH SICILY GRAIN - WA6) | L18: HEAVY WEIGHT PU WITH SICILY GRAIN - WA6 | M18: 100 | N18: 0 | O18: 44385 | P18: NA | Q18: 6528 | R18: 135 | S18: 27 | T18: VINYL SICILY GRAN | U18: 3.1 | V18: 0 | W18: 0 | X18: 0 | Y18: 0 | Z18: 3.1 | AA18: 8 | AB18: 4.5 | AC18: 4.5 | AD18: 21.79 | AE18: 7.83 | AF18: FXI A200060EL 6MM FOAM // LAMINATION | AG18: REGISTERED PERFORATION | AI18: 8 | AJ18: 4.5 | AK18: 8 | AL18: 4.5
B19: 0 | C19: 3 | H19: 231 | I19: 540 | J19: FVSVTX7 | K19: SICILY GRAIN-TX7 (HEAVY WEIGHT PU WITH SICILY GRAIN-TX7) | L19: HEAVY WEIGHT PU WITH SICILY GRAIN-TX7 | O19: NULL | U19: 3.1 | V19: 0 | W19: 0 | X19: 0 | Y19: 0 | Z19: 3.1 | AA19: 8 | AB19: 4.5 | AC19: 4.5 | AD19: 21.79 | AE19: 7.83 | AI19: 8 | AJ19: 4.5 | AK19: 8 | AL19: 4.5
B20: 0 | C20: 3 | H20: 231 | I20: 542 | J20: FVSXSD4 | K20: SICILY GRAIN-SD4 (HEAVY WEIGTH PU WITH SICILY GRAIN - SD4) | L20: HEAVY WEIGTH PU WITH SICILY GRAIN - SD4 | O20: NULL | U20: 3.1 | V20: 0 | W20: 0 | X20: 0 | Y20: 0 | Z20: 3.1 | AA20: 8 | AB20: 4.5 | AC20: 4.5 | AD20: 22.53 | AE20: 7.83 | AI20: 8 | AJ20: 4.5 | AK20: 8 | AL20: 4.5
B21: 10 | C21: 3 | D21: FAUR01 | E21: WS | F21: S3U | G21: 9 | H21: 232 | I21: 544 | J21: FVSVTX7 | K21: SICILY GRAIN-TX7 (HEAVY WEIGHT PU WITH SICILY GRAIN-TX7) | L21: HEAVY WEIGHT PU WITH SICILY GRAIN-TX7 | M21: 100 | N21: 0 | O21: 44385 | P21: NA | Q21: 6528 | R21: 135 | S21: 27 | T21: VINYL SICILY GRAN | U21: 3.1 | V21: 0 | W21: 0 | X21: 0 | Y21: 0 | Z21: 3.1 | AA21: 8 | AB21: 5.43 | AC21: 5.43 | AD21: 52.51 | AE21: 35.69 | AF21: FXI A200060EL FOAM // LAMINATION | AG21: REGISTERED PERFORATION | AH21: RECUT // QUILTING | AI21: 8 | AJ21: 5.43 | AK21: 8 | AL21: 5.43
B22: 0 | C22: 3 | H22: 232 | I22: 545 | J22: FVSBWA6 | K22: SICILY GRAIN-WA6 (HEAVY WEIGHT PU WITH SICILY GRAIN - WA6) | L22: HEAVY WEIGHT PU WITH SICILY GRAIN - WA6 | O22: NULL | U22: 3.1 | V22: 0 | W22: 0 | X22: 0 | Y22: 0 | Z22: 3.1 | AA22: 8 | AB22: 5.43 | AC22: 5.43 | AD22: 52.51 | AE22: 35.69 | AI22: 8 | AJ22: 5.43 | AK22: 8 | AL22: 5.43
B23: 0 | C23: 3 | H23: 232 | I23: 543 | J23: FVSBWT5 | K23: SICILY GRAIN-WT5 (HEAVY WEIGHT PU WITH SICILY GRAIN - WT5) | L23: HEAVY WEIGHT PU WITH SICILY GRAIN - WT5 | O23: NULL | U23: 3.1 | V23: 0 | W23: 0 | X23: 0 | Y23: 0 | Z23: 3.1 | AA23: 8 | AB23: 5.43 | AC23: 5.43 | AD23: 53.41 | AE23: 35.69 | AI23: 8 | AJ23: 5.43 | AK23: 8 | AL23: 5.43
B24: 10 | C24: 3 | D24: FAUR01 | E24: WS | F24: WS3 | G24: 6 | H24: 273 | I24: 642 | J24: FWSPAA6 | K24: PALERMO WA6 (AGAVE) | L24: AGAVE | M24: 46 | N24: 0 | O24: 44424 | P24: ECR161958 | Q24: 7500 | R24: 155 | S24: 31 | T24: PALERMO | U24: 2.8883 | V24: 0.35 | W24: 0 | X24: 0 | Y24: 0 | Z24: 3.2383 | AA24: 54 | AB24: 33.61 | AC24: 73.07 | AD24: 388.77 | AE24: 177.73 | AF24: KUFNER R179G46 // KUFNER TX9080 | AG24: REGISTERED PERF // AXIS II PERFORATION | AH24: SKIVING 1.0 ± 0.1 MM // RECUT // QUILTING // FXI: CLIMATEFLOW 250 – 6MM | AI24: 34 | AJ24: 23.41 | AK24: 30 | AL24: 21.29
B25: 0 | C25: 3 | H25: 273 | I25: 641 | J25: FWSPAX7 | K25: PALERMO TX7 (GLOBAL BLACK) | L25: GLOBAL BLACK | O25: NULL | U25: 2.8883 | V25: 0.35 | W25: 0 | X25: 0 | Y25: 0 | Z25: 3.2383 | AA25: 54 | AB25: 33.61 | AC25: 73.07 | AD25: 388.77 | AE25: 177.73 | AI25: 34 | AJ25: 23.41 | AK25: 30 | AL25: 21.29
B26: 0 | C26: 3 | H26: 273 | I26: 640 | J26: FWSPAT5 | K26: PALERMO WT5 (TUPELO) | L26: TUPELO | O26: NULL | U26: 2.8883 | V26: 0.35 | W26: 0 | X26: 0 | Y26: 0 | Z26: 3.2383 | AA26: 54 | AB26: 33.61 | AC26: 73.07 | AD26: 388.77 | AE26: 177.73 | AI26: 34 | AJ26: 23.41 | AK26: 30 | AL26: 21.29
B27: 10 | C27: 4 | D27: GRAM04 | E27: WL | F27: GR1 | G27: 2 | H27: 235 | I27: 551 | J27: FWSPAT5 | K27: PALERMO WT5 (TUPELO) | L27: TUPELO | M27: 39 | N27: 0 | O27: 44390 | P27: TBC | Q27: 2933 | R27: 60 | S27: 12 | T27: PALERMO | U27: 2.888 | V27: 0.4 | W27: 0 | X27: 0 | Y27: 0 | Z27: 3.288 | AA27: 6 | AB27: 1.9 | AC27: 4.88 | AD27: 16.04 | AE27: 1.95 | AI27: 0 | AJ27: 0 | AK27: 0 | AL27: 0
B28: 0 | C28: 4 | H28: 235 | I28: 552 | J28: FWSPAX7 | K28: PALERMO TX7 (GLOBAL BLACK) | L28: GLOBAL BLACK | O28: NULL | U28: 2.888 | V28: 0.4 | W28: 0 | X28: 0 | Y28: 0 | Z28: 3.288 | AA28: 6 | AB28: 1.9 | AC28: 4.88 | AD28: 16.04 | AE28: 1.95 | AI28: 0 | AJ28: 0 | AK28: 0 | AL28: 0
B29: 10 | C29: 4 | D29: GRAM04 | E29: WS | F29: GR2 | G29: 2 | H29: 252 | I29: 592 | J29: FWSPAT5 | K29: PALERMO WT5 (TUPELO) | L29: TUPELO | M29: 44 | N29: 0 | O29: 44413 | P29: TBC | Q29: 42228 | R29: 895 | S29: 179 | T29: PALERMO | U29: 2.888 | V29: 0.603 | W29: 0 | X29: 0 | Y29: 0 | Z29: 3.491 | AA29: 3 | AB29: 2.59 | AC29: 5.88 | AD29: 20.52 | AE29: 3.54 | AI29: 0 | AJ29: 0 | AK29: 0 | AL29: 0
B30: 0 | C30: 4 | H30: 252 | I30: 593 | J30: FWSPAX7 | K30: PALERMO TX7 (GLOBAL BLACK) | L30: GLOBAL BLACK | O30: NULL | U30: 2.888 | V30: 0.603 | W30: 0 | X30: 0 | Y30: 0 | Z30: 3.491 | AA30: 3 | AB30: 2.59 | AC30: 5.88 | AD30: 20.52 | AE30: 3.54 | AI30: 0 | AJ30: 0 | AK30: 0 | AL30: 0
B31: 0 | C31: 4 | H31: 252 | I31: 595 | J31: FWSPAA6 | K31: PALERMO WA6 (AGAVE) | L31: AGAVE | O31: NULL | U31: 2.888 | V31: 0.603 | W31: 0 | X31: 0 | Y31: 0 | Z31: 3.491 | AA31: 3 | AB31: 2.59 | AC31: 5.88 | AD31: 20.52 | AE31: 3.54 | AI31: 0 | AJ31: 0 | AK31: 0 | AL31: 0
B32: 0 | C32: 4 | H32: 252 | I32: 594 | J32: FWSPAD4 | K32: PALERMO SD4 (SEA SALT) | L32: SEA SALT | O32: NULL | U32: 2.888 | V32: 0.603 | W32: 0 | X32: 0 | Y32: 0 | Z32: 3.491 | AA32: 3 | AB32: 2.59 | AC32: 5.88 | AD32: 20.52 | AE32: 3.54 | AI32: 0 | AJ32: 0 | AK32: 0 | AL32: 0
B33: 10 | C33: 4 | D33: GRAM04 | E33: WL | F33: GRM | G33: 2 | H33: 253 | I33: 596 | J33: FWSPAX7 | K33: PALERMO TX7 (GLOBAL BLACK) | L33: GLOBAL BLACK | M33: 40 | N33: 0 | O33: 44413 | P33: TBC | Q33: 10205 | R33: 215 | S33: 43 | T33: PALERMO | U33: 2.888 | V33: 0.4 | W33: 0 | X33: 0 | Y33: 0 | Z33: 3.288 | AA33: 2 | AB33: 2.26 | AC33: 5.64 | AD33: 18.56 | AE33: 2.26 | AI33: 0 | AJ33: 0 | AK33: 0 | AL33: 0
B34: 0 | C34: 4 | H34: 253 | I34: 597 | J34: FWSPAT5 | K34: PALERMO WT5 (TUPELO) | L34: TUPELO | O34: NULL | U34: 2.888 | V34: 0.4 | W34: 0 | X34: 0 | Y34: 0 | Z34: 3.288 | AA34: 2 | AB34: 2.26 | AC34: 5.64 | AD34: 18.56 | AE34: 2.26 | AI34: 0 | AJ34: 0 | AK34: 0 | AL34: 0
B35: 10 | C35: 4 | D35: GRAM04 | E35: WS | F35: GWS | G35: 2 | H35: 133 | I35: 309 | J35: FGMPAA6 | K35: PALERMO WA6 (AGAVE BLUE) | L35: AGAVE BLUE | M35: 44 | N35: 0 | O35: 44250 | P35: ECR_265 | Q35: 42228 | R35: 895 | S35: 179 | T35: PALERMO | U35: 2.888 | V35: 0.603 | W35: 0 | X35: 0 | Y35: 0 | Z35: 3.491 | AA35: 3 | AB35: 2.59 | AC35: 5.88 | AD35: 20.52 | AE35: 3.54 | AI35: 0 | AJ35: 0 | AK35: 0 | AL35: 0
B36: 0 | C36: 4 | H36: 133 | I36: 310 | J36: FGMPAD4 | K36: PALERMO SD4 (SEA SALT) | L36: SEA SALT | O36: NULL | U36: 2.888 | V36: 0.603 | W36: 0 | X36: 0 | Y36: 0 | Z36: 3.491 | AA36: 3 | AB36: 2.59 | AC36: 5.88 | AD36: 20.52 | AE36: 3.54 | AI36: 0 | AJ36: 0 | AK36: 0 | AL36: 0
B37: 0 | C37: 4 | H37: 133 | I37: 311 | J37: FGMPAT5 | K37: PALERMO WT5 (TUPELO) | L37: TUPELO | O37: NULL | U37: 2.888 | V37: 0.603 | W37: 0 | X37: 0 | Y37: 0 | Z37: 3.491 | AA37: 3 | AB37: 2.59 | AC37: 5.88 | AD37: 20.52 | AE37: 3.54 | AI37: 0 | AJ37: 0 | AK37: 0 | AL37: 0
B38: 0 | C38: 4 | H38: 133 | I38: 312 | J38: FGMPAX7 | K38: PALERMO TX7 (GLOBAL BLACK) | L38: GLOBAL BLACK | O38: NULL | U38: 2.888 | V38: 0.603 | W38: 0 | X38: 0 | Y38: 0 | Z38: 3.491 | AA38: 3 | AB38: 2.59 | AC38: 5.88 | AD38: 20.52 | AE38: 3.54 | AI38: 0 | AJ38: 0 | AK38: 0 | AL38: 0
B39: 10 | C39: 5 | D39: MAGN02 | E39: WL | F39: W7A | G39: 7 | H39: 267 | I39: 628 | J39: FWLCPT3 | K39: CAPRI WT3 (WICKER BEIGE) | L39: WICKER BEIGE | M39: 48 | N39: 0 | O39: 44420 | P39: 003498-00350 | Q39: 66500 | R39: 1410 | S39: 282 | T39: CAPRI | U39: 1.6943 | V39: 0.35 | W39: 0 | X39: 0 | Y39: 0 | Z39: 2.0443 | AA39: 18 | AB39: 11.75 | AC39: 24.47 | AD39: 69.09 | AE39: 27.63 | AF39: MULLER 6MM 6035 // KUFNER TK 1080 | AG39: AXIS II | AI39: 18 | AJ39: 11.75 | AK39: 18 | AL39: 11.75
B40: 0 | C40: 5 | H40: 267 | I40: 629 | J40: FWLCPX7 | K40: CAPRI TX7 (GLOBAL BLACK) | L40: GLOBAL BLACK | O40: NULL | U40: 1.6943 | V40: 0.35 | W40: 0 | X40: 0 | Y40: 0 | Z40: 2.0443 | AA40: 18 | AB40: 11.75 | AC40: 24.47 | AD40: 69.09 | AE40: 27.63 | AI40: 18 | AJ40: 11.75 | AK40: 18 | AL40: 11.75
B41: 10 | C41: 5 | D41: MAGN02 | E41: WL | F41: W7B | G41: 9 | H41: 266 | I41: 627 | J41: FWLNPA5 | K41: NAPPA SA5 (SEAL GREY) | L41: SEAL GREY | M41: 43.7 | N41: 0 | O41: 44419 | P41: 003498-00350 | Q41: 28500 | R41: 605 | S41: 121 | T41: NAPPA | U41: 2.13 | V41: 0.35 | W41: 0 | X41: 0 | Y41: 0 | Z41: 2.48 | AA41: 26 | AB41: 16.06 | AC41: 36.75 | AD41: 118.14 | AE41: 39.86 | AF41: MULLER 6MM 6035 // KUFNER TK 1080 | AG41: AXIS II | AI41: 26 | AJ41: 16.06 | AK41: 26 | AL41: 16.06
B42: 0 | C42: 5 | H42: 266 | I42: 626 | J42: FWLNPX7 | K42: NAPPA TX7 (GLOBAL BLACK) | L42: GLOBAL BLACK | O42: NULL | U42: 2.13 | V42: 0.35 | W42: 0 | X42: 0 | Y42: 0 | Z42: 2.48 | AA42: 26 | AB42: 16.06 | AC42: 36.75 | AD42: 118.14 | AE42: 39.86 | AI42: 26 | AJ42: 16.06 | AK42: 26 | AL42: 16.06
...
